File: data/rawdata5.txt
File Path: C:\2024\20240314 CTLbio tensile\Test Run 5 03-14-24 16 22 53 PM\DAQ- Time, … - (Timed).txt
Test: CTLbio_tensile_EC5AA
Test Run: Test Run 5
Date: 3/14/2024 4:20:14 PM


Time 	Crosshead 	Load 	Extensometer
sec	mm	kN	mm
0.916999995708466	0.00126953125345608	0.0310938663482666	0.000364888904869076
1.11699998378754	0.0045410156417347	0.121592330932617	0.0012704903156191
1.31700003147125	0.00957031261350494	0.274603820800781	0.00317360081680818
1.51699995994568	0.0167968755704351	0.504213256835938	0.0056483268053853
1.71700000762939	0.0236816413234919	0.722658264160156	0.00829052260087337
1.91700005531311	0.0309082024614327	0.951276306152344	0.0110855889943196
2.11700010299683	0.0375000017811544	1.16449841308594	0.0134521960717393
2.31699991226196	0.0447753918706439	1.39063500976563	0.0162132655532332
2.51699995994568	0.0529785138496663	1.65463610839844	0.0195339798665373
2.71700000762939	0.0603515618422534	1.88808764648437	0.0223425122385379
2.91700005531311	0.0671386733301915	2.10425024414063	0.0247376628976781
3.11700010299683	0.0739257811801508	2.31716918945313	0.0274840458587278
3.31699991226196	0.081054684414994	2.54303149414062	0.0303354263451183
3.51699995994568	0.0885742192622274	2.77966748046875	0.0331393457599916
3.71700000762939	0.0957519514486194	3.00781176757812	0.0361202437488828
3.91700005531311	0.102099606010597	3.2058818359375	0.0384396698791534
4.11700010299683	0.10864257637877	3.40541821289063	0.0408518462791108
4.31699991226196	0.115673828986473	3.62369702148438	0.0438317147199996
4.51700019836426	0.122167970403098	3.81500439453125	0.0461097588413395
4.71700000762939	0.129296880913898	4.03430639648438	0.049149679398397
4.91699981689453	0.135888665681705	4.2313037109375	0.051186481869081
5.11700010299683	0.142480465001427	4.4374501953125	0.0538341046194546
5.31699991226196	0.149609375512227	4.65001708984375	0.0565091577300336
5.51700019836426	0.156201174831949	4.8503759765625	0.0590042400290258
5.71700000762939	0.162548822117969	5.04120458984375	0.0614561868133023
5.91699981689453	0.169140621437691	5.23950439453125	0.0639586432953365
6.11700010299683	0.17583007866051	5.442044921875	0.0663204482407309
6.31699991226196	0.182861331268214	5.65603125	0.0691779132466763
6.51700019836426	0.189355472684838	5.8553388671875	0.0715969581506215
6.71700000762939	0.195898435777053	6.0515400390625	0.0740163814043626
6.91699981689453	0.201806644327007	6.231373046875	0.0766167504480109
7.11700010299683	0.208740239031613	6.4340302734375	0.0789384430390783
7.31699991226196	0.216259766602889	6.66015576171875	0.0818595362943597
7.51700019836426	0.222998045501299	6.86173779296875	0.0843878151499666
7.71700000762939	0.229785160627216	7.06569921875	0.086932152044028
7.91699981689453	0.235986328334548	7.251845703125	0.0892157695489004
8.11699962615967	0.242382811848074	7.44016455078125	0.0915701893973164
8.31700038909912	0.250000011874363	7.66758544921875	0.0942461265367456
8.51700019836426	0.256933592027053	7.87253857421875	0.097051277407445
8.71700000762939	0.263476569671184	8.05036328125	0.0993223729892634
8.91699981689453	0.269482436124235	8.222806640625	0.101576020824723
9.11699962615967	0.275927741313353	8.41119140625	0.104137150628958
9.31700038909912	0.282763678114861	8.6126474609375	0.106610816146713
9.51700019836426	0.28999024652876	8.8242783203125	0.109556240204256
9.71700000762939	0.296874990453944	9.0131328125	0.111837885924615
9.91699981689453	0.302978529362008	9.1882197265625	0.113864625745919
10.1169996261597	0.309423834551126	9.3770869140625	0.116363626148086
10.3170003890991	0.316406250931323	9.5782841796875	0.119129974336829
10.5170001983643	0.322802719892934	9.76150390625	0.121534103527665
10.7170000076294	0.329785165376961	9.962517578125	0.124247802887112
10.9169998168945	0.336132798111066	10.1390205078125	0.126555329188704
11.1169996261597	0.342578132404014	10.31805859375	0.128814819618128
11.3170003890991	0.349462876329198	10.51346875	0.131429886096157
11.5170001983643	0.355957017745823	10.6962890625	0.134068090119399
11.7170000076294	0.362304679583758	10.8775986328125	0.136324699269608
11.9169998168945	0.369042973034084	11.0613408203125	0.138699353556149
12.1169996261597	0.375927746063098	11.258533203125	0.141492448165081
12.3170003890991	0.383251957828179	11.4594501953125	0.144148245453835
12.5170001983643	0.389990222174674	11.64954296875	0.146454171044752
12.7170000076294	0.396533199818805	11.8324736328125	0.14881206152495
12.9169998168945	0.402587902499363	11.99936328125	0.151088053826243
13.1169996261597	0.409521482652053	12.1906884765625	0.153464119648561
13.3170003890991	0.416845694417134	12.3964765625	0.156129550305195
13.5170001983643	0.423388672061265	12.5732734375	0.158642767928541
13.7170000076294	0.430029293056577	12.750099609375	0.161084783030674
13.9169998168945	0.436035159509629	12.8424990234375	0.162152864504606
14.1169996261597	0.442382821347564	12.99095703125	0.163988559506834
14.3170003890991	0.450097664725035	13.1574599609375	0.166188445291482
14.5170001983643	0.457031244877726	13.3089912109375	0.168142607435584
14.7170000076294	0.463769538328052	13.46646875	0.170292041730136
14.9169998168945	0.469921884359792	13.6103251953125	0.172364234458655
15.1169996261597	0.476464832900092	13.76183984375	0.174298300407827
15.3170003890991	0.4833007697016	13.931998046875	0.176588728209026
15.5170001983643	0.49023434985429	14.1024072265625	0.178840709850192
15.7170000076294	0.496826192829758	14.260875	0.181128052645363
15.9169998168945	0.502636714372784	14.3994716796875	0.182757154107094
16.117000579834	0.508935539983213	14.5508095703125	0.184784948942252
16.3169994354248	0.515869120135903	14.72153125	0.18675668979995
16.5170001983643	0.522363290656358	14.8651953125	0.189226178918034
16.7169990539551	0.529492215719074	15.0162734375	0.191384999197908
16.9169998168945	0.536035164259374	15.1422265625	0.193390907952562
17.117000579834	0.542626949027181	15.2882890625	0.195705753867514
17.3169994354248	0.549755874089897	15.450046875	0.198179259314202
17.5170001983643	0.55639649508521	15.592044921875	0.200895447051153
17.7169990539551	0.562988279853016	15.734333984375	0.203328716452233
17.9169998168945	0.569726573303342	15.87482421875	0.20622881129384
18.117000579834	0.576513644773513	16.0122353515625	0.208918296266347
18.3169994354248	0.583544897381216	16.15155859375	0.212275437661447
18.5170001983643	0.590039067901671	16.268140625	0.215260792174377
18.7169990539551	0.596484402194619	16.3819755859375	0.218565604882315
18.9169998168945	0.602539046667516	16.478314453125	0.221821203012951
19.117000579834	0.609716807957739	16.599775390625	0.225758383749053
19.3169994354248	0.617382815107703	16.71694921875	0.229918252443895
19.5170001983643	0.624121108558029	16.80058984375	0.234197461395524
19.7169990539551	0.630810565780848	16.87402734375	0.238722874200903
19.9169998168945	0.636767596006393	16.93069921875	0.242632202571258
20.117000579834	0.643115257844329	16.989552734375	0.247178686549887
20.3169994354248	0.650537083856761	17.0699140625	0.251964520430192
20.5170001983643	0.657275377307087	17.1208515625	0.257103471085429
20.7169990539551	0.663671875372529	17.16115234375	0.261770561337471
20.9169998168945	0.669628905598074	17.18664453125	0.266316870693117
21.117000579834	0.676025403663516	17.22977734375	0.271388416877016
21.3169994354248	0.682763697113842	17.277380859375	0.276479870080948
21.5170001983643	0.689941400196403	17.32478125	0.281968066701666
21.7169990539551	0.696826144121587	17.357544921875	0.2873866178561
21.9169998168945	0.703173805959523	17.373095703125	0.29276791610755
22.117000579834	0.709912099409848	17.40408984375	0.29812750290148
22.3169994354248	0.717041024472564	17.445826171875	0.303751876344904
22.5170001983643	0.723681645467877	17.4627734375	0.309157854644582
22.7169990539551	0.730761734303087	17.4981015625	0.315124838380143
22.9169998168945	0.737109396141022	17.497107421875	0.319772661896423
23.117000579834	0.743603508453816	17.491669921875	0.324555992847309
23.3169994354248	0.750683597289026	17.52369140625	0.329801783664152
23.5170001983643	0.757128931581974	17.540001953125	0.334741780534387
23.7169990539551	0.763671880122274	17.562314453125	0.339521910063922
23.9169998168945	0.7704101735726	17.588623046875	0.34471190883778
24.117000579834	0.777294917497784	17.610619140625	0.349864858435467
24.3169994354248	0.7844238425605	17.652162109375	0.355734315235168
24.5170001983643	0.791064463555813	17.65194921875	0.36094049573876
24.7169990539551	0.797607412096113	17.64893359375	0.365717685781419
24.9169998168945	0.803710951004177	17.6500078125	0.370206835214049
25.117000579834	0.810839817859232	17.683025390625	0.375443196389824
25.3169994354248	0.817968742921948	17.712328125	0.380818761186674
25.5170001983643	0.824072281830013	17.710794921875	0.385700026527047
25.7169990539551	0.830419943667948	17.72460546875	0.39065585588105
25.9169998168945	0.836181628983468	17.726259765625	0.395569193642586
26.117000579834	0.842480454593897	17.7441796875	0.400099350372329
26.3169994354248	0.850097683724016	17.791283203125	0.405882601626217
26.5170001983643	0.857128878124058	17.806892578125	0.411055312724784
26.7169990539551	0.863720721099526	17.81453515625	0.416502851294354
26.9169998168945	0.869824201799929	17.812072265625	0.421300908783451
27.117000579834	0.87636720854789	17.829056640625	0.426709972089157
27.3169994354248	0.883203116245568	17.853892578125	0.431983411544934
27.5170001983643	0.890429713763297	17.875947265625	0.437532231444493
27.7169990539551	0.897167949005961	17.8850234375	0.442880118498579
27.9169998168945	0.903271487914026	17.884740234375	0.447892991360277
28.117000579834	0.909619149751961	17.896130859375	0.45297498581931
28.3169994354248	0.916455057449639	17.911447265625	0.458657887065783
28.5170001983643	0.922900391742587	17.920306640625	0.463859090814367
28.7169990539551	0.930029316805303	17.948974609375	0.46953558921814
28.9169998168945	0.936718774028122	17.955896484375	0.474879343528301
29.117000579834	0.943505845498294	17.9684296875	0.480524991871789
29.3169994354248	0.950830057263374	17.994115234375	0.486368808196858
29.5170001983643	0.957275391556323	17.988896484375	0.491568585857749
29.7169990539551	0.963867176324129	17.998734375	0.497219152748585
29.9169998168945	0.970507797319442	18.008291015625	0.50252623623237
30.117000579834	0.977392541244626	18.023720703125	0.50830451073125
30.3169994354248	0.984423793852329	18.03723046875	0.513450417201966
30.5170001983643	0.990869128145278	18.03743359375	0.519095279742032
30.7169990539551	0.997265568003058	18.0395390625	0.524268951267004
30.9169998168945	1.00312498398125	18.034611328125	0.529250944964588
31.117000579834	1.01020513102412	18.062509765625	0.53485477110371
31.3169994354248	1.01743161212653	18.0887734375	0.540313543751836
31.5170001983643	1.02392572443932	18.089484375	0.545860442798585
31.7169990539551	1.0305664036423	18.09636328125	0.551301171071827
31.9169998168945	1.03666994255036	18.0902421875	0.556741084437817
32.117000579834	1.04326172731817	18.105642578125	0.561711785849184
32.3170013427734	1.05087889824063	18.13558203125	0.567439070437104
32.5169982910156	1.05761713348329	18.140962890625	0.573188008274883
32.7169990539551	1.06391601730138	18.131193359375	0.578361097723246
32.9169998168945	1.06987298931926	18.127416015625	0.583432847633958
33.117000579834	1.07641599606723	18.142724609375	0.588368566241115
33.3170013427734	1.08334957621992	18.162546875	0.594028970226645
33.5169982910156	1.09062495175749	18.1868515625	0.599637918639928
33.7169990539551	1.09750975389034	18.195857421875	0.605224922765046
33.9169998168945	1.10366207081825	18.185095703125	0.61080401064828
34.117000579834	1.11030275002122	18.192646484375	0.615992408711463
34.3170013427734	1.11738278064877	18.21340234375	0.621767889242619
34.5169982910156	1.12407223787159	18.215009765625	0.627129338681698
34.7169990539551	1.13125005736947	18.233111328125	0.632855750154704
34.9169998168945	1.13774416968226	18.230322265625	0.63846172997728
35.117000579834	1.14423828199506	18.23415625	0.643873354420066
35.3170013427734	1.15117186214775	18.24778515625	0.649247958790511
35.5169982910156	1.15742185153067	18.24015625	0.654500385280699
35.7169990539551	1.16376951336861	18.24302734375	0.659534765873104
35.9169998168945	1.17036129813641	18.25398046875	0.665038009174168
36.117000579834	1.17724610026926	18.269162109375	0.670514011289924
36.3170013427734	1.18437502533197	18.284287109375	0.67626015515998
36.5169982910156	1.19086913764477	18.27970703125	0.681668461766094
36.7169990539551	1.1972167994827	18.277759765625	0.686926243361086
36.9169998168945	1.20302732102573	18.270701171875	0.691861379891634
37.117000579834	1.20996090117842	18.289970703125	0.697121140547097
37.3170013427734	1.21728517115116	18.310330078125	0.703012687154114
37.5169982910156	1.22377928346395	18.309583984375	0.7085797842592
37.7169990539551	1.23037106823176	18.3095	0.713776331394911
37.9169998168945	1.2362792622298	18.29847265625	0.718625029549003
38.117000579834	1.2426758185029	18.3071953125	0.723998411558568
38.3170013427734	1.25029298942536	18.3446171875	0.729567662347108
38.5169982910156	1.2572753475979	18.35388671875	0.735522713512182
38.7169990539551	1.26396480482072	18.350986328125	0.741082592867315
38.9169998168945	1.27026368863881	18.3438046875	0.746234436519444
39.117000579834	1.27700192388147	18.35524609375	0.751802464947104
39.3170013427734	1.28408207092434	18.3691796875	0.757643603719771
39.5169982910156	1.29121087957174	18.37844921875	0.763229618314654
39.7169990539551	1.29780278075486	18.38661328125	0.768884085118771
39.9169998168945	1.30380864720792	18.370734375	0.774358923081309
40.117000579834	1.31035153754056	18.376193359375	0.779673340730369
40.3170013427734	1.31733401212841	18.390453125	0.785369367804378
40.5169982910156	1.32387690246105	18.3878125	0.790789315942675
40.7169990539551	1.33100582752377	18.4059609375	0.796413165517151
40.9169998168945	1.3373534893617	18.397951171875	0.801824673544616
41.117000579834	1.34389649610966	18.399931640625	0.807074597105384
41.3170013427734	1.3508788542822	18.413478515625	0.812633719760925
41.5169982910156	1.35732418857515	18.4082734375	0.818116823211312
41.7169990539551	1.36381841730326	18.4089609375	0.82332716556266
41.9169998168945	1.37050775811076	18.41551953125	0.828773656394333
42.117000579834	1.37729488778859	18.42264453125	0.834184174891561
42.3170013427734	1.38417968992144	18.4348359375	0.840186607092619
42.5169982910156	1.39047857373953	18.426822265625	0.845143862534314
42.7169990539551	1.3967773411423	18.42350390625	0.850643264129758
42.9169998168945	1.4027344295755	18.418888671875	0.855558202601969
43.117000579834	1.40991213265806	18.442294921875	0.861129548866302
43.3170013427734	1.41748052556068	18.46577734375	0.867173017468303
43.5169982910156	1.42416986636817	18.462830078125	0.872592383529991
43.7169990539551	1.43081054557115	18.460373046875	0.878284859936684
43.9169998168945	1.43671873956919	18.44459375	0.883458589669317
44.117000579834	1.44316407386214	18.44689453125	0.888572249095887
44.3170013427734	1.45073246676475	18.478763671875	0.894469441846013
44.5169982910156	1.45756837446243	18.480419921875	0.90033357264474
44.7169990539551	1.46406248677522	18.47296484375	0.905596592929214
44.9169998168945	1.47011713124812	18.46307421875	0.910887960344553
45.117000579834	1.47656246554106	18.466861328125	0.916024204343557
45.3170013427734	1.4833495952189	18.480431640625	0.921617669519037
45.5169982910156	1.49047852028161	18.494595703125	0.927487213630229
45.7169990539551	1.49736332241446	18.499052734375	0.933300994802266
45.9169998168945	1.50361331179738	18.486005859375	0.938540615607053
46.117000579834	1.51035154704005	18.491416015625	0.943894148804247
46.3170013427734	1.51738279964775	18.50483984375	0.949857640080154
46.5169982910156	1.52387691196054	18.500896484375	0.955006980802864
46.7169990539551	1.53066404163837	18.509140625	0.960641948040575
46.9169998168945	1.53681635856628	18.499322265625	0.966072315350175
47.117000579834	1.54306646436453	18.4950390625	0.971195928286761
47.3170013427734	1.54990237206221	18.5051328125	0.976578798145056
47.5169982910156	1.55629881191999	18.50643359375	0.981885939836502
47.7169990539551	1.56279292423278	18.511673828125	0.987397041171789
47.9169998168945	1.56953127589077	18.518751953125	0.992712564766407
48.117000579834	1.57641596160829	18.526259765625	0.99830876570195
48.3170013427734	1.58364255912602	18.542056640625	1.00390193983912
48.5169982910156	1.59033201634884	18.53690625	1.00944354198873
48.7169990539551	1.59702147357166	18.536673828125	1.01539492607117
48.9169998168945	1.60317379049957	18.52609765625	1.02050742134452
49.117000579834	1.61049806047231	18.548638671875	1.02626788429916
49.3170013427734	1.6178711084649	18.56083984375	1.03233766276389
49.5169982910156	1.62426754832268	18.546720703125	1.03774282615632
49.7169990539551	1.63076166063547	18.544638671875	1.04338699020445
49.9169998168945	1.63671874906868	18.530259765625	1.04844989255071
50.117000579834	1.64331053383648	18.537716796875	1.05347030330449
50.3170013427734	1.65112304966897	18.57509375	1.06010178569704
50.5169982910156	1.65815430227667	18.5765546875	1.06604106258601
50.7169990539551	1.66469730902463	18.5662578125	1.07144156936556
50.9169998168945	1.67080073151737	18.55157421875	1.0768350912258
51.117000579834	1.67734373826534	18.55446875	1.08240905683488
51.3170013427734	1.68432621285319	18.566498046875	1.08789664227515
51.5169982910156	1.69145502150059	18.578154296875	1.09373743180186
51.7169990539551	1.69814447872341	18.573255859375	1.09940476249903
51.9169998168945	1.70415034517646	18.5576875	1.1044037528336
52.117000579834	1.71064457390457	18.561177734375	1.10989378299564
52.3170013427734	1.71723635867238	18.56746484375	1.11570197623223
52.5169982910156	1.72363279853016	18.5654765625	1.12101039849222
52.7169990539551	1.73066405113786	18.579330078125	1.12646364141256
52.9169998168945	1.73715816345066	18.57588671875	1.1320955818519
53.117000579834	1.74389651510864	18.58329296875	1.13764649722725
53.3170013427734	1.75107421819121	18.59216796875	1.14321114961058
53.5169982910156	1.75747065804899	18.582763671875	1.14877487067133
53.7169990539551	1.76386721432209	18.580451171875	1.15411740262061
53.9169998168945	1.77041010465473	18.581921875	1.15963048301637
54.117000579834	1.77709956187755	18.590796875	1.16520968731493
54.3170013427734	1.78403325844556	18.6002734375	1.17081310600042
54.5169982910156	1.79047847632319	18.58882421875	1.1762409703806
54.7169990539551	1.79692381061614	18.589556640625	1.18188059423119
54.9169998168945	1.80297857150435	18.58125	1.18716061115265
55.117000579834	1.80996092967689	18.598197265625	1.19263550732285
55.3170013427734	1.81743165012449	18.61835546875	1.19879760313779
55.5169982910156	1.8240234348923	18.609630859375	1.204326399602
55.7169990539551	1.83085934258997	18.61277734375	1.2103634653613
55.9169998168945	1.83701177593321	18.5979765625	1.21551612392068
56.117000579834	1.84375001117587	18.604580078125	1.22121558524668
56.3170013427734	1.85136718209833	18.628185546875	1.22723530512303
56.5169982910156	1.85791018884629	18.618296875	1.23297411482781
56.7169990539551	1.86420895624906	18.6084375	1.23853597324342
56.9169998168945	1.8701171502471	18.59305859375	1.24370132107288
57.117000579834	1.87656248454005	18.594486328125	1.24885409604758
57.3170013427734	1.88344728667289	18.60931640625	1.25445623416454
57.5169982910156	1.89067388419062	18.623802734375	1.26025208737701
57.7169990539551	1.8975097918883	18.618740234375	1.26614770852029
57.9169998168945	1.90351565834135	18.6071796875	1.27121596597135
58.117000579834	1.91005854867399	18.607701171875	1.27667840570211
58.3170013427734	1.916992245242	18.6176171875	1.28217961173505
58.5169982910156	1.92353513557464	18.614521484375	1.28789246082306
58.7169990539551	1.9307128386572	18.6311875	1.29368877969682
58.9169998168945	1.93725584540516	18.622849609375	1.29913631826639
59.117000579834	1.94384763017297	18.622787109375	1.3048117980361
59.3170013427734	1.95078121032566	18.626703125	1.31063023582101
59.5169982910156	1.95703119970858	18.62048046875	1.31582503672689
59.7169990539551	1.96342775598168	18.61774609375	1.3215005164966
59.9169998168945	1.97016610763967	18.627880859375	1.32705317810178
60.117000579834	1.97714846581221	18.63571484375	1.33313611149788
60.3170013427734	1.98447261936963	18.646421875	1.33892393205315
60.5169982910156	1.99111318215728	18.64184375	1.34464376606047
60.7169990539551	1.99755863286555	18.634625	1.3503183145076
60.9169998168945	2.00351560488343	18.618609375	1.35550531558692
61.117000579834	2.0105957519263	18.639697265625	1.36144366115332
61.3170013427734	2.01791990548372	18.655330078125	1.36749260127544
61.5169982910156	2.02441401779652	18.64391796875	1.37331511359662
61.7169990539551	2.03095702454448	18.637865234375	1.37890211772174
61.9169998168945	2.03686533495784	18.620994140625	1.38416385743767
62.117000579834	2.04321299679577	18.622904296875	1.38930301181972
62.3170013427734	2.05073249526322	18.644107421875	1.39542296528816
62.5169982910156	2.05751950852573	18.64719140625	1.4011082239449
62.7169990539551	2.06406251527369	18.6397109375	1.40670337714255
62.9169998168945	2.07026372663677	18.629154296875	1.41207466367632
63.117000579834	2.07690428942442	18.632908203125	1.41763198189437
63.3170013427734	2.08388664759696	18.64503515625	1.4235214330256
63.5169982910156	2.09091790020466	18.652458984375	1.42927910201252
63.7169990539551	2.09746090695262	18.646205078125	1.43449264578521
63.9169998168945	2.1034178789705	18.6288984375	1.43986416514963
64.1169967651367	2.10981443524361	18.631859375	1.44519296009094
64.3170013427734	2.11674813181162	18.643296875	1.45086960401386
64.5169982910156	2.1233398001641	18.647236328125	1.45635928492993
64.7170028686523	2.13051750324667	18.659953125	1.46263022907078
64.9169998168945	2.13696295395494	18.651900390625	1.46815914195031
65.1169967651367	2.14355462230742	18.65023828125	1.47363194264472
65.3170013427734	2.15068366378546	18.66011328125	1.47940416354686
65.5169982910156	2.15717777609825	18.655234375	1.48544786497951
65.7170028686523	2.16376944445074	18.64987109375	1.49075814988464
65.9169998168945	2.17050779610872	18.653462890625	1.49669614620507
66.1169967651367	2.17739259824157	18.6560546875	1.50227337144315
66.3170013427734	2.18427740037441	18.6605	1.50835071690381
66.5169982910156	2.19057616777718	18.648076171875	1.5137066366151
66.7170028686523	2.19692382961512	18.644806640625	1.51925731915981
66.9169998168945	2.202880801633	18.631091796875	1.52446597348899
67.1169967651367	2.21005850471556	18.6554140625	1.52989535126835
67.3170013427734	2.21757823601365	18.6697578125	1.53613882139325
67.5169982910156	2.22416990436614	18.664244140625	1.54191406909376
67.7170028686523	2.23076180554926	18.657091796875	1.54738640412688
67.9169998168945	2.23662098869681	18.639076171875	1.55279238242656
68.1169967651367	2.24301754496992	18.64192578125	1.55828392598778
68.3170013427734	2.2506348323077	18.669623046875	1.56419223640114
68.5169982910156	2.25747074000537	18.66527734375	1.56972173135728
68.7170028686523	2.26401374675333	18.6575625	1.57552445307374
68.9169998168945	2.27001961320639	18.64162109375	1.58073473721743
69.1169967651367	2.27641593664885	18.643521484375	1.58602907322347
69.3170013427734	2.28315428830683	18.64617578125	1.5916028060019
69.5169982910156	2.29028309695423	18.661087890625	1.59731123130769
69.7170028686523	2.29716789908707	18.665041015625	1.60326028708369
69.9169998168945	2.30336911045015	18.65173828125	1.60874670837075
70.1169967651367	2.31010746210814	18.65551171875	1.61449576262385
70.3170013427734	2.31713871471584	18.664220703125	1.62015412934124
70.5169982910156	2.3236817214638	18.657376953125	1.62558373995125
70.7170028686523	2.33061518520117	18.65983203125	1.63161335512996
70.9169998168945	2.33686529099941	18.649947265625	1.63714506197721
71.1169967651367	2.34326161444187	18.649857421875	1.64276815485209
71.3170013427734	2.35024420544505	18.65714453125	1.64835329633206
71.5169982910156	2.35668942332268	18.654919921875	1.65408034808934
71.7170028686523	2.36313487403095	18.64969921875	1.65936478879303
71.9169998168945	2.3697754368186	18.650697265625	1.66496017482132
72.1169967651367	2.37651355564594	18.65184375	1.67056114878505
72.3170013427734	2.38354480825365	18.660712890625	1.67641858570278
72.5169982910156	2.39008781500161	18.6535234375	1.68205250520259
72.7170028686523	2.39663082174957	18.651513671875	1.68755545746535
72.9169998168945	2.40268558263779	18.63678125	1.69281812850386
73.1169967651367	2.40981439128518	18.65341015625	1.6984767280519
73.3170013427734	2.41713877767324	18.668208984375	1.70454848557711
73.5169982910156	2.42348643951118	18.653787109375	1.71003420837224
73.7170028686523	2.42983386851847	18.64955078125	1.71571411192417
73.9169998168945	2.43574217893183	18.635896484375	1.72068784013391
74.1169967651367	2.44218739680946	18.638498046875	1.72604911495
74.3170013427734	2.45000002905726	18.668521484375	1.73224543686956
74.5169982910156	2.45717773213983	18.673072265625	1.73778610769659
74.7170028686523	2.46391608379781	18.66630859375	1.74414552748203
74.9169998168945	2.47001950629056	18.6484921875	1.74962624441832
75.1169967651367	2.47661140747368	18.6487109375	1.75503175705671
75.3170013427734	2.48359376564622	18.661013671875	1.7607738263905
75.5169982910156	2.49086902476847	18.66917578125	1.7668497748673
75.7170028686523	2.49775382690132	18.667716796875	1.77285354584455
75.9169998168945	2.5038574822247	18.6491015625	1.77840562537313
76.1169967651367	2.5103515945375	18.646681640625	1.78379670251161
76.3170013427734	2.51713860780001	18.65398828125	1.78974121809006
76.5169982910156	2.52358405850828	18.649521484375	1.79515650961548
76.7170028686523	2.53071286715567	18.66196875	1.80101708974689
76.9169998168945	2.5373047683388	18.65552734375	1.80682085920125
77.1169967651367	2.54404288716614	18.653380859375	1.8124122871086
77.3170013427734	2.55117192864418	18.66287890625	1.81839684955776
77.5169982910156	2.55756825208664	18.649794921875	1.82398152537644
77.7170028686523	2.56396480835974	18.642630859375	1.82958703953773
77.9169998168945	2.57045892067254	18.6409609375	1.83496240060776
78.1169967651367	2.57714837789536	18.641703125	1.84078805614263
78.3170013427734	2.58413096889853	18.654265625	1.84622313827276
78.5169982910156	2.59052729234099	18.643794921875	1.8520534504205
78.7170028686523	2.59697274304926	18.6372734375	1.85771193355322
78.9169998168945	2.60297860950232	18.62814453125	1.86304678209126
79.1169967651367	2.61005852371454	18.644533203125	1.86883343849331
79.3170013427734	2.61752936057746	18.66184765625	1.87442591413856
79.5169982910156	2.62416992336512	18.652853515625	1.88034714665264
79.7170028686523	2.63085938058794	18.649369140625	1.88619387336075
79.9169998168945	2.63696280308068	18.634572265625	1.89154455438256
80.1169967651367	2.64360359869897	18.640037109375	1.89698662143201
80.3170013427734	2.65117175877094	18.6625234375	1.90335488878191
80.5169982910156	2.65786121599376	18.656228515625	1.90932478290051
80.7170028686523	2.6642088778317	18.643853515625	1.91497232299298
80.9169998168945	2.67021474428475	18.6272421875	1.92043394781649
81.1169967651367	2.67670908942819	18.63166015625	1.92587543278933
81.3170013427734	2.68374034203589	18.643818359375	1.93164497613907
81.5169982910156	2.69111339002848	18.655873046875	1.93754804786295
81.7170028686523	2.69794929772615	18.653896484375	1.94365892093629
81.9169998168945	2.70410161465406	18.63831640625	1.94925256073475
82.1169967651367	2.71069328300655	18.63609375	1.95483467541635
82.3170013427734	2.71752919070423	18.638453125	1.96043821051717
82.5169982910156	2.7239746414125	18.634615234375	1.96624174714088
82.7170028686523	2.73090810514987	18.6428125	1.97214120998979
82.9169998168945	2.7372557669878	18.629783203125	1.97767629288137
83.1169967651367	2.74360342882574	18.62539453125	1.98298203758895
83.3170013427734	2.75039067491889	18.627830078125	1.98862771503627
83.5169982910156	2.75659188628197	18.62077734375	1.99399911798537
83.7170028686523	2.7629395481199	18.617685546875	1.99965434148908
83.9169998168945	2.76972656138241	18.6270390625	2.00519151985645
84.1169967651367	2.77680670842528	18.633517578125	2.01094709336758
84.3170013427734	2.78417975641787	18.642849609375	2.01695901341736
84.5169982910156	2.79082031920552	18.635083984375	2.02293344773352
84.7170028686523	2.79721687547863	18.625556640625	2.02838215045631
84.9169998168945	2.80317384749651	18.612529296875	2.03378056176007
85.1169967651367	2.81025399453938	18.625486328125	2.03946931287646
85.3170013427734	2.81762704253197	18.64124609375	2.04581278376281
85.5169982910156	2.82416981644928	18.629513671875	2.05132341943681
85.7170028686523	2.83081061206758	18.626935546875	2.05734488554299
85.9169998168945	2.83676758408546	18.6080546875	2.06276308745146
86.1169967651367	2.84321280196309	18.608873046875	2.06827791407704
86.3170013427734	2.85083008930087	18.63485546875	2.0746614318341
86.5169982910156	2.85781244747341	18.634458984375	2.08045705221593
86.7170028686523	2.86440434865654	18.62130859375	2.08655092865229
86.9169998168945	2.8707031160593	18.612650390625	2.09209439344704
87.1169967651367	2.87739257328212	18.61239453125	2.09774309769273
87.3170013427734	2.88432626985013	18.615208984375	2.10380414500833
87.5169982910156	2.8912597335875	18.622005859375	2.10969685576856
87.7170028686523	2.8977538459003	18.60996484375	2.11534556001425
87.9169998168945	2.90361326187849	18.590828125	2.1206724923104
88.1169967651367	2.91005847975612	18.59072265625	2.12608324363828
88.3170013427734	2.91689462028444	18.601095703125	2.1320644300431
88.5169982910156	2.92343739420176	18.59749609375	2.13762768544257
88.7170028686523	2.93056643567979	18.60608984375	2.14350433088839
88.9169998168945	2.93701165355742	18.5978203125	2.14925454929471
89.1169967651367	2.94360355474055	18.5968203125	2.15490465052426
89.3170013427734	2.95068370178342	18.6036875	2.1607109811157
89.5169982910156	2.95717781409621	18.59588671875	2.1664360538125
89.7170028686523	2.9637694824487	18.59732421875	2.17233458533883
89.9169998168945	2.97060539014637	18.595234375	2.17800145037472
90.1169967651367	2.97744129784405	18.597216796875	2.1841274574399
90.3170013427734	2.9843260999769	18.5981796875	2.18994193710387
90.5169982910156	2.99067376181483	18.589984375	2.19572219066322
90.7170028686523	2.99702142365277	18.580484375	2.20145517960191
90.9169998168945	3.00302729010582	18.56603515625	2.20677978359163
91.1169967651367	3.01025388762355	18.585369140625	2.21281358972192
91.3170013427734	3.01782228052616	18.599482421875	2.21899175085127
91.5169982910156	3.02446284331381	18.590111328125	2.22505256533623
91.7170028686523	3.03105474449694	18.581388671875	2.23080324940383
91.9169998168945	3.03696282207966	18.563408203125	2.23641935735941
92.1169967651367	3.04345693439245	18.55995703125	2.24210182204843
92.3170013427734	3.05092777125537	18.58077734375	2.24829092621803
92.5169982910156	3.05771478451788	18.5755703125	2.2543235681951
92.7170028686523	3.0640137847513	18.5635390625	2.26003164425492
92.9169998168945	3.06997075676918	18.548818359375	2.26540653966367
93.1169967651367	3.07631841860712	18.5444765625	2.27101519703865
93.3170013427734	3.08305653743446	18.551333984375	2.27662408724427
93.5169982910156	3.0901855789125	18.562287109375	2.28264299221337
93.7170028686523	3.09702148661017	18.5618359375	2.28848913684487
93.9169998168945	3.10332025401294	18.548337890625	2.29412876069546
94.1169967651367	3.10996104963124	18.5455	2.29989737272263
94.3170013427734	3.1171387527138	18.5559453125	2.30607483536005
94.5169982910156	3.12368152663112	18.5450078125	2.31208908371627
94.7170028686523	3.13076167367399	18.548291015625	2.31811497360468
94.9169998168945	3.13715822994709	18.537705078125	2.32369266450405
95.1169967651367	3.14365234225988	18.532447265625	2.32946709729731
95.3170013427734	3.15068359486759	18.540361328125	2.33584991656244
95.5169982910156	3.15708015114069	18.529326171875	2.34141875989735
95.7170028686523	3.16372071392834	18.527765625	2.34724348410964
95.9169998168945	3.17041017115116	18.52683203125	2.3529150057584
96.1169967651367	3.17729497328401	18.53021484375	2.35892715863883
96.3170013427734	3.1844237819314	18.5326484375	2.36509670503438
96.5169982910156	3.19106434471905	18.525275390625	2.37096636556089
96.7170028686523	3.19760735146701	18.515474609375	2.37688049674034
96.9169998168945	3.20375966839492	18.497896484375	2.38248659297824
97.1169967651367	3.21093760430813	18.51279296875	2.38848873414099
97.3170013427734	3.21811530739069	18.51915625	2.39485106430948
97.5169982910156	3.22441407479346	18.500232421875	2.40054144524038
97.7170028686523	3.23071284219623	18.489875	2.40644509904087
97.9169998168945	3.23647470213473	18.468923828125	2.41170753724873
98.1169967651367	3.24282236397266	18.469697265625	2.41709779947996
98.3170013427734	3.25048831291497	18.496154296875	2.4232214782387
98.5169982910156	3.25737311504781	18.49066796875	2.42951489053667
98.7170028686523	3.26391612179577	18.479587890625	2.43533309549093
98.9169998168945	3.26992198824883	18.462537109375	2.44089728221297
99.1169967651367	3.27636720612645	18.457943359375	2.44643725454807
99.3170013427734	3.28320311382413	18.464119140625	2.4524531327188
99.5169982910156	3.29042971134186	18.475228515625	2.45854444801807
99.7170028686523	3.29726561903954	18.467404296875	2.46456661261618
99.9169998168945	3.30341793596745	18.45101171875	2.47035385109484
100.116996765137	3.31000983715057	18.44442578125	2.4760568048805
100.317001342773	3.31684574484825	18.45138671875	2.48236791230738
100.516998291016	3.32319340668619	18.441396484375	2.48804478906095
100.717002868652	3.33032221533358	18.449517578125	2.49451701529324
100.916999816895	3.33696277812123	18.4390625	2.50036502256989
101.116996765137	3.34375002421439	18.436412109375	2.50655971467495
101.317001342773	3.35102528333664	18.439412109375	2.51293391920626
101.516998291016	3.35742183960974	18.425103515625	2.51864362508059
101.717002868652	3.3639648463577	18.413619140625	2.52501713111997
101.916999816895	3.37060540914536	18.40883984375	2.53115105442703
102.116996765137	3.37744131684303	18.4068359375	2.53701023757458
102.317001342773	3.38442390784621	18.4033359375	2.54348339512944
102.516998291016	3.39086912572384	18.390466796875	2.54950788803399
102.717002868652	3.39731434360147	18.37863671875	2.55530676804483
102.916999816895	3.40317375957966	18.356875	2.56084091961384
103.116996765137	3.41020501218736	18.372681640625	2.56687449291348
103.317001342773	3.41748050414026	18.3795625	2.57319561205804
103.516998291016	3.42392572201788	18.364640625	2.57928832434118
103.717002868652	3.43056651763618	18.352759765625	2.58541782386601
103.916999816895	3.43662104569376	18.3331484375	2.59106629528105
104.116996765137	3.44321294687688	18.329041015625	2.59679812006652
104.317001342773	3.4507813397795	18.345330078125	2.60338187217712
104.516998291016	3.45751945860684	18.32896875	2.60961661115289
104.717002868652	3.46386712044477	18.316798828125	2.61595984920859
104.916999816895	3.46987298689783	18.29737890625	2.62160156853497
105.116996765137	3.47641599364579	18.292166015625	2.62751430273056
105.317001342773	3.48344724625349	18.299078125	2.63365241698921
105.516998291016	3.49077139981091	18.304193359375	2.64027924276888
105.717002868652	3.49770509637892	18.2972109375	2.64686136506498
105.916999816895	3.50385741330683	18.265369140625	2.65285139903426
106.116996765137	3.51054687052965	18.26065234375	2.65924748964608
106.317001342773	3.51748056709766	18.25736328125	2.66553927212954
106.516998291016	3.52421868592501	18.245373046875	2.67190812155604
106.717002868652	3.53129883296788	18.241634765625	2.6785449590534
106.916999816895	3.5377440508455	18.2233359375	2.68488051369786
107.116996765137	3.54428705759346	18.209869140625	2.69118556752801
107.317001342773	3.55112296529114	18.198578125	2.69740470685065
107.516998291016	3.55737307108939	18.18150390625	2.70355818793178
107.717002868652	3.56376962736249	18.170265625	2.7096236590296
107.916999816895	3.57045908458531	18.165013671875	2.71612405776978
108.116996765137	3.57739254832268	18.160154296875	2.72240047343075
108.317001342773	3.58452158980072	18.15562890625	2.7289129793644
108.516998291016	3.59106436371803	18.134302734375	2.73511768318713
108.717002868652	3.59741202555597	18.111935546875	2.74142855778337
108.916999816895	3.60332033596933	18.090009765625	2.7476055547595
109.116996765137	3.6102537997067	18.09207421875	2.7537711430341
109.317001342773	3.61762684769928	18.096712890625	2.76059843599796
109.516998291016	3.62407229840755	18.07205859375	2.76680989190936
109.717002868652	3.63066396676004	18.053419921875	2.77311378158629
109.916999816895	3.6365722771734	18.02939453125	2.77912686578929
110.116996765137	3.64291993901134	18.01459375	2.78513785451651
110.317001342773	3.65048833191395	18.028306640625	2.79195536859334
110.516998291016	3.65732423961163	18.010951171875	2.79871188104153
110.717002868652	3.66401369683444	17.991939453125	2.80539412051439
110.916999816895	3.67021490819752	17.96675	2.81165982596576
111.116996765137	3.67700192146003	17.954853515625	2.81819375231862
111.317001342773	3.68403317406774	17.94521484375	2.82514560967684
111.516998291016	3.69111332111061	17.938037109375	2.83192400820553
111.717002868652	3.6976074334234	17.9131484375	2.83872988075018
111.916999816895	3.70356440544128	17.880376953125	2.84487986937165
112.116996765137	3.71000985614955	17.864275390625	2.85108131356537
112.317001342773	3.71694331988692	17.85832421875	2.85819312557578
112.516998291016	3.72353522107005	17.838130859375	2.86443321965635
112.717002868652	3.73076181858778	17.83329296875	2.87161185406148
112.916999816895	3.7373045925051	17.809548828125	2.87820165976882
113.116996765137	3.74384759925306	17.783669921875	2.88503733463585
113.317001342773	3.75092774629593	17.776541015625	2.89202248677611
113.516998291016	3.75732430256903	17.7450859375	2.89839785546064
113.717002868652	3.76381841488183	17.723203125	2.90507264435291
113.916999816895	3.77050787210464	17.703076171875	2.91167036630213
114.116996765137	3.77724599093199	17.686091796875	2.91854958049953
114.317001342773	3.78413079306483	17.673736328125	2.92527233250439
114.516998291016	3.79042979329824	17.638154296875	2.93191010132432
114.717002868652	3.79677745513618	17.616224609375	2.93835368938744
114.916999816895	3.80283198319376	17.58673046875	2.94456584379077
115.116996765137	3.81000968627632	17.5854140625	2.95106437988579
115.317001342773	3.81757807917893	17.581173828125	2.95859528705478
115.516998291016	3.82431643083692	17.551109375	2.96562956646085
115.717002868652	3.83095699362457	17.522962890625	2.97264545224607
115.916999816895	3.83691396564245	17.48580859375	2.97908508218825
116.116996765137	3.84340831078589	17.463375	2.9853533487767
116.317001342773	3.85107425972819	17.469623046875	2.9929771553725
116.516998291016	3.85791016742587	17.440203125	3.00009315833449
116.717002868652	3.86440427973866	17.40664453125	3.00720939412713
116.916999816895	3.87050770223141	17.368361328125	3.01352702081203
117.116996765137	3.87700204737484	17.34869921875	3.02016851492226
117.317001342773	3.88388661667705	17.331578125	3.02733131684363
117.516998291016	3.89101565815508	17.312572265625	3.03490879014134
117.717002868652	3.89780267141759	17.2739453125	3.04191908799112
117.916999816895	3.90400388278067	17.23292578125	3.04861925542355
118.116996765137	3.91079112887383	17.21178515625	3.05541302077472
118.317001342773	3.91767593100667	17.187388671875	3.06261563673615
118.516998291016	3.9241211488843	17.1548671875	3.06941731832922
118.717002868652	3.93095705658197	17.1261875	3.07662063278258
118.916999816895	3.93715826794505	17.08154296875	3.08331754058599
119.116996765137	3.94350569695234	17.049259765625	3.09037184342742
119.317001342773	3.95048828795552	17.0292109375	3.09723964892328
119.516998291016	3.95698240026832	16.990982421875	3.10431141406298
119.717002868652	3.96342761814594	16.95592578125	3.11119365505874
119.916999816895	3.97016620263457	16.920142578125	3.11861489899457
120.116996765137	3.97695321589708	16.874314453125	3.12575814314187
120.317001342773	3.98408202454448	16.82491796875	3.13350185751915
120.516998291016	3.99072282016277	16.759072265625	3.14122647978365
120.717002868652	3.99726582691073	16.69121484375	3.14874830655754
120.916999816895	4.00336924940348	16.635763671875	3.15597886219621
121.116996765137	4.01054695248604	16.610009765625	3.16342455334961
121.317001342773	4.01787087321281	16.58158203125	3.17157828249037
121.516998291016	4.02416987344623	16.52295703125	3.17890918813646
121.717002868652	4.03071288019419	16.46164453125	3.18643427453935
121.916999816895	4.03662119060755	16.393841796875	3.19357845000923
122.116996765137	4.04316419735551	16.3443779296875	3.20121855475008
122.317001342773	4.05097659677267	16.3057578125	3.21020372211933
122.516998291016	4.05800761654973	16.22746484375	3.21873440407217
122.717002868652	4.06455062329769	16.10306640625	3.22843343019485
122.916999816895	4.07075183466077	15.798234375	3.24305659160018
123.033996582031	4.07495116814971	-1.59535913085938	3.46922408789396