File: data/rawdata2.txt
File Path: C:\2024\20240314 CTLbio tensile\Test Run 2 03-14-24 16 22 53 PM\DAQ- Time, … - (Timed).txt
Test: CTLbio_tensile_EC5AA
Test Run: Test Run 2
Date: 3/14/2024 3:56:51 PM


Time 	Crosshead 	Load 	Extensometer
sec	mm	kN	mm
0.919000029563904	0.00102539058843831	0.0389839172363281	5.94701603517933E-05
1.11899995803833	0.00463867172584287	0.146567291259766	0.00117370473162737
1.31900000572205	0.0103027341538109	0.326541656494141	0.00356332316187036
1.51900005340576	0.0168457027029945	0.536300659179688	0.0060378924899851
1.71899998188019	0.0234375002037268	0.744048706054688	0.00845691010908922
1.9190000295639	0.0312500014842954	0.991819274902344	0.0114409558591433
2.11899995803833	0.0388671869586688	1.23923901367187	0.0144082778206212
2.31900000572205	0.0460449227830395	1.46512243652344	0.0170679759321501
2.51900005340576	0.0529296885360964	1.682974609375	0.0197345561900875
2.71900010108948	0.0595703131693881	1.89778857421875	0.0223771821765695
2.91899991035461	0.0673828108119778	2.14951245117188	0.025541776267346
3.11899995803833	0.0747558588045649	2.382416015625	0.0283678364212392
3.31900000572205	0.0817382824607193	2.6045302734375	0.0308569069602527
3.51900005340576	0.0879882791195996	2.79962866210938	0.0335997974616475
3.71900010108948	0.0946777363424189	3.0200888671875	0.0356438977178186
3.91899991035461	0.101660152722616	3.241279296875	0.0387044638046063
4.11899995803833	0.109082029666752	3.47463500976562	0.0414887290389743
4.31899976730347	0.116015624371357	3.69246948242187	0.0439135365013499
4.51900005340576	0.122265628306195	3.88622802734375	0.0463119940832257
4.7189998626709	0.129003907204606	4.09550244140625	0.0486926292069256
4.91900014877319	0.136035159812309	4.31318603515625	0.0518304368597455
5.11899995803833	0.142578122904524	4.51434033203125	0.0540245200681966
5.31899976730347	0.149609375512227	4.73418603515625	0.0566381568205543
5.51900005340576	0.156005859025754	4.92603271484375	0.0588456423429307
5.7189998626709	0.162500000442378	5.1171552734375	0.0612320945947431
5.91900014877319	0.169482416822575	5.3232626953125	0.0637747798464261
6.11899995803833	0.175878900336102	5.52133154296875	0.0662264501443133
6.31899976730347	0.182324220077135	5.71976904296875	0.0683825492160395
6.51900005340576	0.189111335203052	5.9269658203125	0.0709651139914058
6.7189998626709	0.19614257325884	6.13581884765625	0.0735756839276291
6.91900014877319	0.203417963348329	6.3544072265625	0.0766065131756477
7.11899995803833	0.210107420571148	6.5573740234375	0.0787903481977992
7.31899976730347	0.216601561987773	6.75474169921875	0.0810697747510858
7.51900005340576	0.222607428440824	6.93442138671875	0.0832538498798385
7.7189998626709	0.22973632439971	7.14934326171875	0.0857803606777452
7.91900014877319	0.237011714489199	7.36719677734375	0.0884460896486416
8.11900043487549	0.243408198002726	7.559916015625	0.0909655573195778
8.31900024414063	0.250000011874363	7.7569462890625	0.0932974216993898
8.51900005340576	0.255957042099908	7.933484375	0.095372975920327
8.7189998626709	0.262451183516532	8.12202734375	0.0977369927568361
8.91899967193604	0.270214834017679	8.3529990234375	0.100672201369889
9.11900043487549	0.277099607046694	8.5580185546875	0.103030833997764
9.31900024414063	0.2836913918145	8.7467919921875	0.105607927253004
9.51900005340576	0.289892574073747	8.9107822265625	0.107529915112536
9.7189998626709	0.296484387945384	9.0983369140625	0.109647400677204
9.91899967193604	0.303369131870568	9.2975	0.112124100269284
10.1190004348755	0.310351548250765	9.500400390625	0.11477272346383
10.3190002441406	0.316796882543713	9.687728515625	0.117076095193624
10.5190000534058	0.322656240314245	9.8537529296875	0.119095595437102
10.7189998626709	0.329101574607193	10.035783203125	0.121313380077481
10.918999671936	0.335986318532377	10.2369384765625	0.123697929666378
11.1190004348755	0.342431652825326	10.416490234375	0.12602296192199
11.3190002441406	0.349560548784211	10.625271484375	0.128539351862855
11.5190000534058	0.356103526428342	10.8056982421875	0.13093625602778
11.7189998626709	0.362744147423655	10.9986171875	0.13360709999688
11.918999671936	0.369921879610047	11.203380859375	0.135894893901423
12.1190004348755	0.376464857254177	11.385130859375	0.13794882397633
12.3190002441406	0.383056642021984	11.5656396484375	0.140473668579943
12.5190000534058	0.38979493547231	11.7550390625	0.142477234476246
12.7189998626709	0.396679679397494	11.949173828125	0.145071142469533
12.918999671936	0.403564452426508	12.130802734375	0.147259066579863
13.1190004348755	0.410058593843132	12.3097919921875	0.149537110701203
13.3190002441406	0.416455091908574	12.48664453125	0.151607615407556
13.5190000534058	0.422607408836484	12.659	0.153850123751909
13.7189998626709	0.429931649705395	12.8662509765625	0.156339068780653
13.918999671936	0.437402341049165	13.0722705078125	0.158938331878744
14.1190004348755	0.444042962044477	13.2529580078125	0.161147894687019
14.3190002441406	0.450732419267297	13.43346484375	0.163530130521394
14.5190000534058	0.456689449492842	13.59145703125	0.165467150509357
14.7189998626709	0.463183590909466	13.767169921875	0.167816499015316
14.918999671936	0.470507802674547	13.9674970703125	0.170328246895224
15.1190004348755	0.47714842366986	14.1445068359375	0.172433457919396
15.3190002441406	0.483447278384119	14.3099189453125	0.174709537532181
15.5190000534058	0.489453144837171	14.4686748046875	0.176685105543584
15.7189998626709	0.495898420922458	14.6345859375	0.178783593582921
15.918999671936	0.50268555060029	14.81103515625	0.181357536348514
16.1189994812012	0.509814475663006	14.9924736328125	0.183738491614349
16.3190002441406	0.516601547133178	15.166642578125	0.186123550520279
16.5189990997314	0.522900372743607	15.3155458984375	0.188653153600171
16.7189998626709	0.529785174876451	15.484314453125	0.191066632396542
16.9190006256104	0.536865205504	15.65085546875	0.193965155631304
17.1189994812012	0.543457048479468	15.8045	0.196653840248473
17.3190002441406	0.550439464859664	15.9622568359375	0.199808971956372
17.5189990997314	0.5567871266976	16.0915693359375	0.202289651497267
17.7189998626709	0.5633300752379	16.22948046875	0.205384611035697
17.9190006256104	0.57041016407311	16.3712529296875	0.208713026950136
18.1189994812012	0.576806662138551	16.48472265625	0.211884471355006
18.3190002441406	0.583349610678852	16.599578125	0.215233056223951
18.5189990997314	0.590087904129177	16.7109296875	0.218967543332838
18.7189998626709	0.597070320509374	16.819310546875	0.222918199142441
18.9190006256104	0.60419924557209	16.918697265625	0.226618809392676
19.1189994812012	0.610888644587249	17.002373046875	0.230824938626029
19.3190002441406	0.617333978880197	17.066572265625	0.23465949925594
19.5189990997314	0.623632804490626	17.12583203125	0.238630236708559
19.7189998626709	0.630761729553342	17.1991875	0.243081463850103
19.9190006256104	0.637744145933539	17.258240234375	0.247824820689857
20.1189994812012	0.643994135316461	17.29425390625	0.25216827634722
20.3190002441406	0.650341797154397	17.331330078125	0.25665681459941
20.5189990997314	0.656152318697423	17.355419921875	0.260903005255386
20.7189998626709	0.662646489217877	17.398515625	0.2652037946973
20.9190006256104	0.670312496367842	17.46261328125	0.270289980107918
21.1189994812012	0.677197240293026	17.488572265625	0.275233847787604
21.3190002441406	0.683642574585974	17.50704296875	0.280191248748451
21.5189990997314	0.68984372774139	17.5237421875	0.284675479633734
21.7189998626709	0.696337898261845	17.5481484375	0.289531832095236
21.9190006256104	0.703320314642042	17.58066015625	0.294176250463352
22.1189994812012	0.710498075932264	17.61644921875	0.299395498586819
22.3190002441406	0.717138696927577	17.632515625	0.304205896100029
22.5189990997314	0.723291013855487	17.6406015625	0.309051683871076
22.7189998626709	0.729833962395787	17.66059375	0.31380241853185
22.9190006256104	0.736621092073619	17.68623828125	0.318867823807523
23.1189994812012	0.743115262594074	17.699814453125	0.323404965456575
23.3190002441406	0.750244129449129	17.726205078125	0.328568741679192
23.5189990997314	0.756884750444442	17.737544921875	0.333495670929551
23.7189998626709	0.763720716349781	17.760873046875	0.338760117301717
23.9190006256104	0.771044928114861	17.788216796875	0.343842810252681
24.1189994812012	0.777539040427655	17.793642578125	0.348898349329829
24.3190002441406	0.784130883403122	17.80566796875	0.354062765836716
24.5189990997314	0.790771504398435	17.818322265625	0.359015568392351
24.7189998626709	0.797753920778632	17.842232421875	0.364092935342342
24.9190006256104	0.804492214228958	17.853685546875	0.368958164472133
25.1189994812012	0.811035162769258	17.862029296875	0.374118040781468
25.3190002441406	0.817236315924674	17.866970703125	0.37900116876699
25.5189990997314	0.823339854832739	17.869962890625	0.383413193048909
25.7189998626709	0.830468721687794	17.9057421875	0.388824293622747
25.9190006256104	0.83759764675051	17.92534765625	0.393953872844577
26.1189994812012	0.844091817270964	17.929818359375	0.39883452700451
26.3190002441406	0.850683602038771	17.939482421875	0.404028280172497
26.5189990997314	0.856787082739174	17.942111328125	0.408993160817772
26.7189998626709	0.863623048644513	17.962162109375	0.413815898355097
26.9190006256104	0.871093769092113	17.99075390625	0.419225281802937
27.1189994812012	0.877734390087426	17.995275390625	0.424441503128037
27.3190002441406	0.883837870787829	17.99080078125	0.429223233368248
27.5189990997314	0.8899902459234	17.99319921875	0.433895271271467
27.7189998626709	0.8965331944637	18.008654296875	0.438699091318995
27.9190006256104	0.90361328329891	18.036505859375	0.444012403022498
28.1189994812012	0.910888658836484	18.056568359375	0.449523504357785
28.3190002441406	0.917578116059303	18.0629140625	0.454436900326982
28.5189990997314	0.923730491194874	18.0571328125	0.459529983345419
28.7189998626709	0.930517562665045	18.07334765625	0.464280252344906
28.9190006256104	0.937451142817736	18.089083984375	0.469672144390643
29.1189994812012	0.944189436268061	18.09853515625	0.474842148832977
29.3190002441406	0.951171852648258	18.110849609375	0.480066984891891
29.5189990997314	0.957666023168713	18.111744140625	0.485143944388255
29.7189998626709	0.964208971709013	18.114955078125	0.490212521981448
29.9190006256104	0.971093773841858	18.132193359375	0.495400978252292
30.1189994812012	0.977294868789613	18.12938671875	0.500323891174048
30.3190002441406	0.983740203082561	18.13515234375	0.505004776641726
30.5189990997314	0.990380882285535	18.1474921875	0.510227284394205
30.7189998626709	0.997314462438226	18.1663828125	0.515067833475769
30.9190006256104	1.00434571504593	18.180384765625	0.520481436979026
31.1189994812012	1.01088872179389	18.18166015625	0.525395851582289
31.3190002441406	1.01713871117681	18.179873046875	0.530553341377527
31.5189990997314	1.02314457762986	18.178212890625	0.535296450834721
31.7189998626709	1.03027338627726	18.20353125	0.540323148015887
31.9190006256104	1.03745120577514	18.223666015625	0.545747694559395
32.1189994812012	1.04389654006809	18.220181640625	0.550634053070098
32.3190002441406	1.05043943040073	18.219669921875	0.555823324248195
32.5190010070801	1.05634762439877	18.215443359375	0.560375570785254
32.7190017700195	1.06303708162159	18.228482421875	0.56541443336755
32.9189987182617	1.07055669650435	18.254798828125	0.570706324651837
33.1189994812012	1.07749027665704	18.25864453125	0.576101650949568
33.3190002441406	1.08398438896984	18.26130078125	0.58115174761042
33.5190010070801	1.09042972326279	18.261833984375	0.586148235015571
33.7190017700195	1.09721685294062	18.27533203125	0.591140938922763
33.9189987182617	1.10434566158801	18.29239453125	0.596629979554564
34.1189994812012	1.11132813617587	18.30155078125	0.602131942287087
34.3190002441406	1.11782224848866	18.29558984375	0.606919114943594
34.5190010070801	1.12387700937688	18.287140625	0.61199365882203
34.7190017700195	1.13061524461955	18.302384765625	0.61699835350737
34.9189987182617	1.13740237429738	18.31211328125	0.622185179963708
35.1189994812012	1.14404293708503	18.317541015625	0.62711734790355
35.3190002441406	1.15102541167289	18.33077734375	0.63264649361372
35.5190010070801	1.15742185153067	18.32576171875	0.637504446785897
35.7190017700195	1.16401363629848	18.330609375	0.642893312033266
35.9189987182617	1.17099611088634	18.34690234375	0.647940672934055
36.1189994812012	1.17734377272427	18.34344921875	0.652813469059765
36.3190002441406	1.18393555749208	18.346564453125	0.657754950225353
36.5190010070801	1.19057612027973	18.354650390625	0.662932579871267
36.7190017700195	1.19736324995756	18.361767578125	0.668176275212318
36.9189987182617	1.20410160161555	18.3676953125	0.673288246616721
37.1189994812012	1.21044926345348	18.364298828125	0.678478565532714
37.3190002441406	1.21665035840124	18.365177734375	0.683165853843093
37.5190010070801	1.2227538973093	18.362439453125	0.688016705680639
37.7190017700195	1.23007816728204	18.39196484375	0.69335731677711
37.9189987182617	1.23754877131432	18.41046875	0.698938732966781
38.1189994812012	1.2441894505173	18.405185546875	0.70433784276247
38.3190002441406	1.2507812352851	18.403521484375	0.709519197698683
38.5190010070801	1.25673832371831	18.39343359375	0.714313995558769
38.7190017700195	1.26347655896097	18.40656640625	0.719545467291027
38.9189987182617	1.27099605742842	18.4358046875	0.725207442883402
39.1189994812012	1.27783208154142	18.436119140625	0.730614468920976
39.3190002441406	1.28427729941905	18.426130859375	0.735952402465045
39.5190010070801	1.29052728880197	18.42062109375	0.740591203793883
39.7190017700195	1.29702151753008	18.425123046875	0.74571167351678
39.9189987182617	1.30400387570262	18.44289453125	0.750878709368408
40.1189994812012	1.31113280076534	18.455947265625	0.756347551941872
40.3190002441406	1.31782225798815	18.453869140625	0.761775590945035
40.5190010070801	1.32407224737108	18.4430625	0.76672324212268
40.7190017700195	1.33095704950392	18.455216796875	0.771964085288346
40.9189987182617	1.33774417918175	18.46040625	0.777051202021539
41.1189994812012	1.34428706951439	18.459484375	0.78224268509075
41.3190002441406	1.35092774871737	18.463546875	0.787561759352684
41.5190010070801	1.35703128762543	18.45616796875	0.792161386925727
41.7190017700195	1.36337894946337	18.459599609375	0.797109678387642
41.9189987182617	1.37026363518089	18.4760390625	0.802346272394061
42.1189994812012	1.37656251899898	18.47102734375	0.807253120001405
42.3190002441406	1.38310552574694	18.477208984375	0.81227213377133
42.5190010070801	1.38979486655444	18.483166015625	0.817520369309932
42.7190017700195	1.39672856312245	18.492451171875	0.822839443571866
42.9189987182617	1.40380859375	18.50586328125	0.828095769975334
43.1189994812012	1.41054682899266	18.5060703125	0.833480968140066
43.3190002441406	1.41708983574063	18.507224609375	0.838804058730602
43.5190010070801	1.42338871955872	18.50130859375	0.843861722387373
43.7190017700195	1.4307617675513	18.5220390625	0.849302159622312
43.9189987182617	1.4378905761987	18.52768359375	0.855030142702162
44.1189994812012	1.44423823803663	18.515435546875	0.860090716741979
44.3190002441406	1.45068357232958	18.51247265625	0.865239126142114
44.5190010070801	1.45664066076279	18.50321484375	0.870099756866693
44.7190017700195	1.46352534648031	18.51717578125	0.875140191055834
44.9189987182617	1.47124018985778	18.54513671875	0.880913634318858
45.1189994812012	1.47812499199063	18.54649609375	0.886511988937855
45.3190002441406	1.48452143184841	18.531955078125	0.891712552402169
45.5190010070801	1.49072264321148	18.523095703125	0.89644588297233
45.7190017700195	1.49731442797929	18.528939453125	0.901838997378945
45.9189987182617	1.50434568058699	18.54971875	0.907218316569924
46.1189994812012	1.51142582762986	18.55304296875	0.912758056074381
46.3190002441406	1.51791993994266	18.547134765625	0.918031670153141
46.5190010070801	1.52397458441556	18.5308046875	0.923065410461277
46.7190017700195	1.53061526361853	18.540412109375	0.928268651477993
46.9189987182617	1.53720704838634	18.544693359375	0.933514151256531
47.1189994812012	1.54365238267928	18.5466953125	0.938439625315368
47.3190002441406	1.55058596283197	18.55552734375	0.943754974287003
47.5190010070801	1.55717774759978	18.55628125	0.948997214436531
47.7190017700195	1.56391598284245	18.563142578125	0.95420383149758
47.9189987182617	1.57109380234033	18.577037109375	0.959670345764607
48.1189994812012	1.57749024219811	18.566119140625	0.965032028034329
48.3190002441406	1.58393557649106	18.566533203125	0.970421184320003
48.5190010070801	1.59057613927871	18.5693671875	0.975303410086781
48.7190017700195	1.5973144909367	18.577400390625	0.980598968453705
48.9189987182617	1.60419917665422	18.582294921875	0.986076658591628
49.1189994812012	1.61074218340218	18.577943359375	0.991357257589698
49.3190002441406	1.61713862325996	18.57383984375	0.99647615570575
49.5190010070801	1.62338872905821	18.57035546875	1.00152054801583
49.7190017700195	1.63056643214077	18.590603515625	1.00703188218176
49.9189987182617	1.63784180767834	18.603521484375	1.01271236781031
50.1189994812012	1.64433591999114	18.593798828125	1.01777771487832
50.3190002441406	1.65097659919411	18.59494921875	1.02313619572669
50.5190010070801	1.65708002168685	18.58096484375	1.02815078571439
50.7190017700195	1.66401371825486	18.594388671875	1.03349320124835
50.9189987182617	1.67133787181228	18.609689453125	1.03927543386817
51.1189994812012	1.67788087856025	18.600154296875	1.04445836041123
51.3190002441406	1.68403319548815	18.591189453125	1.04947434738278
51.5190010070801	1.69003906194121	18.584046875	1.05446274392307
51.7190017700195	1.69658206868917	18.588626953125	1.05956185143441
51.9189987182617	1.7035644268617	18.60407421875	1.06498622335494
52.1189994812012	1.71079102437943	18.6184921875	1.07052770908922
52.3190002441406	1.71743158716708	18.613236328125	1.07605883385986
52.5190010070801	1.72353512607515	18.5999140625	1.08077027834952
52.7190017700195	1.73022458329797	18.607494140625	1.08609686139971
52.9189987182617	1.73710938543081	18.615298828125	1.09141762368381
53.1189994812012	1.74379884265363	18.61492578125	1.09641707967967
53.3190002441406	1.75083009526134	18.625109375	1.10218161717057
53.5190010070801	1.75732420757413	18.618287109375	1.10741576645523
53.7190017700195	1.76391599234194	18.61615625	1.11249776091427
53.9189987182617	1.77080079447478	18.62678125	1.11810758244246
54.1189994812012	1.77695311140269	18.6136953125	1.12324371002614
54.3190002441406	1.78344722371548	18.610123046875	1.12828658893704
54.5190010070801	1.79018557537347	18.62396484375	1.13381666596979
54.7190017700195	1.79731450043619	18.636244140625	1.13942427560687
54.9189987182617	1.80449220351875	18.645779296875	1.14512257277966
55.1189994812012	1.8111327663064	18.638333984375	1.15027511492372
55.3190002441406	1.81743165012449	18.62841015625	1.15578295662999
55.5190010070801	1.8235839670524	18.618353515625	1.16087205242366
55.7190017700195	1.83071289211512	18.63488671875	1.16613297723234
55.9189987182617	1.83784181717783	18.648103515625	1.17209786549211
56.1189994812012	1.84428715147078	18.6333828125	1.17743876762688
56.3190002441406	1.85078126378357	18.632587890625	1.18253543041646
56.5190010070801	1.85668945778161	18.617814453125	1.18764792568982
56.7190017700195	1.86333002056926	18.627455078125	1.19253585580736
56.9189987182617	1.87075196299702	18.64894140625	1.19826931040734
57.1189994812012	1.87749019823968	18.647892578125	1.20372232049704
57.3190002441406	1.88393553253263	18.637939453125	1.20890978723764
57.5190010070801	1.89028319437057	18.635794921875	1.21423252858222
57.7190017700195	1.89697265159339	18.637392578125	1.21947075240314
57.9189987182617	1.90400390420109	18.647640625	1.22488115448505
58.1189994812012	1.91098637878895	18.656044921875	1.23054825235158
58.3190002441406	1.91743159666657	18.647232421875	1.23573746532202
58.5190010070801	1.92343746311963	18.63358203125	1.24058220535517
58.7190017700195	1.93002924788743	18.6438984375	1.24626012984663
58.9189987182617	1.93691405002028	18.6555625	1.25134363770485
59.1189994812012	1.94355472922325	18.654306640625	1.25674006994814
59.3190002441406	1.9506347598508	18.663537109375	1.26237235963345
59.5190010070801	1.95712898857892	18.65859375	1.26758171245456
59.7190017700195	1.96376955136657	18.659873046875	1.27300305757672
59.9189987182617	1.97089836001396	18.66856640625	1.27873278688639
60.1189994812012	1.97734381072223	18.660392578125	1.28433096688241
60.3190002441406	1.98403326794505	18.6631484375	1.28970528021455
60.5190010070801	1.99077138677239	18.66408984375	1.29511998966336
60.7190017700195	1.99770508334041	18.666587890625	1.30046415142715
60.9189987182617	2.00444343499839	18.665404296875	1.30575464572757
61.1189994812012	2.01079109683633	18.65668359375	1.31109158974141
61.3190002441406	2.01699207536876	18.647484375	1.31639942992479
61.5190010070801	2.02314462512732	18.6451015625	1.32116070017219
61.7190017700195	2.03046877868474	18.665349609375	1.32695795036852
61.9189987182617	2.03784182667732	18.678103515625	1.33250211365521
62.1189994812012	2.04433593899012	18.667306640625	1.33791367989033
62.3190002441406	2.05083005130291	18.6614609375	1.3430843828246
62.5190010070801	2.0566894672811	18.64490234375	1.34811317548156
62.7190017700195	2.06337892450392	18.652720703125	1.35323067661375
62.9189987182617	2.0708495285362	18.67792578125	1.35900941677392
63.1189994812012	2.07758788019419	18.67663671875	1.36459385976195
63.3190002441406	2.08393554203212	18.666837890625	1.36982253752649
63.5190010070801	2.09003896452487	18.65226953125	1.37476064264774
63.7190017700195	2.09648441523314	18.6547890625	1.37989223003387
63.9189987182617	2.10336921736598	18.666236328125	1.38526014052331
64.1190032958984	2.11049802601337	18.68106640625	1.39108393341303
64.3190002441406	2.11728527210653	18.68082421875	1.39648409094661
64.5189971923828	2.1235840395093	18.6697578125	1.40179693698883
64.7190017700195	2.13056639768183	18.67794140625	1.40724657103419
64.9189987182617	2.13750009424984	18.6796015625	1.41281890682876
65.1190032958984	2.1441406570375	18.678150390625	1.41828542109579
65.3190002441406	2.15092767030001	18.6784765625	1.42381154000759
65.5189971923828	2.15722667053342	18.670673828125	1.42920773942024
65.7190017700195	2.16372078284621	18.66883203125	1.43443990964442
65.9189987182617	2.17065424658358	18.67811328125	1.43976719118655
66.1190032958984	2.17695301398635	18.672111328125	1.4452903997153
66.3190002441406	2.18344735912979	18.666248046875	1.45002279896289
66.5189971923828	2.19003902748227	18.66908203125	1.45555997733027
66.7190017700195	2.19687493517995	18.67346484375	1.46082323044538
66.9189987182617	2.20380863174796	18.678181640625	1.46628473885357
67.1190032958984	2.21030274406075	18.6751640625	1.4718925813213
67.3190002441406	2.21674796193838	18.671193359375	1.47692486643791
67.5189971923828	2.22294917330146	18.6609765625	1.48209999315441
67.7190017700195	2.23022466525435	18.679205078125	1.48767197970301
67.9189987182617	2.23740236833692	18.689115234375	1.49319309275597
68.1190032958984	2.24370113573968	18.67404296875	1.49893620982766
68.3190002441406	2.25014658644795	18.671123046875	1.50396348908544
68.5189971923828	2.25610355846584	18.65664453125	1.50858203414828
68.7190017700195	2.26284191012383	18.6665703125	1.51414086576551
68.9189987182617	2.27060541510582	18.69616015625	1.51996489148587
69.1190032958984	2.27763666771352	18.695720703125	1.52577611152083
69.3190002441406	2.28413078002632	18.682548828125	1.53123051859438
69.5189971923828	2.29033199138939	18.674693359375	1.5363359125331
69.7190017700195	2.29692389257252	18.6732421875	1.54172419570386
69.9189987182617	2.30395514518023	18.68517578125	1.54748454224318
70.1190032958984	2.31113284826279	18.692921875	1.55310775153339
70.3190002441406	2.31782230548561	18.687568359375	1.55886635184288
70.5189971923828	2.32392572797835	18.670951171875	1.56411877833307
70.7190017700195	2.330566290766	18.6760234375	1.56946340575814
70.9189987182617	2.33725574798882	18.6775703125	1.57484377268702
71.1190032958984	2.34379875473678	18.676447265625	1.5803111018613
71.3190002441406	2.35078134573996	18.685583984375	1.58593209926039
71.5189971923828	2.35742190852761	18.684783203125	1.59140909090638
71.7190017700195	2.3641602601856	18.682916015625	1.59697921480983
71.9189987182617	2.37124017439783	18.688673828125	1.60287762992084
72.1190032958984	2.37749028019607	18.67746484375	1.60796311683953
72.3190002441406	2.38388660363853	18.668826171875	1.61339400801808
72.5189971923828	2.39038094878197	18.6700625	1.61881477106363
72.7190017700195	2.39716796204448	18.67734375	1.62419816479087
72.9189987182617	2.40400386974216	18.6802421875	1.62976619321853
73.1190032958984	2.41049798205495	18.67592578125	1.6351630911231
73.3190002441406	2.41684564389288	18.670525390625	1.64057302754372
73.5189971923828	2.42299796082079	18.66485546875	1.64590147323906
73.7190017700195	2.43022455833852	18.684478515625	1.65149313397706
73.9189987182617	2.43754871189594	18.69877734375	1.65719841606915
74.1190032958984	2.4440917186439	18.686271484375	1.66258646640927
74.3190002441406	2.4507325142622	18.6843046875	1.66845950298011
74.5189971923828	2.45688483119011	18.673228515625	1.67364289518446
74.7190017700195	2.46376963332295	18.679568359375	1.6790684312582
74.9189987182617	2.47119134292006	18.69811328125	1.68548093643039
75.1190032958984	2.47783213853836	18.694185546875	1.69108074624091
75.3190002441406	2.48403311707079	18.67507421875	1.69645482674241
75.5189971923828	2.49023432843387	18.6693359375	1.7016400815919
75.7190017700195	2.49677733518183	18.674384765625	1.70712650287896
75.9189987182617	2.50390614382923	18.68690625	1.71268882695585
76.1190032958984	2.51113274134696	18.6954765625	1.71894021332264
76.3190002441406	2.51782219856977	18.689087890625	1.72447494696826
76.5189971923828	2.52402340993285	18.6731015625	1.72981945797801
76.7190017700195	2.53071286715567	18.6746328125	1.73544557765126
76.9189987182617	2.53750011324883	18.677796875	1.7411329317838
77.1190032958984	2.54404288716614	18.67592578125	1.7464654520154
77.3190002441406	2.55092768929899	18.6792421875	1.75256293732673
77.5189971923828	2.55727535113692	18.669302734375	1.75764935556799
77.7190017700195	2.56372080184519	18.669421875	1.76318525336683
77.9189987182617	2.57055670954287	18.674064453125	1.76871463190764
78.1190032958984	2.57666013203561	18.6651484375	1.77374412305653
78.3190002441406	2.58310558274388	18.663126953125	1.77921983413398
78.5189971923828	2.58984370157123	18.669982421875	1.78441382013261
78.7190017700195	2.5969238486141	18.678470703125	1.79017975460738
78.9189987182617	2.60410155169666	18.687849609375	1.79607653990388
79.1190032958984	2.61074211448431	18.68083984375	1.80157064460218
79.3190002441406	2.61704111471772	18.67261328125	1.80677627213299
79.5189971923828	2.62314453721046	18.661625	1.81175698526204
79.7190017700195	2.63037113472819	18.67859765625	1.81773665826768
79.9189987182617	2.63764639385045	18.690787109375	1.82342412881553
80.1190032958984	2.64414073899388	18.679638671875	1.82898307684809
80.3190002441406	2.65078130178154	18.6737890625	1.83461478445679
80.5189971923828	2.65673827379942	18.6580859375	1.83959561400115
80.7190017700195	2.66342773102224	18.663990234375	1.84507016092539
80.9189987182617	2.67099612392485	18.684931640625	1.85096822679043
81.1190032958984	2.67792958766222	18.68518359375	1.8569054082036
81.3190002441406	2.68442393280566	18.672927734375	1.86235806904733
81.5189971923828	2.69082025624812	18.6660390625	1.867676503025
81.7190017700195	2.69750971347094	18.668001953125	1.87305454164743
81.9189987182617	2.70449207164347	18.67435546875	1.87871081288904
82.1190032958984	2.71137687377632	18.671748046875	1.88408955000341
82.3190002441406	2.71777343004942	18.66503515625	1.8894582754001
82.5189971923828	2.7237304020673	18.64721875	1.89473235514015
82.7190017700195	2.73032230325043	18.653064453125	1.8998725572601
82.9189987182617	2.73706065490842	18.65816796875	1.90510787069798
83.1190032958984	2.74360342882574	18.657974609375	1.91046681720763
83.3190002441406	2.75063468143344	18.667099609375	1.9162081880495
83.5189971923828	2.75708013214171	18.668185546875	1.92161765880883
83.7190017700195	2.76367180049419	18.66290234375	1.92731141578406
83.9189987182617	2.77080084197223	18.673181640625	1.93292507901788
84.1190032958984	2.77724605984986	18.662095703125	1.9379238365218
84.3190002441406	2.78388662263751	18.66098828125	1.9435731228441
84.5189971923828	2.79067386873066	18.6622421875	1.94896175526083
84.7190017700195	2.79755867086351	18.66654296875	1.95474759675562
84.9189987182617	2.80429678969085	18.66378125	1.96028198115528
85.1190032958984	2.81069334596395	18.656578125	1.96578190661967
85.3190002441406	2.8169434517622	18.647130859375	1.97088159620762
85.5189971923828	2.82314443029463	18.6421875	1.97620922699571
85.7190017700195	2.83056637272239	18.665697265625	1.981804613024
85.9189987182617	2.83793942071497	18.67762109375	1.9877185113728
86.1190032958984	2.84457998350263	18.66485546875	1.9935688469559
86.3190002441406	2.85107432864606	18.657376953125	1.99913885444403
86.5189971923828	2.85703130066395	18.63958203125	2.00420361943543
86.7190017700195	2.86381831392646	18.644083984375	2.00948189012706
86.9189987182617	2.87119136191905	18.66221875	2.01530498452485
87.1190032958984	2.87792971357703	18.6570703125	2.02086521312594
87.3190002441406	2.88408203050494	18.640119140625	2.02622846700251
87.5189971923828	2.89018545299768	18.630732421875	2.0313102286309
87.7190017700195	2.89658200927079	18.63264453125	2.03648814931512
87.9189987182617	2.90341791696846	18.63806640625	2.04197410494089
88.1190032958984	2.91049806401134	18.648087890625	2.04752129502594
88.3190002441406	2.91718752123415	18.64463671875	2.05304753035307
88.5189971923828	2.92348628863692	18.628802734375	2.05854116939008
88.7190017700195	2.9303221963346	18.640234375	2.06377170979977
88.9189987182617	2.93730478733778	18.646255859375	2.06950935535133
89.1190032958984	2.9439942445606	18.644587890625	2.07488937303424
89.3190002441406	2.9508788138628	18.644591796875	2.08072829991579
89.5189971923828	2.9572753701359	18.633173828125	2.08578002639115
89.7190017700195	2.96386727131903	18.632763671875	2.09113513119519
89.9189987182617	2.97089852392673	18.644337890625	2.09680828265846
90.1190032958984	2.97724618576467	18.63330859375	2.10211798548698
90.3190002441406	2.98388674855232	18.633033203125	2.10731639526784
90.5189971923828	2.99057620577514	18.63078125	2.11279164068401
90.7190017700195	2.99760745838284	18.64039453125	2.11842637509108
90.9189987182617	3.00454092212021	18.639064453125	2.12423200719059
91.1190032958984	3.01123037934303	18.630623046875	2.12975265458226
91.3190002441406	3.01762693561614	18.618591796875	2.13514687493443
91.5189971923828	3.02397459745407	18.6149140625	2.14028754271567
91.7190017700195	3.03125008940697	18.630787109375	2.14588479138911
91.9189987182617	3.0382324475795	18.63233203125	2.15143198147416
92.1190032958984	3.0444823205471	18.614474609375	2.15680198743939
92.3190002441406	3.05073242634535	18.602970703125	2.16196780093014
92.5189971923828	3.05654294788837	18.589103515625	2.1668856497854
92.7190017700195	3.06318351067603	18.59782421875	2.17185216024518
92.9189987182617	3.07075190357864	18.620607421875	2.17758375220001
93.1190032958984	3.07763670571148	18.6178671875	2.18338868580759
93.3190002441406	3.08398436754942	18.60665234375	2.18843878246844
93.5189971923828	3.0901855789125	18.600029296875	2.19367537647486
93.7190017700195	3.09677724726498	18.597294921875	2.19890801236033
93.9189987182617	3.10380849987268	18.611138671875	2.20418092794716
94.1190032958984	3.11093754135072	18.61870703125	2.21004197373986
94.3190002441406	3.11762699857354	18.610134765625	2.21572583541274
94.5189971923828	3.12373042106628	18.590767578125	2.22075101919472
94.7190017700195	3.1304198782891	18.596927734375	2.22626887261868
94.9189987182617	3.13710933551192	18.600759765625	2.23166355863214
95.1190032958984	3.14365234225988	18.59668359375	2.23705777898431
95.3190002441406	3.15068359486759	18.60502734375	2.24269181489944
95.5189971923828	3.15732415765524	18.600017578125	2.24825390614569
95.7190017700195	3.16416006535292	18.600259765625	2.2537843324244
95.9189987182617	3.17133800126612	18.605576171875	2.25946609862149
96.1190032958984	3.17768566310406	18.58915234375	2.26478953845799
96.3190002441406	3.18422843702137	18.58571484375	2.27035046555102
96.5189971923828	3.19086923263967	18.58310546875	2.27568158879876
96.7190017700195	3.19775380194187	18.584328125	2.28137569501996
96.9189987182617	3.20454104803503	18.583880859375	2.28674267418683
97.1190032958984	3.21108405478299	18.57508203125	2.29223002679646
97.3190002441406	3.21728526614606	18.563896484375	2.29761679656804
97.5189971923828	3.22338868863881	18.552955078125	2.30224058032036
97.7190017700195	3.2305174972862	18.57112109375	2.30797822587192
97.9189987182617	3.23769520036876	18.579974609375	2.31386278755963
98.1190032958984	3.2441895455122	18.570251953125	2.31891847215593
98.3190002441406	3.25078121386468	18.564677734375	2.324448665604
98.5189971923828	3.2568359747529	18.547150390625	2.32956046238542
98.7190017700195	3.26367188245058	18.55353125	2.33492301777005
98.9189987182617	3.27104493044317	18.568560546875	2.34059756621718
99.1190032958984	3.2776368316263	18.55898828125	2.34611285850406
99.3190002441406	3.28383781015873	18.54413671875	2.35131732188165
99.5189971923828	3.28999012708664	18.532431640625	2.35653063282371
99.7190017700195	3.29658202826977	18.5336953125	2.36164219677448
99.9189987182617	3.30366217531264	18.550255859375	2.36727064475417
100.119003295898	3.31093743443489	18.556279296875	2.37306603230536
100.319000244141	3.31762689165771	18.548427734375	2.37884162925184
100.518997192383	3.32377920858562	18.530662109375	2.38404283300042
100.71900177002	3.33066401071846	18.538228515625	2.38955765962601
100.918998718262	3.33749991841614	18.535853515625	2.39514233544469
101.119003295898	3.3442871645093	18.5342734375	2.40068533457816
101.319000244141	3.35122062824667	18.531935546875	2.40622507408261
101.518997192383	3.35771474055946	18.521865234375	2.41161021403968
101.71900177002	3.36430664174259	18.514529296875	2.41720303893089
101.918998718262	3.37114254944026	18.513962890625	2.42264941334724
102.119003295898	3.37734376080334	18.5001484375	2.42796912789345
102.319000244141	3.38378897868097	18.49672265625	2.43311724625528
102.518997192383	3.39052733033895	18.4950078125	2.43868911638856
102.71900177002	3.39750968851149	18.503974609375	2.44399765506387
102.918998718262	3.40449227951467	18.5010390625	2.44965986348689
103.119003295898	3.41103505343199	18.49281640625	2.45497864671052
103.319000244141	3.41728515923023	18.479017578125	2.46007647365332
103.518997192383	3.42338858172297	18.467548828125	2.46519362553954
103.71900177002	3.43046872876585	18.477685546875	2.47077760286629
103.918998718262	3.43759777024388	18.48266015625	2.47651501558721
104.119003295898	3.44404298812151	18.47014453125	2.4817471858114
104.319000244141	3.4505371004343	18.4668359375	2.48732604086399
104.518997192383	3.45644541084766	18.445712890625	2.49227811582386
104.71900177002	3.46308597363532	18.446642578125	2.49773729592562
104.918998718262	3.47060547210276	18.4654921875	2.50372150912881
105.119003295898	3.47744137980044	18.460791015625	2.50906590372324
105.319000244141	3.4839843865484	18.446453125	2.51459633000195
105.518997192383	3.49033204838634	18.435326171875	2.52006016671658
105.71900177002	3.49716795608401	18.433453125	2.52562644891441
105.918998718262	3.50424810312688	18.44081640625	2.53121578134596
106.119003295898	3.51123046129942	18.4335859375	2.53718858584762
106.319000244141	3.51762701757252	18.41780078125	2.54241330549121
106.518997192383	3.52358398959041	18.398681640625	2.54789809696376
106.71900177002	3.53017589077353	18.393150390625	2.55316123366356
106.918998718262	3.53706046007574	18.39916796875	2.55876057781279
107.119003295898	3.54374991729856	18.393546875	2.56417947821319
107.319000244141	3.55078116990626	18.394763671875	2.57015158422291
107.518997192383	3.55722662061453	18.37954296875	2.57532764226198
107.71900177002	3.56381828896701	18.370208984375	2.58092163130641
107.918998718262	3.57084954157472	18.3700703125	2.58651585318148
108.119003295898	3.57719720341265	18.352380859375	2.59177829138935
108.319000244141	3.58378910459578	18.3451875	2.59728403761983
108.518997192383	3.5904785618186	18.340021484375	2.60300072841346
108.71900177002	3.59736336395144	18.337994140625	2.60841147974133
108.918998718262	3.60410148277879	18.329544921875	2.61408742517233
109.119003295898	3.61049803905189	18.3155234375	2.61928793042898
109.319000244141	3.61679680645466	18.297390625	2.62457225471735
109.518997192383	3.62294912338257	18.286875	2.63018137775362
109.71900177002	3.63032217137516	18.300318359375	2.63583939522505
109.918998718262	3.63774411380291	18.30294921875	2.64187273569405
110.119003295898	3.64428712055087	18.281900390625	2.64749978668988
110.319000244141	3.650879021734	18.2626015625	2.65283440239727
110.518997192383	3.65683599375188	18.245869140625	2.65844166278839
110.71900177002	3.66362300701439	18.2422890625	2.66394321806729
110.918998718262	3.67114250548184	18.256419921875	2.67009832896292
111.119003295898	3.67792975157499	18.233166015625	2.67603690735996
111.319000244141	3.68422851897776	18.2118671875	2.68141273409128
111.518997192383	3.69042973034084	18.1918828125	2.6870088186115
111.71900177002	3.6969727370888	18.185205078125	2.69269174896181
111.918998718262	3.70390620082617	18.186771484375	2.69812671467662
112.119003295898	3.71103524230421	18.1823203125	2.70411721430719
112.319000244141	3.71772469952703	18.16205078125	2.70981364883482
112.518997192383	3.72397457249463	18.134744140625	2.71552754566073
112.71900177002	3.73085937462747	18.13223828125	2.72124540060759
112.918998718262	3.73759772628546	18.11745703125	2.72720376960933
113.119003295898	3.74414073303342	18.100521484375	2.73251975886524
113.319000244141	3.75083019025624	18.088513671875	2.73842364549637
113.518997192383	3.75708006322384	18.070296875	2.74366117082536
113.71900177002	3.76357417553663	18.054955078125	2.74938088841736
113.918998718262	3.77055653370917	18.053669921875	2.75523029267788
114.119003295898	3.7769041955471	18.031298828125	2.76082847267389
114.319000244141	3.78344720229506	18.0134296875	2.766496501863
114.518997192383	3.79023444838822	18.0041015625	2.77217105031013
114.71900177002	3.79711925052106	17.997634765625	2.77829729020596
114.918998718262	3.80415050312877	17.986064453125	2.78435321524739
115.119003295898	3.81079106591642	17.963681640625	2.7900526765734
115.319000244141	3.81728517822921	17.937724609375	2.79573537409306
115.518997192383	3.82353505119681	17.916654296875	2.80149164609611
115.71900177002	3.83081054314971	17.917861328125	2.80773779377341
115.918998718262	3.8379393517971	17.9065625	2.81392293982208
116.119003295898	3.84423835203052	17.872033203125	2.8198251966387
116.319000244141	3.85068356990814	17.849912109375	2.82578472979367
116.518997192383	3.8565918803215	17.818263671875	2.83130281604826
116.71900177002	3.86342778801918	17.816365234375	2.8372653760016
116.918998718262	3.87109373696148	17.820013671875	2.84376181662083
117.119003295898	3.8780274335295	17.795873046875	2.85024079494178
117.319000244141	3.88442375697196	17.75873046875	2.85637006163597
117.518997192383	3.89062496833503	17.728720703125	2.86209629848599
117.71900177002	3.89721686951816	17.712603515625	2.8680230025202
117.918998718262	3.9041992276907	17.701953125	2.8742786962539
118.119003295898	3.91127914190292	17.689330078125	2.88087781518698
118.319000244141	3.91777325421572	17.654853515625	2.88738356903195
118.518997192383	3.92387714236975	17.617970703125	2.89348210208118
118.71900177002	3.93042014911771	17.60158203125	2.89945933036506
118.918998718262	3.93706047907472	17.581771484375	2.905746223405
119.119003295898	3.94355459138751	17.557748046875	2.91215884499252
119.319000244141	3.95053718239069	17.547078125	2.91885435581207
119.518997192383	3.95712908357382	17.51884375	2.92487628757954
119.71900177002	3.96386720240116	17.4960390625	2.93129053898156
119.918998718262	3.97099601104856	17.480658203125	2.93801166117191
120.119003295898	3.97734390571713	17.44518359375	2.94452765956521
120.319000244141	3.9838869124651	17.42023828125	2.95113469474018
120.518997192383	3.99047834798694	17.39475	2.95737176202238
120.71900177002	3.99741204455495	17.377732421875	2.96422210521996
120.918998718262	4.00429684668779	17.354421875	2.97103240154684
121.119003295898	4.01088874787092	17.318212890625	2.97739636152983
121.319000244141	4.01723617687821	17.276818359375	2.98402574844658
121.518997192383	4.02348628267646	17.242619140625	2.99024116247892
121.71900177002	4.03076177462935	17.22988671875	2.99728568643332
121.918998718262	4.03798837214708	17.19198046875	3.004205878824
122.119003295898	4.04462870210409	17.131478515625	3.01108392886817
122.319000244141	4.05126949772239	17.066013671875	3.01815452985466
122.518997192383	4.0574218146503	16.997203125	3.02512245252728
122.71900177002	4.06435551121831	16.8765	3.03294276818633
122.829002380371	4.0695802308619	0.160437683105469	3.26667237095535