File: data/rawdata3.txt
File Path: C:\2024\20240314 CTLbio tensile\Test Run 3 03-14-24 16 22 53 PM\DAQ- Time, … - (Timed).txt
Test: CTLbio_tensile_EC5AA
Test Run: Test Run 3
Date: 3/14/2024 4:08:34 PM


Time 	Crosshead 	Load 	Extensometer
sec	mm	kN	mm
0.912000000476837	0.00170898442775069	0.0386541061401367	6.87302872393047E-05
1.11199998855591	0.00502929697177024	0.127094184875488	0.000505658590554958
1.31200003623962	0.00913085932552349	0.247054168701172	0.00241077032114845
1.51199996471405	0.0152832035382744	0.438922912597656	0.00460896671938826
1.71200001239777	0.0225097664952045	0.659905944824219	0.007204227586044
1.91199994087219	0.0296875005005859	0.883157043457031	0.00988807187241036
2.11199998855591	0.0373046859749593	1.11668432617188	0.0127869197967811
2.31200003623962	0.0445800797024276	1.34034631347656	0.0153764449351002
2.51200008392334	0.0518554697919171	1.55983032226563	0.018114791600965
2.71199989318848	0.0596679674345069	1.80240686035156	0.0208209439733764
2.91199994087219	0.0667480489937589	2.02230322265625	0.023737187802908
3.11199998855591	0.0737792943255045	2.23992309570313	0.0262182420556201
3.31200003623962	0.0808105469332077	2.46300854492188	0.028885771826026
3.51200008392334	0.0880371080711484	2.6879248046875	0.0316127479891293
3.71199989318848	0.0950683606788516	2.90146655273438	0.0343057909049094
3.91199994087219	0.101806639577262	3.11147900390625	0.0368631626770366
4.11199998855591	0.108203123090789	3.30797290039063	0.0392265574191697
4.31199979782104	0.11479492241051	3.51081079101563	0.0415226386394352
4.51200008392334	0.122412107884884	3.73997241210937	0.0443321587226819
4.71199989318848	0.129638676298782	3.94245971679688	0.0471599742013495
4.91200017929077	0.136425776872784	4.1524375	0.0497014407301322
5.11199998855591	0.142871096613817	4.3486005859375	0.051892737246817
5.31199979782104	0.149072264321148	4.53844287109375	0.0543638670933433
5.51200008392334	0.156152338604443	4.7455341796875	0.0569574331166223
5.71199989318848	0.163232427439652	4.96133984375	0.0595046294620261
5.91200017929077	0.169873048434965	5.15245556640625	0.0620494101895019
6.11199998855591	0.175927736563608	5.3283359375	0.0641351361991838
6.31199979782104	0.182226562174037	5.51512451171875	0.0662847960484214
6.51200008392334	0.188818361493759	5.7069345703125	0.0686794810462743
6.71199989318848	0.195800777873956	5.909580078125	0.0711940956534818
6.91200017929077	0.202832030481659	6.115291015625	0.0735241555958055
7.11199998855591	0.209326171898283	6.3067724609375	0.0760784969315864
7.31199979782104	0.215771491639316	6.490392578125	0.0783447103458457
7.51200008392334	0.22285156592261	6.69646484375	0.0808809563750401
7.71199989318848	0.229589844821021	6.89151806640625	0.0832346486276947
7.91200017929077	0.23647460329812	7.08686083984375	0.0857328559504822
8.11200046539307	0.243115238845348	7.27847314453125	0.0877847560332157
8.3120002746582	0.24951170780696	7.46428955078125	0.0903690815903246
8.51200008392334	0.256347644608468	7.6602216796875	0.0927897417568602
8.71199989318848	0.263183581409976	7.85889111328125	0.094982075097505
8.91199970245361	0.269580079475418	8.0426728515625	0.0975815346464515
9.11200046539307	0.276220700470731	8.2296806640625	0.0999317344394512
9.3120002746582	0.282958993921056	8.423140625	0.102089667052496
9.51200008392334	0.290087889879942	8.6266025390625	0.10451978596393
9.71199989318848	0.29692382668145	8.804607421875	0.106890278402716
9.91199970245361	0.303613283904269	8.9921279296875	0.10909926641034
10.1120004653931	0.309716793708503	9.1628701171875	0.111334629764315
10.3120002746582	0.316406250931323	9.3409873046875	0.113496775156818
10.5120000839233	0.323681626468897	9.54324609375	0.116451585199684
10.7119998931885	0.330224604113027	9.7272119140625	0.118684991321061
10.9119997024536	0.336523429723457	9.9038984375	0.120662632980384
11.1120004653931	0.342578132404014	10.07328515625	0.123019519378431
11.3120002746582	0.348632805980742	10.2417216796875	0.124908445286565
11.5120000839233	0.355712894815952	10.4323125	0.127378385514021
11.7119998931885	0.36293946322985	10.6302451171875	0.129895182908513
11.9119997024536	0.369726563803852	10.814646484375	0.132330242195167
12.1120004653931	0.375927746063098	10.980857421875	0.134636342409067
12.3120002746582	0.38232421502471	11.15671484375	0.136566071887501
12.5120000839233	0.388964836020023	11.3382490234375	0.139251686050557
12.7119998931885	0.395996088627726	11.5294599609375	0.141539901960641
12.9119997024536	0.402978505007923	11.716099609375	0.143918266985565
13.1120004653931	0.409326166845858	11.8853603515625	0.146220889291726
13.3120002746582	0.415624992456287	12.05602734375	0.148147184518166
13.5120000839233	0.422460929257795	12.240091796875	0.150421634316444
13.7119998931885	0.429052743129432	12.4163876953125	0.15300813538488
13.9119997024536	0.435791007475927	12.598	0.155343004735187
14.1120004653931	0.442675780504942	12.7808623046875	0.157892834977247
14.3120002746582	0.449316401500255	12.9562294921875	0.159771996550262
14.5120000839233	0.456445326562971	13.143115234375	0.162062409799546
14.7119998931885	0.463378906715661	13.3229072265625	0.164588578627445
14.9119997024536	0.469921884359792	13.4652783203125	0.166634170454927
15.1120004653931	0.476562505355105	13.592068359375	0.168169237440452
15.3120002746582	0.483203126350418	13.7385546875	0.170257626450621
15.5120000839233	0.490283186081797	13.909453125	0.172329222550616
15.7119998931885	0.496875029057264	14.06951171875	0.174401939148083
15.9119997024536	0.503417977597564	14.22925	0.17652842507232
16.1119995117188	0.50937500782311	14.3707373046875	0.178361107828096
16.3120002746582	0.515966792590916	14.5320439453125	0.1803616178222
16.511999130249	0.523193331900984	14.7101767578125	0.182951407623477
16.7119998931885	0.530029297806323	14.869853515625	0.185376120498404
16.9120006561279	0.536621082574129	15.017978515625	0.18745799025055
17.1119995117188	0.542968744412065	15.159341796875	0.189574115211144
17.3120002746582	0.549267570022494	15.2891572265625	0.192080435226671
17.511999130249	0.556542945560068	15.4420390625	0.194647742318921
17.7119998931885	0.563623034395278	15.5785380859375	0.197595101781189
17.9120006561279	0.570166041143239	15.6994345703125	0.200328300707042
18.1119995117188	0.576171849388629	15.7980732421875	0.202881667064503
18.3120002746582	0.582568347454071	15.907166015625	0.206123033422045
18.511999130249	0.589306640904397	16.0156865234375	0.209555466426536
18.7119998931885	0.596533180214465	16.1309072265625	0.213212944800034
18.9120006561279	0.603564432822168	16.2273056640625	0.216973247006536
19.1119995117188	0.60996093088761	16.3020146484375	0.220801055547781
19.3120002746582	0.616308592725545	16.3709462890625	0.224675459321588
19.511999130249	0.623339845333248	16.458380859375	0.229021548875608
19.7119998931885	0.630029302556068	16.52165234375	0.233368366025388
19.9120006561279	0.637109391391277	16.5934921875	0.237692249356769
20.1119995117188	0.643798848614097	16.64572265625	0.242456590058282
20.3120002746582	0.650244124699384	16.680986328125	0.246761832386255
20.511999130249	0.657080090604722	16.731708984375	0.251146353548393
20.7119998931885	0.663671875372529	16.774580078125	0.255811319220811
20.9120006561279	0.669921864755452	16.811615234375	0.260279863141477
21.1119995117188	0.676513649523258	16.853837890625	0.265348789980635
21.3120002746582	0.683154270518571	16.89251953125	0.269722164375708
21.511999130249	0.690332031808794	16.94472265625	0.275219150353223
21.7119998931885	0.697070325259119	16.94660546875	0.279613333987072
21.9120006561279	0.703662110026926	16.972837890625	0.283994624624029
22.1119995117188	0.709619140252471	16.990013671875	0.28835327248089
22.3120002746582	0.716210925020278	17.03049609375	0.293206074275076
22.511999130249	0.723486300557852	17.0764296875	0.298007566016167
22.7119998931885	0.730273430235684	17.10124609375	0.302991335047409
22.9120006561279	0.73686521500349	17.122212890625	0.307848473312333
23.1119995117188	0.743066426366568	17.137970703125	0.312481017317623
23.3120002746582	0.749169907066971	17.15764453125	0.317043391987681
23.511999130249	0.756445340812206	17.20425390625	0.322265463182703
23.7119998931885	0.763623043894768	17.236333984375	0.327356072375551
23.9120006561279	0.770459009800106	17.256763671875	0.332548021106049
24.1119995117188	0.776708999183029	17.268888671875	0.337608100380749
24.3120002746582	0.783398456405848	17.29212890625	0.342565297614783
24.511999130249	0.790283200331032	17.31877734375	0.347790191881359
24.7119998931885	0.797460961621255	17.350060546875	0.353222858393565
24.9120006561279	0.804296869318932	17.3721484375	0.358663033694029
25.1119995117188	0.810400408226997	17.370265625	0.363578961696476
25.3120002746582	0.816699233837426	17.38591796875	0.368576496839523
25.511999130249	0.823632813990116	17.420462890625	0.37379702553153
25.7119998931885	0.830224598757923	17.430111328125	0.378980010282248
25.9120006561279	0.837304687593132	17.462162109375	0.384232524083927
26.1119995117188	0.843798799905926	17.472015625	0.389554130379111
26.3120002746582	0.850244134198874	17.48333984375	0.394684670027345
26.511999130249	0.857031263876706	17.5021328125	0.399833428673446
26.7119998931885	0.863769557327032	17.520296875	0.40529080433771
26.9120006561279	0.870165997184813	17.53551953125	0.410518201533705
27.1119995117188	0.876855454407632	17.5029921875	0.41463683010079
27.3120002746582	0.883496075402945	17.505619140625	0.419015384977683
27.511999130249	0.890429713763297	17.53133984375	0.423518038587645
27.7119998931885	0.896874989848584	17.543908203125	0.428024010034278
27.9120006561279	0.903271487914026	17.562337890625	0.432639091741294
28.1119995117188	0.909277354367077	17.56851953125	0.437023874837905
28.3120002746582	0.916015647817403	17.59955859375	0.441509939264506
28.511999130249	0.923535146284848	17.6367734375	0.446712045231834
28.7119998931885	0.930468726437539	17.650783203125	0.45204654452391
28.9120006561279	0.937109347432852	17.660330078125	0.457142799859866
29.1119995117188	0.943310558795929	17.664763671875	0.462236057501286
29.3120002746582	0.949462875723839	17.671509765625	0.466981407953426
29.511999130249	0.956835923716426	17.7081796875	0.47244958113879
29.7119998931885	0.963964848779142	17.72809375	0.477788882562891
29.9120006561279	0.97080075647682	17.735404296875	0.483241339679807
30.1119995117188	0.976953073404729	17.729609375	0.488235877128318
30.3120002746582	0.983349629677832	17.74125390625	0.493363942950964
30.511999130249	0.990039086900651	17.76197265625	0.498440465889871
30.7119998931885	0.997168011963367	17.78394140625	0.503951858263463
30.9120006561279	1.0041503701359	17.801244140625	0.50954450853169
31.1119995117188	1.01049803197384	17.79854296875	0.514605781063437
31.3120002746582	1.01699214428663	17.8053203125	0.519678695127368
31.511999130249	1.02402339689434	17.826099609375	0.525380310136825
31.7119998931885	1.03051762562245	17.830138671875	0.53022475913167
31.9120006561279	1.03730463888496	17.843240234375	0.535777769982815
32.1119995117188	1.04350585024804	17.84443359375	0.540959183126688
32.3120002746582	1.04975583963096	17.849220703125	0.546177383512259
32.5120010375977	1.05634762439877	17.866150390625	0.551407691091299
32.7120018005371	1.06308597605675	17.87892578125	0.556578394025564
32.9119987487793	1.06943363789469	17.885666015625	0.561797409318388
33.1119995117188	1.07617187313735	17.897654296875	0.567328068427742
33.3120002746582	1.08291010838002	17.9166328125	0.572870252653956
33.5120010375977	1.0900879278779	17.9322578125	0.578435836359859
33.7120018005371	1.09682616312057	17.9386796875	0.583955028560013
33.9119987487793	1.1036132927984	17.947111328125	0.589710252825171
34.1119995117188	1.10981450416148	17.9448515625	0.594832468777895
34.3120002746582	1.116699189879	17.962439453125	0.600504514295608
34.5120010375977	1.12412113230675	17.98596484375	0.606362416874617
34.7120018005371	1.13076169509441	17.98415625	0.611926021520048
34.9119987487793	1.13715825136751	17.985671875	0.617557496298105
35.1119995117188	1.14335934631526	17.980740234375	0.623112253379077
35.3120002746582	1.14956055767834	17.986994140625	0.627779052592814
35.5120010375977	1.15712895058095	18.02192578125	0.633976422250271
35.7120018005371	1.16435543168336	18.036935546875	0.64015161478892
35.9119987487793	1.17119145579636	18.040294921875	0.645860680378973
36.1119995117188	1.1772948782891	18.027306640625	0.650963454972953
36.3120002746582	1.18374021258205	18.0351875	0.656664196867496
36.5120010375977	1.19047856424004	18.047978515625	0.662097940221429
36.7120018005371	1.19760737288743	18.071150390625	0.667593092657626
36.9119987487793	1.20454106945544	18.07491796875	0.673465430736542
37.1119995117188	1.21064449194819	18.06038671875	0.678768497891724
37.3120002746582	1.21689448133111	18.0627734375	0.684220169205219
37.5120010375977	1.2236328329891	18.077341796875	0.689653330482543
37.7120018005371	1.22998049482703	18.080029296875	0.694719492457807
37.9119987487793	1.23686518054456	18.095771484375	0.700357370078564
38.1119995117188	1.24350585974753	18.103484375	0.705796119291335
38.3120002746582	1.25019531697035	18.115232421875	0.711440283339471
38.5120010375977	1.2572753475979	18.12769140625	0.717329676263034
38.7120018005371	1.26406247727573	18.133	0.723286881111562
38.9119987487793	1.27041013911366	18.126984375	0.728584069292992
39.1119995117188	1.27700192388147	18.13281640625	0.733897730242461
39.3120002746582	1.28354493062943	18.1419609375	0.739559007342905
39.5120010375977	1.29052728880197	18.156462890625	0.745110213756561
39.7120018005371	1.2971191899851	18.158853515625	0.750868988689035
39.9119987487793	1.30366208031774	18.160693359375	0.756421883124858
40.1119995117188	1.3097656192258	18.152185546875	0.761548522859812
40.3120002746582	1.31645507644862	18.166232421875	0.767213641665876
40.5120010375977	1.32387690246105	18.193345703125	0.772984174545854
40.7120018005371	1.33071292657405	18.198486328125	0.779200694523752
40.9119987487793	1.33740238379687	18.196162109375	0.784835370723158
41.1119995117188	1.34370115119964	18.1913203125	0.790557241998613
41.3120002746582	1.35000003501773	18.188708984375	0.796024454757571
41.5120010375977	1.35747075546533	18.22091796875	0.801998423412442
41.7120018005371	1.36425776872784	18.21990234375	0.808257726021111
41.9119987487793	1.37075199745595	18.21498046875	0.814295606687665
42.1119995117188	1.37661129701883	18.2008828125	0.819623819552362
42.3120002746582	1.38295895885676	18.20965625	0.825238472316414
42.5120010375977	1.38964841607958	18.219669921875	0.831323093734682
42.7120018005371	1.39682611916214	18.239177734375	0.837625353597105
42.9119987487793	1.40385737176985	18.24958203125	0.844066496938467
43.1119995117188	1.41010747756809	18.239396484375	0.850590295158327
43.3120002746582	1.4164550229907	18.2349375	0.8845318807289
43.5120010375977	1.42338871955872	18.250208984375	0.889721093699336
43.7120018005371	1.42998050432652	18.253412109375	0.895060715265572
43.9119987487793	1.43701175693423	18.265974609375	0.900506449397653
44.1119995117188	1.44365231972188	18.265396484375	0.906064000446349
44.3120002746582	1.45024410448968	18.265458984375	0.911314389668405
44.5120010375977	1.45703123416752	18.273474609375	0.916806457098573
44.7120018005371	1.46362301893532	18.275923828125	0.922382925637066
44.9119987487793	1.46987300831825	18.2706875	0.927724351640791
45.1119995117188	1.47661135997623	18.279326171875	0.932865543290973
45.3120002746582	1.48339848965406	18.288697265625	0.938434794079512
45.5120010375977	1.49077153764665	18.30312890625	0.944428786169738
45.7120018005371	1.49746099486947	18.306458984375	0.949777429923415
45.9119987487793	1.50410155765712	18.30326171875	0.955414434429258
46.1119995117188	1.51005864609033	18.29031640625	0.960640958510339
46.3120002746582	1.51674810331315	18.2994140625	0.966111198067665
46.5120010375977	1.52407225687057	18.320986328125	0.971783534623682
46.7120018005371	1.53076171409339	18.318810546875	0.977443414740264
46.9119987487793	1.53730472084135	18.3152890625	0.982573721557856
47.1119995117188	1.54340825974941	18.304732421875	0.988142099231482
47.3120002746582	1.54946290422231	18.301001953125	0.992993707768619
47.5120010375977	1.55664060730487	18.32427734375	0.998552073724568
47.7120018005371	1.56367185991257	18.33094140625	1.00425386335701
47.9119987487793	1.57041021157056	18.33228515625	1.00945599842817
48.1119995117188	1.57661130651832	18.323091796875	1.01495778653771
48.3120002746582	1.58320309128612	18.326048828125	1.0202347766608
48.5120010375977	1.58999022096395	18.335755859375	1.02570804301649
48.7120018005371	1.59707036800683	18.348765625	1.03130668867379
48.9119987487793	1.60380860324949	18.35043359375	1.03692419361323
49.1119995117188	1.6099609201774	18.33973828125	1.0419674217701
49.3120002746582	1.61611323710531	18.333763671875	1.0472210124135
49.5120010375977	1.62299803923815	18.34920703125	1.05260848067701
49.7120018005371	1.62968749646097	18.348859375	1.05798267759383
49.9119987487793	1.63666997104883	18.365669921875	1.06401811353862
50.1119995117188	1.64335942827165	18.366255859375	1.06964528094977
50.3120002746582	1.64995121303946	18.3613125	1.07511109672487
50.5120010375977	1.65688479319215	18.374427734375	1.08059076592326
50.7120018005371	1.66372070088983	18.373666015625	1.08645902946591
50.9119987487793	1.67026370763779	18.370373046875	1.09194661490619
51.1119995117188	1.67705083731562	18.373662109375	1.09742896165699
51.3120002746582	1.68378907255828	18.379083984375	1.10299256630242
51.5120010375977	1.69086910318583	18.382173828125	1.10883766319603
51.7120018005371	1.69721676502377	18.3762421875	1.11425796058029
51.9119987487793	1.70361332129687	18.3719140625	1.11960887443274
52.1119995117188	1.70961918774992	18.36153515625	1.12481298856437
52.3120002746582	1.71635742299259	18.372638671875	1.13018229603767
52.5120010375977	1.72382814344019	18.39796875	1.1359826894477
52.7120018005371	1.73071294557303	18.398669921875	1.14175898488611
52.9119987487793	1.73730473034084	18.3915078125	1.14735355600715
53.1119995117188	1.74340815283358	18.3822109375	1.15249003283679
53.3120002746582	1.74956058617681	18.374630859375	1.15757738240063
53.5120010375977	1.75688473973423	18.396376953125	1.16347963921726
53.7120018005371	1.7639648867771	18.404240234375	1.16910540964454
53.9119987487793	1.77070312201977	18.401642578125	1.17482605855912
54.1119995117188	1.77675776649266	18.387169921875	1.17996369954199
54.3120002746582	1.78315432276577	18.387568359375	1.18533161003143
54.5120010375977	1.78979488555342	18.39272265625	1.19082687888294
54.7120018005371	1.79682613816112	18.4067109375	1.19665579404682
54.9119987487793	1.80380861274898	18.414158203125	1.20236317161471
55.1119995117188	1.81025394704193	18.40473828125	1.20771420188248
55.3120002746582	1.81674805935472	18.402875	1.2130931718275
55.5120010375977	1.82382808998227	18.417666015625	1.2187771499157
55.7120018005371	1.83046876918525	18.412197265625	1.22444215230644
55.9119987487793	1.83735357131809	18.41771875	1.23014114797115
56.1119995117188	1.8437011167407	18.40991015625	1.23547622933984
56.3120002746582	1.85009767301381	18.407611328125	1.24098442029208
56.5120010375977	1.85688480269164	18.415408203125	1.24644779134542
56.7120018005371	1.8636230379343	18.41555078125	1.25207740347832
56.9119987487793	1.86992192175239	18.411142578125	1.25751900486648
57.1119995117188	1.87656248454005	18.414328125	1.26277608796954
57.3120002746582	1.88310549128801	18.41828125	1.26852793619037
57.5120010375977	1.89018552191556	18.427609375	1.27413670998067
57.7120018005371	1.89672852866352	18.42190234375	1.27986574079841
57.9119987487793	1.90341798588634	18.42046875	1.28555693663657
58.1119995117188	1.9095215247944	18.411064453125	1.29060121253133
58.3120002746582	1.91630853805691	18.4193203125	1.29625364206731
58.5120010375977	1.9236815860495	18.436205078125	1.30205391906202
58.7120018005371	1.93032226525247	18.43182421875	1.30761822219938
58.9119987487793	1.93666992709041	18.41925390625	1.31324410904199
59.1119995117188	1.94287113845348	18.410015625	1.31837255321443
59.3120002746582	1.94902345538139	18.413427734375	1.323412056081
59.5120010375977	1.95644539780915	18.439646484375	1.32922118064016
59.7120018005371	1.96376955136657	18.44776171875	1.33519608061761
59.9119987487793	1.97065435349941	18.443927734375	1.34122231975198
60.1119995117188	1.97675777599216	18.42643359375	1.34672329295427
60.3120002746582	1.98325188830495	18.423861328125	1.35228887666017
60.5120010375977	1.98999023996294	18.43066015625	1.35779404081404
60.7120018005371	1.99726573191583	18.44578125	1.36376253794879
60.9119987487793	2.00429698452353	18.444212890625	1.36968656443059
61.1119995117188	2.0105957519263	18.43184765625	1.37501256540418
61.3120002746582	2.01689451932907	18.42296484375	1.38039060402662
61.5120010375977	2.02368153259158	18.432998046875	1.38589856214821
61.7120018005371	2.03012698329985	18.42610546875	1.39173783827573
61.9119987487793	2.03706044703722	18.440244140625	1.39713857788593
62.1119995117188	2.04374990426004	18.43795703125	1.40311510767788
62.3120002746582	2.05043936148286	18.439115234375	1.40857778023928
62.5120010375977	2.05742195248604	18.445376953125	1.41420448198915
62.7120018005371	2.06411140970886	18.437455078125	1.42023281659931
62.9119987487793	2.07041017711163	18.428333984375	1.42560235690325
63.1119995117188	2.07695318385959	18.42888671875	1.43117678817362
63.3120002746582	2.08349619060755	18.43065234375	1.43655051942915
63.5120010375977	2.09052744321525	18.441046875	1.44252507016063
63.7120018005371	2.09702155552804	18.4332734375	1.44765945151448
63.9119987487793	2.10361322388053	18.43437109375	1.45321269519627
64.1119995117188	2.10966798476875	18.4208203125	1.45863660145551
64.3119964599609	2.11635744199157	18.4300390625	1.46380730438977
64.5120010375977	2.12373048998415	18.450328125	1.47013680543751
64.7119979858398	2.13056639768183	18.443994140625	1.47593556903303
64.9120025634766	2.13725585490465	18.445564453125	1.48172467015684
65.1119995117188	2.14355462230742	18.433146484375	1.48731272201985
65.3119964599609	2.14985362254083	18.42904296875	1.49263942148536
65.5120010375977	2.15727533213794	18.448201171875	1.49854063056409
65.7119979858398	2.16416013427079	18.446501953125	1.5046299668029
65.9120025634766	2.17065424658358	18.440921875	1.51044817175716
66.1119995117188	2.17661121860147	18.426357421875	1.51556986384094
66.3119964599609	2.18305666930974	18.4260859375	1.5210829442367
66.5120010375977	2.18979502096772	18.439052734375	1.52656016871333
66.7119979858398	2.19711917452514	18.451095703125	1.53269967995584
66.9120025634766	2.20415042713284	18.4531171875	1.53871066868305
67.1119995117188	2.21049808897078	18.439650390625	1.54435238800943
67.3119964599609	2.21679685637355	18.432302734375	1.55000074300915
67.5120010375977	2.22373055294156	18.44059765625	1.5556839061901
67.7119979858398	2.23027332685888	18.435734375	1.56136753503233
67.9120025634766	2.23720702342689	18.43974609375	1.56700983643532
68.1119995117188	2.24370113573968	18.435548828125	1.57273025251925
68.3119964599609	2.25009769201279	18.429435546875	1.57818710431457
68.5120010375977	2.25673825480044	18.431619140625	1.58389541320503
68.7119979858398	2.2632812615484	18.43062109375	1.58946728333831
68.9120025634766	2.26948247291148	18.420921875	1.59493705723435
69.1119995117188	2.2761719301343	18.429330078125	1.60051428247243
69.3119964599609	2.28300783783197	18.432623046875	1.60628836601973
69.5120010375977	2.29033199138939	18.44573046875	1.61226082127541
69.7119979858398	2.29716789908707	18.442337890625	1.6181314131245
69.9120025634766	2.30380869470537	18.435658203125	1.62401725538075
70.1119995117188	2.30981456115842	18.42001953125	1.6293847002089
70.3119964599609	2.31655267998576	18.429107421875	1.63521466311067
70.5120010375977	2.32392572797835	18.445169921875	1.64137175306678
70.7119979858398	2.33076163567603	18.441162109375	1.64708693046123
70.9120025634766	2.33735353685915	18.43494140625	1.65286322589964
71.1119995117188	2.34350585378706	18.42323046875	1.65850785560906
71.3119964599609	2.34965817071497	18.41576953125	1.66374223772436
71.5120010375977	2.35703121870756	18.437126953125	1.66977033950388
71.7119979858398	2.3641602601856	18.4452265625	1.67604361195117
71.9120025634766	2.37099616788328	18.438037109375	1.68196100275964
72.1119995117188	2.37724604085088	18.42452734375	1.68797071091831
72.3119964599609	2.38383794203401	18.4231171875	1.6935879830271
72.5120010375977	2.39067384973168	18.4274140625	1.69931421987712
72.7119979858398	2.39770510233939	18.433078125	1.7053356859833
72.9120025634766	2.40439455956221	18.425	1.71144760679454
73.1119995117188	2.41044932045043	18.40950390625	1.71669060364366
73.3119964599609	2.41660163737833	18.402892578125	1.72237388323992
73.5120010375977	2.42348643951118	18.417166015625	1.72816647682339
73.7119979858398	2.42998055182397	18.412912109375	1.73377292230725
73.9120025634766	2.43701180443168	18.422806640625	1.73965923022479
74.1119995117188	2.44355457834899	18.41877734375	1.74564425833523
74.3119964599609	2.45009758509696	18.4141640625	1.75139494240284
74.5120010375977	2.4569823872298	18.41771484375	1.75721128471196
74.7119979858398	2.46376963332295	18.41756640625	1.7630459042266
74.9120025634766	2.47026374563575	18.409375	1.76879798527807
75.1119995117188	2.47700186446309	18.41518359375	1.77457043901086
75.3119964599609	2.48369132168591	18.413671875	1.78056338336319
75.5120010375977	2.49062501825392	18.418591796875	1.78647972643375
75.7119979858398	2.49702157452703	18.4073515625	1.79221190046519
75.9120025634766	2.50341789796948	18.405943359375	1.79794791620225
76.1119995117188	2.5094726588577	18.389697265625	1.80356344208121
76.3119964599609	2.51621101051569	18.403552734375	1.80915545206517
76.5120010375977	2.5237794034183	18.4215	1.81563838850707
76.7119979858398	2.53081065602601	18.4206328125	1.82188069447875
76.9120025634766	2.53745121881366	18.41704296875	1.82783114723861
77.1119995117188	2.54360353574157	18.4013984375	1.83371885214001
77.3119964599609	2.54975585266948	18.38805859375	1.83937232941389
77.5120010375977	2.55703134462237	18.4073671875	1.84535223525017
77.7119979858398	2.56401370279491	18.40910546875	1.85156578663737
77.9120025634766	2.57060537114739	18.39711328125	1.85758911538869
78.1119995117188	2.57656257599592	18.381998046875	1.86297600157559
78.3119964599609	2.58291023783386	18.38062109375	1.86864880379289
78.5120010375977	2.58940435014665	18.384962890625	1.87414884567261
78.7119979858398	2.59648426435888	18.3945546875	1.88019534107298
78.9120025634766	2.60341796092689	18.394837890625	1.88642740249634
79.1119995117188	2.60996096767485	18.38933203125	1.89217261504382
79.3119964599609	2.61640618555248	18.380041015625	1.89783447422087
79.5120010375977	2.62348633259535	18.38926171875	1.90375884994864
79.7119979858398	2.630126895383	18.389126953125	1.90988485701382
79.9120025634766	2.63706059195101	18.3905546875	1.91596534568816
80.1119995117188	2.64355470426381	18.381822265625	1.92174105904996
80.3119964599609	2.64999992214143	18.374	1.92770571447909
80.5120010375977	2.65683582983911	18.38056640625	1.93370983470231
80.7119979858398	2.6635741814971	18.38018359375	1.93968135863543
80.9120025634766	2.6699707377702	18.368490234375	1.94565486162901
81.1119995117188	2.67675775103271	18.375072265625	1.95161229930818
81.3119964599609	2.68344720825553	18.37630859375	1.95755995810032
81.5120010375977	2.69067380577326	18.383259765625	1.96391623467207
81.7119979858398	2.69736326299608	18.37791796875	1.97002291679382
81.9120025634766	2.7040527202189	18.373908203125	1.97619129903615
82.1119995117188	2.71020503714681	18.35856640625	1.9820926245302
82.3119964599609	2.71713873371482	18.368603515625	1.98824913240969
82.5120010375977	2.72451178170741	18.3760546875	1.99463777244091
82.7119979858398	2.73105478845537	18.364529296875	2.00095749460161
82.9120025634766	2.7374024502933	18.35487109375	2.00676778331399
83.1119995117188	2.74340831674635	18.340927734375	2.01230542734265
83.3119964599609	2.74946284480393	18.333125	2.01780046336353
83.5120010375977	2.75688478723168	18.353396484375	2.02386151067913
83.7119979858398	2.76406249031425	18.362994140625	2.03027599491179
83.9120025634766	2.77080084197223	18.356666015625	2.03632586635649
84.1119995117188	2.77685537002981	18.335509765625	2.04233452677727
84.3119964599609	2.78325192630291	18.33444140625	2.04775296151638
84.5120010375977	2.78994138352573	18.33631640625	2.05391901545227
84.7119979858398	2.79716798104346	18.348189453125	2.06002383492887
84.9120025634766	2.80410167761147	18.347236328125	2.06638942472637
85.1119995117188	2.81040044501424	18.33059765625	2.07243510521948
85.3119964599609	2.81669921241701	18.322580078125	2.07849056459963
85.5120010375977	2.82353512011468	18.33208203125	2.08420935086906
85.7119979858398	2.82993167638779	18.32444921875	2.0900689996779
85.9120025634766	2.83686514012516	18.333861328125	2.09655496291816
86.1119995117188	2.84360349178314	18.331279296875	2.10260995663702
86.3119964599609	2.85029294900596	18.32795703125	2.10906285792589
86.5120010375977	2.85737309604883	18.33036328125	2.11524381302297
86.7119979858398	2.86416010931134	18.322474609375	2.12159450165927
86.9120025634766	2.87050777114928	18.312650390625	2.12779082357883
87.1119995117188	2.8771972283721	18.3108828125	2.13392823934555
87.3119964599609	2.88378912955523	18.308134765625	2.14005168527365
87.5120010375977	2.89086904376745	18.315791015625	2.14651343412697
87.7119979858398	2.89736338891089	18.303662109375	2.15272349305451
87.9120025634766	2.90395505726337	18.2983984375	2.15865788049996
88.1119995117188	2.90986336767673	18.28156640625	2.16473522596061
88.3119964599609	2.91655282489955	18.2862265625	2.17086938209832
88.5120010375977	2.92382808402181	18.30021875	2.17731622979045
88.7119979858398	2.93061533011496	18.294955078125	2.18331604264677
88.9120025634766	2.93725589290261	18.286681640625	2.18970328569412
89.1119995117188	2.94350576587021	18.27334765625	2.19542579725385
89.3119964599609	2.94980476610363	18.26870703125	2.20147962681949
89.5120010375977	2.95722647570074	18.282291015625	2.20792554318905
89.7119979858398	2.96411127783358	18.281447265625	2.21438589505851
89.9120025634766	2.97065428458154	18.26817578125	2.22054170444608
90.1119995117188	2.97661125659943	18.24898828125	2.22637760452926
90.3119964599609	2.98300781287253	18.246642578125	2.23230849951506
90.5120010375977	2.98979482613504	18.252666015625	2.23815091885626
90.7119979858398	2.99702142365277	18.26423046875	2.24478426389396
90.9120025634766	3.00410157069564	18.265640625	2.25151726044714
91.1119995117188	3.01044923253357	18.248427734375	2.25759693421423
91.3119964599609	3.01684578880668	18.23719921875	2.26396648213267
91.5120010375977	3.02382814697921	18.243580078125	2.27030669339001
91.7119979858398	3.03046870976686	18.237830078125	2.27671000175178
91.9120025634766	3.03754885680974	18.2407421875	2.28336011059582
92.1119995117188	3.0440918635577	18.230376953125	2.2894274443388
92.3119964599609	3.05068353191018	18.223298828125	2.29601887986064
92.5120010375977	3.05742188356817	18.219859375	2.30238260701299
92.7119979858398	3.06396489031613	18.212037109375	2.308668801561
92.9120025634766	3.07016610167921	18.200044921875	2.31479946523905
93.1119995117188	3.07680666446686	18.198275390625	2.32107494957745
93.3119964599609	3.08359367772937	18.1982421875	2.32733087614179
93.5120010375977	3.0908202752471	18.20555859375	2.33403663150966
93.7119979858398	3.09746083803475	18.19534765625	2.34036007896066
93.9120025634766	3.10400384478271	18.183330078125	2.34691938385367
94.1119995117188	3.10996104963124	18.160982421875	2.35275737941265
94.3119964599609	3.11660161241889	18.1644921875	2.35876720398664
94.5120010375977	3.12387687154114	18.1750859375	2.3655598051846
94.7119979858398	3.13056632876396	18.166740234375	2.37208418548107
94.9120025634766	3.13710933551192	18.153482421875	2.37826467491686
95.1119995117188	3.14326165243983	18.141619140625	2.3843941744417
95.3119964599609	3.14936530776322	18.128408203125	2.39008385688066
95.5120010375977	3.15664056688547	18.14490625	2.39663477987051
95.7119979858398	3.16367181949317	18.14534765625	2.4030536878854
95.9120025634766	3.17055662162602	18.136609375	2.41013569757342
96.1119995117188	3.1767578329891	18.11777734375	2.41643004119396
96.3119964599609	3.18339839577675	18.113123046875	2.42283823899925
96.5120010375977	3.19028319790959	18.110896484375	2.42940871976316
96.7119979858398	3.19741200655699	18.109697265625	2.43598665110767
96.9120025634766	3.20415035821497	18.102328125	2.44268053211272
97.1119995117188	3.21020511910319	18.084642578125	2.44903075508773
97.3119964599609	3.21645499207079	18.071927734375	2.45520239695907
97.5120010375977	3.22338868863881	18.073296875	2.4620748590678
97.7119979858398	3.23002925142646	18.06565234375	2.46855476871133
97.9120025634766	3.23710939846933	18.068806640625	2.47542466968298
98.1119995117188	3.24370106682181	18.05374609375	2.48202588409185
98.3119964599609	3.25024407356977	18.04428125	2.48866435140371
98.5120010375977	3.25712887570262	18.037806640625	2.49518034979701
98.7119979858398	3.26386722736061	18.0269375	2.50166258774698
98.9120025634766	3.27026378363371	18.012103515625	2.5081941857934
99.1119995117188	3.27700190246105	18.005572265625	2.51472764648497
99.3119964599609	3.28369135968387	17.998478515625	2.52125412225723
99.5120010375977	3.29067371785641	17.99525390625	2.52790166996419
99.7119979858398	3.29707027412951	17.978890625	2.53415713086724
99.9120025634766	3.30351572483778	17.967642578125	2.54081701859832
100.111999511719	3.30952159129083	17.94396875	2.54687527194619
100.311996459961	3.31625971011817	17.94758984375	2.55314260721207
100.512001037598	3.32377920858562	17.957521484375	2.56001949310303
100.71199798584	3.3307617995888	17.9473203125	2.5671748444438
100.912002563477	3.33735346794128	17.930884765625	2.57360260002315
101.111999511719	3.34355467930436	17.907470703125	2.58007063530385
101.311996459961	3.34970699623227	17.89126171875	2.58650933392346
101.512001037598	3.35717783309519	17.90039453125	2.59312451817095
101.71199798584	3.3642090857029	17.89201953125	2.6002258528024
101.912002563477	3.37099609896541	17.876755859375	2.60722846724093
102.111999511719	3.37700196541846	17.8488828125	2.61352560482919
102.311996459961	3.38344718329608	17.833591796875	2.62004253454506
102.512001037598	3.39008797891438	17.82890625	2.62635084800422
102.71199798584	3.39721678756177	17.8296015625	2.63365730643272
102.912002563477	3.40419914573431	17.817138671875	2.64038424938917
103.111999511719	3.41054680757225	17.79330078125	2.64722784049809
103.311996459961	3.41704091988504	17.7779375	2.65374919399619
103.512001037598	3.42402351088822	17.77390625	2.66037648543715
103.71199798584	3.43051762320101	17.7528359375	2.66700424253941
103.912002563477	3.43735353089869	17.74512890625	2.67366389743984
104.111999511719	3.44360340386629	17.7216875	2.68011703155935
104.311996459961	3.44999996013939	17.704353515625	2.68660834990442
104.512001037598	3.45673831179738	17.700802734375	2.6933008339256
104.71199798584	3.46347666345537	17.689306640625	2.70008551888168
104.912002563477	3.4698243252933	17.668427734375	2.70650372840464
105.111999511719	3.47656244412065	17.661759765625	2.71296431310475
105.311996459961	3.48325190134346	17.6456171875	2.72008311003447
105.512001037598	3.4903809428215	17.64265234375	2.72669340483844
105.71199798584	3.49707040004432	17.61908203125	2.73359031416476
105.912002563477	3.50371096283197	17.598765625	2.74028652347624
106.111999511719	3.50986327975988	17.57451171875	2.7469692286104
106.311996459961	3.51665029302239	17.564576171875	2.75368895381689
106.512001037598	3.52397467941046	17.565880859375	2.76101799681783
106.71199798584	3.53061524219811	17.54168359375	2.76798941195011
106.912002563477	3.53701179847121	17.516482421875	2.77460901997983
107.111999511719	3.54316411539912	17.4898515625	2.7810144238174
107.311996459961	3.54931643232703	17.472314453125	2.78733903542161
107.512001037598	3.55678703635931	17.4797734375	2.79460824094713
107.71199798584	3.56401363387704	17.469232421875	2.80179805122316
107.912002563477	3.57089843600988	17.444537109375	2.80895549803972
108.111999511719	3.57705075293779	17.407744140625	2.81586404889822
108.311996459961	3.58354486525059	17.387525390625	2.8227255679667
108.512001037598	3.59028321690857	17.37514453125	2.82944366335869
108.71199798584	3.59741202555597	17.364427734375	2.83659878186882
108.912002563477	3.60429682768881	17.346041015625	2.84385262057185
109.111999511719	3.61049803905189	17.314330078125	2.85053998231888
109.311996459961	3.61669925041497	17.285841796875	2.85692233592272
109.512001037598	3.62343760207295	17.278595703125	2.86378571763635
109.71199798584	3.62988281995058	17.2519296875	2.87017179653049
109.912002563477	3.63671872764826	17.244640625	2.87727080285549
110.111999511719	3.64340818487108	17.22540625	2.88407877087593
110.311996459961	3.65000008605421	17.203521484375	2.8909167740494
110.512001037598	3.65703133866191	17.189384765625	2.89764604531229
110.71199798584	3.66381835192442	17.16983203125	2.90490756742656
110.912002563477	3.67021490819752	17.141173828125	2.91154556907713
111.111999511719	3.67685547098517	17.120888671875	2.91863479651511
111.311996459961	3.6834473721683	17.098806640625	2.9252867680043
111.512001037598	3.69052728638053	17.0896484375	2.93220928870142
111.71199798584	3.69711918756366	17.06040625	2.93935975059867
111.912002563477	3.70375975035131	17.038453125	2.94637819752097
112.111999511719	3.70981451123953	17.006552734375	2.95302993617952
112.311996459961	3.71660152450204	16.994998046875	2.95986421406269
112.512001037598	3.72407236136496	16.989146484375	2.9671483207494
112.71199798584	3.73095693066716	16.962291015625	2.97468109056354
112.912002563477	3.73769528232515	16.9364453125	2.98203458078206
113.111999511719	3.74394538812339	16.898328125	2.98886396922171
113.311996459961	3.75034171156585	16.874810546875	2.99540557898581
113.512001037598	3.75776365399361	16.87334765625	3.00251063890755
113.71199798584	3.76450200565159	16.846716796875	3.00990557298064
113.912002563477	3.77080077305436	16.806451171875	3.01681878045201
114.111999511719	3.77666018903255	16.7708828125	3.02327470853925
114.311996459961	3.78300785087049	16.758822265625	3.02970595657825
114.512001037598	3.78964841365814	16.744130859375	3.03668831475079
114.71199798584	3.79687501117587	16.735732421875	3.0438369140029
114.912002563477	3.80385736934841	16.71405078125	3.05099366232753
115.111999511719	3.81020503118634	16.675859375	3.05800978094339
115.311996459961	3.81650379858911	16.646634765625	3.06465080939233
115.512001037598	3.82343749515712	16.63279296875	3.07144992984831
115.71199798584	3.83007805794477	16.60670703125	3.07850004173815
115.912002563477	3.83706064894795	16.592830078125	3.0854232609272
116.111999511719	3.84365231730044	16.562302734375	3.09233693405986
116.311996459961	3.85014642961323	16.533705078125	3.09934094548225
116.512001037598	3.85688478127122	16.51370703125	3.1063340138644
116.71199798584	3.86352534405887	16.488396484375	3.1135065946728
116.912002563477	3.86987300589681	16.460255859375	3.12034226953983
117.111999511719	3.87661135755479	16.4415703125	3.12720378860831
117.311996459961	3.88349615968764	16.421921875	3.13456077128649
117.512001037598	3.89086920768023	16.402345703125	3.14191938377917
117.71199798584	3.89765622094274	16.3768896484375	3.14958323724568
117.912002563477	3.90434567816556	16.3434892578125	3.15643684007227
118.111999511719	3.91035154461861	16.298232421875	3.1632783357054
118.311996459961	3.91713855788112	16.2823447265625	3.17047722637653
118.512001037598	3.92451183870435	16.2717548828125	3.17772943526506
118.71199798584	3.93110373988748	16.23674609375	3.18504520691931
118.912002563477	3.93764628097415	16.20210546875	3.19205457344651
119.111999511719	3.94370127469301	16.1680546875	3.19859082810581
119.311996459961	3.94970690831542	16.1382548828125	3.20498854853213
119.512001037598	3.95703129470348	16.1390419921875	3.2120996620506
119.71199798584	3.96401388570666	16.11315234375	3.21935676038265
119.912002563477	3.97080089896917	16.0835400390625	3.22666927240789
120.111999511719	3.97695321589708	16.0431796875	3.23327980004251
120.311996459961	3.98349622264504	16.0159345703125	3.24048241600394
120.512001037598	3.99028323590755	15.9962958984375	3.24738444760442
120.71199798584	3.99741204455495	15.976193359375	3.25464247725904
120.912002563477	4.00419905781746	15.942205078125	3.26193263754249
121.111999511719	4.01030294597149	15.89721875	3.26868984848261
121.311996459961	4.01655258610845	15.861646484375	3.27549385838211
121.512001037598	4.02343738824129	15.844537109375	3.28282476402819
121.71199798584	4.03002928942442	15.8099033203125	3.28994216397405
121.912002563477	4.03706077486277	15.781923828125	3.29735456034541
122.111999511719	4.04374999925494	15.730982421875	3.30507243052125
122.311996459961	4.0502930060029	15.684791015625	3.31237842328846
122.512001037598	4.05722670257092	15.6416533203125	3.32004460506141
122.71199798584	4.06406261026859	15.560353515625	3.32853966392577
122.912002563477	4.07065451145172	15.43672265625	3.33708222024143
123.111999511719	4.07744152471423	15.3322353515625	3.3459379337728
123.311996459961	4.08417964354157	15.2017421875	3.35498573258519
123.512001037598	4.09121112897992	14.5828876953125	3.37224919348955
123.527000427246	4.09223651513457	-1.57614135742188	3.73497023247182