File: data/rawdata4.txt
File Path: C:\2024\20240314 CTLbio tensile\Test Run 4 03-14-24 16 22 53 PM\DAQ- Time, … - (Timed).txt
Test: CTLbio_tensile_EC5AA
Test Run: Test Run 4
Date: 3/14/2024 4:15:37 PM


Time 	Crosshead 	Load 	Extensometer
sec	mm	kN	mm
0.915000021457672	0.001416015606992	0.0284798717498779	0.000464312080339369
1.11500000953674	0.00429687497671694	0.0921759033203125	0.00121123810004065
1.31500005722046	0.00971679673966719	0.262589233398437	0.00303120646094612
1.51499998569489	0.0167968755704351	0.488920349121094	0.00586560508963885
1.7150000333786	0.0242187506955815	0.722501831054687	0.00835433183965506
1.91499996185303	0.0309082024614327	0.94369580078125	0.0108792273749714
2.11500000953674	0.0377441392629407	1.16436853027344	0.0133570474645239
2.31500005722046	0.0452148451586254	1.39404248046875	0.0161580592248356
2.51500010490417	0.052197265176801	1.6154990234375	0.0186671386472881
2.71499991416931	0.0598632796027232	1.8585263671875	0.0217212273128098
2.91499996185303	0.0667480489937589	2.07474389648437	0.0242232181335567
3.11500000953674	0.073876952228602	2.29742431640625	0.0267821942543378
3.31500005722046	0.0813476581242867	2.53596508789063	0.0296269317914266
3.51500010490417	0.0881835949257948	2.74989526367187	0.0321232801070437
3.71499991416931	0.0948730448726565	2.95980249023438	0.0347657150996383
3.91499996185303	0.101806639577262	3.18238330078125	0.037590813008137
4.11499977111816	0.108740234281868	3.40596752929688	0.0400639764848165
4.31500005722046	0.115625000034925	3.6235244140625	0.0427958220825531
4.5149998664856	0.122167970403098	3.825203125	0.0454586079285946
4.71500015258789	0.128515632241033	4.01255322265625	0.0478004185424652
4.91499996185303	0.134814457851462	4.208287109375	0.049855763791129
5.11499977111816	0.142285149195231	4.440712890625	0.0527381707797758
5.31500005722046	0.14951171760913	4.6621328125	0.0555019214516506
5.5149998664856	0.156298832735047	4.8721572265625	0.0578954350203276
5.71500015258789	0.162841795827262	5.06934912109375	0.0606379508099053
5.91499996185303	0.169042963534594	5.26104638671875	0.0627089830231853
6.11499977111816	0.176025394466706	5.47146630859375	0.0652030576020479
6.31500005722046	0.183251948328689	5.68686474609375	0.0678018186590634
6.5149998664856	0.189892583875917	5.88515478515625	0.0704977137502283
6.71500015258789	0.196044915355742	6.07047705078125	0.0724471465218812
6.91499996185303	0.20229491929058	6.2579560546875	0.0746989098843187
7.11499977111816	0.208886718610302	6.45267578125	0.0773348729126155
7.31500005722046	0.215917971218005	6.66410791015625	0.0798522669356316
7.5149998664856	0.222998045501299	6.872373046875	0.0824421149445698
7.71500015258789	0.229589844821021	7.06950537109375	0.0848283962113783
7.91499996185303	0.23588867043145	7.255859375	0.0870969161042012
8.11499977111816	0.242822265136056	7.457	0.0893697433639318
8.3149995803833	0.249609380261973	7.65872900390625	0.0920791862881742
8.51500034332275	0.256445317063481	7.858595703125	0.0944923813221976
8.71500015258789	0.263183581409976	8.05339306640625	0.0966837978921831
8.91499996185303	0.269628915702924	8.232009765625	0.0990786647889763
9.11499977111816	0.276318372925743	8.4198505859375	0.101283898402471
9.3149995803833	0.283203116850927	8.616150390625	0.103802696685307
9.51500034332275	0.289501942461357	8.801326171875	0.106180894363206
9.71500015258789	0.296044920105487	8.988173828125	0.108514599560294
9.91499996185303	0.302880856906995	9.19130859375	0.111087021650746
10.1149997711182	0.310009752865881	9.39715234375	0.113511727249715
10.3149995803833	0.316943362122402	9.59916796875	0.11564254964469
10.5150003433228	0.323632819345221	9.7883056640625	0.118274183478206
10.7150001525879	0.329785165376961	9.9611884765625	0.120159915240947
10.914999961853	0.336181634338573	10.1425390625	0.122430486953817
11.1149997711182	0.343359366524965	10.34227734375	0.125094476970844
11.3149995803833	0.350146496202797	10.536880859375	0.12747485016007
11.5150003433228	0.356542965164408	10.7151845703125	0.129695705254562
11.7150001525879	0.362841790774837	10.89457421875	0.131750624859706
11.914999961853	0.368847657227889	11.0578095703125	0.134109504870139
12.1149997711182	0.375781237380579	11.2514580078125	0.136325543280691
12.3149995803833	0.383007805794477	11.452904296875	0.138733710628003
12.5150003433228	0.38979493547231	11.6423408203125	0.14093927165959
12.7150001525879	0.396142568206415	11.8144599609375	0.143258293974213
12.914999961853	0.402587902499363	11.994146484375	0.145616999361664
13.1149997711182	0.409375003073364	12.1781806640625	0.147742612170987
13.3149995803833	0.416406255681068	12.369857421875	0.150235180626623
13.5150003433228	0.423388672061265	12.559900390625	0.1524904218968
13.7150001525879	0.4297363338992	12.7360146484375	0.155057205120102
13.914999961853	0.435937487054616	12.9030986328125	0.15691424778197
14.1149997711182	0.442773423856124	13.088634765625	0.159246235853061
14.3149995803833	0.449462881078944	13.2699462890625	0.161630581715144
14.5150003433228	0.456298817880452	13.411451171875	0.163253062055446
14.7150001525879	0.46313475468196	13.5345986328125	0.164787285029888
14.914999961853	0.469726568553597	13.69373046875	0.16700268315617
15.1149997711182	0.476562505355105	13.86761328125	0.168912316439673
15.3149995803833	0.483544921735302	14.047533203125	0.171340143424459
15.5150003433228	0.489990226924419	14.2096162109375	0.173597451066598
15.7150001525879	0.496679684147239	14.384548828125	0.175752764334902
15.914999961853	0.503369141370058	14.5487744140625	0.177963898750022
16.1149997711182	0.510351557750255	14.7209765625	0.180123126483522
16.3150005340576	0.516894506290555	14.8796572265625	0.1824736391427
16.5149993896484	0.523291004355997	15.027005859375	0.184470030944794
16.7150001525879	0.529345707036555	15.1614765625	0.186544755706564
16.9150009155273	0.535742205101997	15.3051005859375	0.188703284948133
17.1149997711182	0.543066416867077	15.462173828125	0.191323619219474
17.3150005340576	0.550048833247274	15.60455078125	0.194040287169628
17.5149993896484	0.556689454242587	15.7349384765625	0.196394408703782
17.7150001525879	0.562988279853016	15.85090625	0.198861176613718
17.9150009155273	0.569091818761081	15.9560166015625	0.201460934476927
18.1149997711182	0.576074235141277	16.079923828125	0.204611395020038
18.3150005340576	0.583349610678852	16.19934375	0.207837932975963
18.5149993896484	0.590136740356684	16.29390234375	0.211281207157299
18.7150001525879	0.596386729739606	16.3765849609375	0.214311396121047
18.9150009155273	0.602832005824894	16.45681640625	0.217939130379818
19.1149997711182	0.609472685027868	16.538416015625	0.221797774429433
19.3150005340576	0.616601551882923	16.623228515625	0.226004223804921
19.5149993896484	0.623681640718132	16.697478515625	0.230246791034006
19.7150001525879	0.630273425485939	16.752130859375	0.234645485761575
19.9150009155273	0.636767596006393	16.801876953125	0.238699984038249
20.1149997711182	0.643847684841603	16.86615625	0.243880858761258
20.3150005340576	0.650585920084268	16.90769921875	0.248615600867197
20.5149993896484	0.657421885989606	16.92491015625	0.25324898888357
20.7150001525879	0.6639159983024	16.9283125	0.256979692494497
20.9150009155273	0.670263660140336	16.961146484375	0.260819244431332
21.1149997711182	0.677001953590661	17.0011171875	0.265186041360721
21.3150005340576	0.683691410813481	17.037802734375	0.269408075837418
21.5149993896484	0.68999023642391	17.0633515625	0.274049903964624
21.7150001525879	0.69653318496421	17.107810546875	0.278762745438144
21.9150009155273	0.703125027939677	17.09901171875	0.282864086329937
22.1149997711182	0.710107444319874	17.1181171875	0.286636204691604
22.3150005340576	0.716894515790045	17.140076171875	0.290637195575982
22.5149993896484	0.723535136785358	17.1643671875	0.294931960524991
22.7150001525879	0.729736348148435	17.18338671875	0.299113249639049
22.9150009155273	0.736279296688735	17.21265234375	0.303217122564092
23.1149997711182	0.743603508453816	17.258533203125	0.307990849250928
23.3150005340576	0.750390638131648	17.2808046875	0.312674470478669
23.5149993896484	0.75678713619709	17.299888671875	0.317169062327594
23.7150001525879	0.763085961807519	17.31578125	0.321570871165022
23.9150009155273	0.769189442507923	17.330724609375	0.326180917909369
24.1149997711182	0.776464818045497	17.372271484375	0.330955925164744
24.3150005340576	0.78388670226559	17.410130859375	0.336452358169481
24.5149993896484	0.790820340625942	17.424677734375	0.341738399583846
24.7150001525879	0.797070330008864	17.4307890625	0.346692657331005
24.9150009155273	0.803515606094152	17.44712109375	0.351487746229395
25.1149997711182	0.810302735771984	17.472359375	0.356741773430258
25.3150005340576	0.817480497062206	17.50153515625	0.362093735020608
25.5149993896484	0.824511691462249	17.524234375	0.367451459169388
25.7150001525879	0.830859353300184	17.526330078125	0.372663809685037
25.9150009155273	0.837158178910613	17.53687109375	0.377564661903307
26.1149997711182	0.843945308588445	17.561412109375	0.382768281269819
26.3150005340576	0.850390642881393	17.57260546875	0.388244166970253
26.5149993896484	0.857177714351565	17.595361328125	0.39334362372756
26.7150001525879	0.863818335346878	17.607146484375	0.398294941987842
26.9150009155273	0.870410178322345	17.623318359375	0.403445912525058
27.1149997711182	0.877246086020023	17.644296875	0.408795254770666
27.3150005340576	0.884082051925361	17.65924609375	0.414125854149461
27.5149993896484	0.890332041308284	17.66316796875	0.419602263718843
27.7150001525879	0.896826153621078	17.676619140625	0.424517580540851
27.9150009155273	0.903369160369039	17.69373828125	0.429354549851269
28.1149997711182	0.910302740521729	17.716720703125	0.434886693255976
28.3150005340576	0.916894525289536	17.72676953125	0.440086238086224
28.5149993896484	0.923486310057342	17.7384140625	0.44540996896103
28.7150001525879	0.929638685192913	17.741228515625	0.450212770374492
28.9150009155273	0.936132797505707	17.756060546875	0.45503830187954
29.1149997711182	0.943408231250942	17.790318359375	0.460605340776965
29.3150005340576	0.950390647631139	17.806798828125	0.466255180072039
29.5149993896484	0.956982432398945	17.81032421875	0.471749663120136
29.7150001525879	0.963427708484232	17.814958984375	0.477061548735946
29.9150009155273	0.969677756074816	17.82337890625	0.482057657791302
30.1149997711182	0.977001967839897	17.854638671875	0.487639772472903
30.3150005340576	0.984130892902613	17.86824609375	0.493228377308697
30.5149993896484	0.990820350125432	17.872130859375	0.498504436109215
30.7150001525879	0.996826216578484	17.8673203125	0.503509771078825
30.9150009155273	1.00322265643626	17.875701171875	0.508583209011704
31.1149997711182	1.00986333563924	17.893826171875	0.513880571816117
31.3150005340576	1.01708981674165	17.91681640625	0.519262801390141
31.5149993896484	1.02412106934935	17.925435546875	0.524928444065154
31.7150001525879	1.03041995316744	17.920177734375	0.530046061612666
31.9150009155273	1.03666994255036	17.9284140625	0.535056809894741
32.1150016784668	1.04355474468321	17.94573046875	0.540178210940212
32.314998626709	1.05014652945101	17.953041015625	0.545352406334132
32.5149993896484	1.05693354271352	17.9681953125	0.550541619304568
32.7150001525879	1.0635742219165	17.9718125	0.555620703380555
32.9150009155273	1.07001955620944	17.98054296875	0.560830696485937
33.1150016784668	1.0766601189971	17.9925390625	0.565811758860946
33.314998626709	1.08339847065508	18.004158203125	0.571469368878752
33.5149993896484	1.08959956560284	18.00640625	0.576540653128177
33.7150001525879	1.09624024480581	18.018533203125	0.581654720008373
33.9150009155273	1.10307615250349	18.036642578125	0.587023096159101
34.1150016784668	1.11035152804106	18.057501953125	0.592610624153167
34.314998626709	1.11723633017391	18.064162109375	0.598232436459512
34.5149993896484	1.12387700937688	18.065876953125	0.603579508606344
34.7150001525879	1.13002932630479	18.06033203125	0.608886650297791
34.9150009155273	1.13657221663743	18.069732421875	0.614150892943144
35.1150016784668	1.14384770859033	18.098041015625	0.619497732259333
35.314998626709	1.15078128874302	18.107712890625	0.625185377430171
35.5149993896484	1.15727540105581	18.105	0.630573078524321
35.7150001525879	1.16362306289375	18.105291015625	0.635673757642508
35.9150009155273	1.16972660180181	18.103724609375	0.640589219983667
36.1150016784668	1.17695308290422	18.13044921875	0.646194210276008
36.314998626709	1.18417968042195	18.148408203125	0.651928363367915
36.5149993896484	1.19101558811963	18.1531484375	0.657472119200975
36.7150001525879	1.1972167994827	18.14054296875	0.66287606023252
36.9150009155273	1.2037109117955	18.14741015625	0.668058579321951
37.1150016784668	1.21040036901832	18.1585078125	0.673310365527868
37.314998626709	1.21743162162602	18.173125	0.678846088703722
37.5149993896484	1.22412107884884	18.17821484375	0.684121157974005
37.7150001525879	1.23017572332174	18.172125	0.689378997776657
37.9150009155273	1.23623048420995	18.169337890625	0.694383343216032
38.1150016784668	1.24301761388779	18.18742578125	0.699579191859812
38.314998626709	1.24965817667544	18.19693359375	0.704883772414178
38.5149993896484	1.25649408437312	18.207953125	0.710199878085405
38.7150001525879	1.26328121405095	18.213521484375	0.715636822860688
38.9150009155273	1.26977544277906	18.21937890625	0.720852403901517
39.1150016784668	1.27656245604157	18.227224609375	0.726298487279564
39.314998626709	1.28349603619426	18.237125	0.731698994059116
39.5149993896484	1.28999026492238	18.2356953125	0.736972608137876
39.7150001525879	1.29677739460021	18.245998046875	0.742599891964346
39.9150009155273	1.30351562984288	18.250607421875	0.747880956623703
40.1150016784668	1.31059566047043	18.266625	0.753700151108205
40.314998626709	1.31713866721839	18.263943359375	0.758984009735286
40.5149993896484	1.32363277953118	18.2656015625	0.764336495194584
40.7150001525879	1.32978521287441	18.25819140625	0.769430596847087
40.9150009155273	1.33647455368191	18.271337890625	0.775093911215663
41.1150016784668	1.34404294658452	18.299951171875	0.780799484346062
41.314998626709	1.35112309362739	18.303923828125	0.786987657193094
41.5149993896484	1.35786132887006	18.30387109375	0.792424194514751
41.7150001525879	1.36406254023314	18.290302734375	0.797647226136178
41.9150009155273	1.37011718470603	18.28440234375	0.802842492703348
42.1150016784668	1.37724610976875	18.309279296875	0.80814107786864
42.314998626709	1.38422846794128	18.31586328125	0.813946011476219
42.5149993896484	1.39082036912441	18.316396484375	0.81946182763204
42.7150001525879	1.39682611916214	18.3076171875	0.824395508971065
42.9150009155273	1.40312500298023	18.308275390625	0.829513010103256
43.1150016784668	1.40961911529303	18.319048828125	0.834707985632122
43.314998626709	1.41660158988088	18.33808203125	0.83994580199942
43.5149993896484	1.42358394805342	18.347283203125	0.845557427965105
43.7150001525879	1.43017573282123	18.347716796875	0.851088669151068
43.9150009155273	1.43657228909433	18.341775390625	0.856559141539037
44.1150016784668	1.44370121415704	18.35678515625	0.861932931002229
44.314998626709	1.45043944939971	18.35959375	0.867712136823684
44.5149993896484	1.45732425153255	18.36358984375	0.873078999575227
44.7150001525879	1.46381836384535	18.360068359375	0.878519203979522
44.9150009155273	1.4702636981383	18.363109375	0.884056556969881
45.1150016784668	1.47700193338096	18.367142578125	0.889203685801476
45.314998626709	1.48383784107864	18.376236328125	0.894966360647231
45.5149993896484	1.49018550291657	18.373482421875	0.900227460078895
45.7150001525879	1.49692385457456	18.3812109375	0.905636115930974
45.9150009155273	1.50361331179738	18.388556640625	0.911057228222489
46.1150016784668	1.5107422368601	18.3976484375	0.916891847737134
46.314998626709	1.51748047210276	18.398931640625	0.922045903280377
46.5149993896484	1.52416992932558	18.39808984375	0.928060559090227
46.7150001525879	1.53037114068866	18.39228515625	0.933330622501671
46.9150009155273	1.53715815395117	18.400361328125	0.938885088544339
47.1150016784668	1.54443364590406	18.417462890625	0.944639381486923
47.314998626709	1.55102543067187	18.4104765625	0.950014509726316
47.5149993896484	1.55727542005479	18.40277734375	0.955441792029887
47.7150001525879	1.56337895896286	18.396990234375	0.960541889071465
47.9150009155273	1.56938470900059	18.395234375	0.965547922533005
48.1150016784668	1.5765136340633	18.41794921875	0.97104231826961
48.314998626709	1.58374023158103	18.434744140625	0.976720242761075
48.5149993896484	1.59052736125886	18.434431640625	0.982228899374604
48.7150001525879	1.59663090016693	18.42228125	0.987866544164717
48.9150009155273	1.60302734002471	18.42204296875	0.992853078059852
49.1150016784668	1.60961912479252	18.429345703125	0.998451840132475
49.314998626709	1.61674804985523	18.4470703125	1.00387388374656
49.5149993896484	1.62373052444309	18.4551796875	1.00970116909593
49.7150001525879	1.63017574232072	18.4492265625	1.01545837242156
49.9150009155273	1.63637695368379	18.44026953125	1.0207126615569
50.1150016784668	1.64311518892646	18.448140625	1.02621270343661
50.314998626709	1.64970697369426	18.449865234375	1.03160657454282
50.5149993896484	1.6564941033721	18.459833984375	1.03721930645406
50.7150001525879	1.66342768352479	18.464525390625	1.04306649882346
50.9150009155273	1.67011714074761	18.47498828125	1.0488141560927
51.1150016784668	1.67714839335531	18.47948046875	1.05470768176019
51.314998626709	1.684081973508	18.479052734375	1.06058886740357
51.5149993896484	1.69052730780095	18.46884375	1.06608599890023
51.7150001525879	1.69721676502377	18.47229296875	1.07154936995357
51.9150009155273	1.70385744422674	18.4692890625	1.07718608342111
52.1150016784668	1.71098636928946	18.4818046875	1.08326179906726
52.314998626709	1.71748048160225	18.472931640625	1.08887325040996
52.5149993896484	1.72407226637006	18.473755859375	1.09406537376344
52.7150001525879	1.73007813282311	18.461033203125	1.09964865259826
52.9150009155273	1.7365722451359	18.471703125	1.10476731788367
53.1150016784668	1.74384762067348	18.489669921875	1.11081078648567
53.314998626709	1.75068364478648	18.495841796875	1.11638091038913
53.5149993896484	1.75722653511912	18.489935546875	1.12206069752574
53.7150001525879	1.76362309139222	18.480744140625	1.12744024954736
53.9150009155273	1.76987308077514	18.478091796875	1.13284715916961
54.1150016784668	1.77714845631272	18.4968203125	1.13837700337172
54.314998626709	1.78422848694026	18.503599609375	1.14420300815254
54.5149993896484	1.79082027170807	18.49980078125	1.14980898797512
54.7150001525879	1.79682613816112	18.486369140625	1.15524034481496
54.9150009155273	1.80317379999906	18.488802734375	1.16053619422019
55.1150016784668	1.80986325722188	18.495005859375	1.16612459532917
55.314998626709	1.81708985473961	18.51346875	1.17217691149563
55.5149993896484	1.82416988536716	18.520353515625	1.17776799015701
55.7150001525879	1.83056644164026	18.51073046875	1.18331331759691
55.9150009155273	1.83686520904303	18.504056640625	1.18904549162835
56.1150016784668	1.84379878919572	18.5140546875	1.19460502173752
56.314998626709	1.8505371408537	18.513341796875	1.20037735905498
56.5149993896484	1.85751949902624	18.523140625	1.20634795166552
56.7150001525879	1.86420895624906	18.51841015625	1.21177500113845
56.9150009155273	1.87070306856185	18.51381640625	1.2176176533103
57.1150016784668	1.87744142021984	18.518642578125	1.22334412299097
57.314998626709	1.88408198300749	18.521798828125	1.22919457498938
57.5149993896484	1.89028319437057	18.511134765625	1.23455945868045
57.7150001525879	1.89682620111853	18.513546875	1.23984494712204
57.9150009155273	1.90346676390618	18.518505859375	1.24544149730355
58.1150016784668	1.9105956889689	18.53418359375	1.25142745673656
58.314998626709	1.91728514619172	18.533173828125	1.25715625472367
58.5149993896484	1.92387693095952	18.531318359375	1.26263441052288
58.7150001525879	1.92983401939273	18.5149375	1.26801722217351
58.9150009155273	1.93627935368568	18.51735546875	1.27339467871934
59.1150016784668	1.94350583478808	18.533150390625	1.27926096320152
59.314998626709	1.95039063692093	18.540025390625	1.28500629216433
59.5149993896484	1.95688474923372	18.533193359375	1.29043916240335
59.7150001525879	1.96323241107166	18.525287109375	1.29598320927471
59.9150009155273	1.9693358335644	18.5203359375	1.30156858358532
60.1150016784668	1.97641598060727	18.53682421875	1.30713649559766
60.314998626709	1.98369147256017	18.551396484375	1.31316226907074
60.5149993896484	1.99062493629754	18.551681640625	1.31907581817359
60.7150001525879	1.99692393653095	18.538931640625	1.32461439352483
60.9150009155273	2.0035644993186	18.538728515625	1.33021909277886
61.1150016784668	2.01044930145144	18.543603515625	1.33577489759773
61.314998626709	2.01757811009884	18.554654296875	1.34220102336258
61.5149993896484	2.02446291223168	18.554068359375	1.34794891346246
61.7150001525879	2.03071278519928	18.538736328125	1.35357980616391
61.9150009155273	2.03691399656236	18.53325390625	1.35923933703452
62.1150016784668	2.04384769313037	18.54514453125	1.3651514891535
62.314998626709	2.05048825591803	18.54740234375	1.37072498910129
62.5149993896484	2.05742195248604	18.552587890625	1.37646973598748
62.7150001525879	2.06406251527369	18.548609375	1.38236931525171
62.9150009155273	2.07055662758648	18.544490234375	1.38818996492773
63.1150016784668	2.0772460848093	18.547763671875	1.3937430921942
63.314998626709	2.08408199250698	18.549583984375	1.39922404196113
63.5149993896484	2.09038075990975	18.544681640625	1.40492420177907
63.7150001525879	2.09697266109288	18.542033203125	1.41048419754952
63.9150009155273	2.10361322388053	18.54252734375	1.41643814276904
64.1149978637695	2.11049802601337	18.549375	1.42201618291438
64.3150024414063	2.11699213832617	18.542869140625	1.42762798350304
64.5149993896484	2.1233398001641	18.540623046875	1.43328413832933
64.7149963378906	2.12944345548749	18.535935546875	1.43830105662346
64.9150009155273	2.13593756780028	18.540916015625	1.44383811857551
65.1149978637695	2.14335927739739	18.56126171875	1.44971464760602
65.3150024414063	2.15048831887543	18.5697109375	1.45609513856471
65.5149993896484	2.15712888166308	18.561234375	1.46178994327784
65.7149963378906	2.16342764906585	18.551037109375	1.46737752947956
65.9150009155273	2.16957996599376	18.541654296875	1.47282937541604
66.1149978637695	2.17675790190697	18.558994140625	1.47874723188579
66.3150024414063	2.18393560498953	18.57029296875	1.48481572978199
66.5149993896484	2.19077151268721	18.5655390625	1.49095489177853
66.7149963378906	2.19702138565481	18.552228515625	1.49675493594259
66.9150009155273	2.20341794192791	18.549611328125	1.50209211278707
67.1149978637695	2.21005850471556	18.558291015625	1.50811742059886
67.3150024414063	2.21713865175843	18.570150390625	1.51413131970912
67.5149993896484	2.22416990436614	18.5723515625	1.52039958629757
67.7149963378906	2.23066401667893	18.557498046875	1.52611511293799
67.9150009155273	2.2371094673872	18.552529296875	1.53162190690637
68.1149978637695	2.2441407199949	18.5589296875	1.53750274330378
68.3150024414063	2.25073238834739	18.56141796875	1.54349894728512
68.5149993896484	2.25751963444054	18.5574921875	1.54926651157439
68.7149963378906	2.26381840184331	18.55324609375	1.55506609007716
68.9150009155273	2.27006827481091	18.543490234375	1.56045728363097
69.1149978637695	2.27661128155887	18.54506640625	1.56618980690837
69.3150024414063	2.28339852765203	18.553083984375	1.57206680160016
69.5149993896484	2.28969729505479	18.547724609375	1.57738907728344
69.7149963378906	2.29638675227761	18.5530234375	1.58319971524179
69.9150009155273	2.3031251039356	18.553638671875	1.58905237913132
70.1149978637695	2.31025391258299	18.56874609375	1.59521936438978
70.3150024414063	2.31708982028067	18.566939453125	1.60112755838782
70.5149993896484	2.32387706637383	18.56316796875	1.60704483278096
70.7149963378906	2.33012693934143	18.54762890625	1.61259260494262
70.9150009155273	2.33686529099941	18.5561640625	1.61856564227492
71.1149978637695	2.344238338992	18.569859375	1.62467814516276
71.3150024414063	2.35097645781934	18.57094140625	1.63091288413852
71.5149993896484	2.35737301409245	18.55762109375	1.63676007650793
71.7149963378906	2.36362311989069	18.5454765625	1.64259073790163
71.9150009155273	2.36972654238343	18.5397578125	1.64821860380471
72.1149978637695	2.37709959037602	18.560970703125	1.6539222560823
72.3150024414063	2.38442374393344	18.568376953125	1.66049634572119
72.5149993896484	2.39130854606628	18.56612109375	1.66670477483422
72.7149963378906	2.39741220138967	18.54794140625	1.67241750750691
72.9150009155273	2.4038574192673	18.54493359375	1.67814828455448
73.1149978637695	2.41044932045043	18.548150390625	1.68406346347183
73.3150024414063	2.41757812909782	18.556447265625	1.6898843459785
73.5149993896484	2.42456048727036	18.559958984375	1.69621570967138
73.7149963378906	2.43076169863343	18.54062890625	1.70151051133871
73.9150009155273	2.43696290999651	18.534501953125	1.70760927721858
74.1149978637695	2.4437012616545	18.542037109375	1.71352759934962
74.3150024414063	2.45009758509696	18.5406640625	1.71902147121727
74.5149993896484	2.45693349279463	18.54679296875	1.72484898939729
74.7149963378906	2.46362295001745	18.543857421875	1.73085683491081
74.9150009155273	2.47031240724027	18.547896484375	1.73658190760761
75.1149978637695	2.47724610380828	18.553708984375	1.74276367761195
75.3150024414063	2.4841798003763	18.551400390625	1.74894405063242
75.5149993896484	2.49052722938359	18.541107421875	1.754657831043
75.7149963378906	2.49707023613155	18.538609375	1.76041340455413
75.9150009155273	2.50361324287951	18.542904296875	1.76634744275361
76.1149978637695	2.51054693944752	18.54860546875	1.77223177161068
76.3150024414063	2.51718750223517	18.546048828125	1.77854066714644
76.5149993896484	2.5237794034183	18.540580078125	1.78434513509274
76.7149963378906	2.52993172034621	18.5311328125	1.79012725129724
76.9150009155273	2.53647449426353	18.535076171875	1.79590680636466
77.1149978637695	2.54384754225612	18.552509765625	1.80206808727235
77.3150024414063	2.55073234438896	18.552794921875	1.80860771797597
77.5149993896484	2.55737314000726	18.545208984375	1.81456282734871
77.7149963378906	2.56381835788488	18.535306640625	1.8204664811492
77.9150009155273	2.57001956924796	18.524302734375	1.8258560448885
78.1149978637695	2.57739261724055	18.54188671875	1.83230603579432
78.3150024414063	2.58432608097792	18.543189453125	1.83854845818132
78.5149993896484	2.59086908772588	18.53372265625	1.84462056495249
78.7149963378906	2.59677739813924	18.51666796875	1.85048137791455
78.9150009155273	2.60307616554201	18.515125	1.8560728058219
79.1149978637695	2.60971672832966	18.521931640625	1.86170486267656
79.3150024414063	2.6168457698077	18.53294921875	1.86795019544661
79.5149993896484	2.62392568401992	18.536125	1.87418784480542
79.7149963378906	2.63032224029303	18.522126953125	1.88014435116202
79.9150009155273	2.63657234609127	18.511353515625	1.88590085599571
80.1149978637695	2.64350580982864	18.522767578125	1.89193582627922
80.3150024414063	2.65019526705146	18.521826171875	1.89773086458445
80.5149993896484	2.65712896361947	18.52473828125	1.90377212129533
80.7149963378906	2.66386708244681	18.52076171875	1.90989836119115
80.9150009155273	2.67041008919477	18.512548828125	1.91597768571228
81.1149978637695	2.67709954641759	18.518548828125	1.92226562649012
81.3150024414063	2.68383789807558	18.5160546875	1.92800047807395
81.5149993896484	2.69003910943866	18.504708984375	1.93389831110835
81.7149963378906	2.69672856666148	18.50974609375	1.9398886943236
81.9150009155273	2.70346668548882	18.51201171875	1.94617186207324
82.1149978637695	2.71079107187688	18.523505859375	1.95242802146822
82.3150024414063	2.71762697957456	18.520794921875	1.95868778973818
82.5149993896484	2.72426754236221	18.511630859375	1.96477794088423
82.7149963378906	2.73027340881526	18.495072265625	1.97054725140333
82.9150009155273	2.73681641556323	18.4918828125	1.97646534070373
83.1149978637695	2.74409190751612	18.508888671875	1.98282022029161
83.3150024414063	2.7509278152138	18.506283203125	1.98926101438701
83.5149993896484	2.75747058913112	18.499240234375	1.99534534476697
83.7149963378906	2.76367180049419	18.486552734375	2.00112606398761
83.9150009155273	2.76977545581758	18.4743203125	2.0071764010936
84.1149978637695	2.77685537002981	18.49078125	2.01300322078168
84.3150024414063	2.78393551707268	18.49603515625	2.01938580721617
84.5149993896484	2.79067386873066	18.493244140625	2.02574813738465
84.7149963378906	2.79692374169827	18.48	2.03167181462049
84.9150009155273	2.80341785401106	18.47525	2.03731702640653
85.1149978637695	2.81015620566905	18.482392578125	2.04320228658617
85.3150024414063	2.81723635271192	18.489375	2.04942398704588
85.5149993896484	2.82402336597443	18.48671875	2.05588806420565
85.7149963378906	2.83027347177267	18.469990234375	2.06197169609368
85.9150009155273	2.83637689426541	18.45880078125	2.06765602342784
86.1149978637695	2.84321280196309	18.4705859375	2.0737606100738
86.3150024414063	2.84990225918591	18.471123046875	2.07995111122727
86.5149993896484	2.85683595575392	18.47459375	2.08606314845383
86.7149963378906	2.86357430741191	18.4722109375	2.09270697087049
86.9150009155273	2.87011708132923	18.462396484375	2.09883973002434
87.1149978637695	2.87695322185755	18.4686171875	2.10515293292701
87.3150024414063	2.88388668559492	18.4694296875	2.11125612258911
87.5149993896484	2.89033213630319	18.456474609375	2.11737235076725
87.7149963378906	2.8971191495657	18.455724609375	2.12369253858924
87.9150009155273	2.90380860678852	18.454599609375	2.13011307641864
88.1149978637695	2.91079096496105	18.455005859375	2.13638204149902
88.3150024414063	2.91728507727385	18.4442109375	2.14243773370981
88.5149993896484	2.92368163354695	18.437251953125	2.14839610271156
88.7149963378906	2.92973639443517	18.424984375	2.15453514829278
88.9150009155273	2.93627940118313	18.425103515625	2.1602725610137
89.1149978637695	2.94370111078024	18.44067578125	2.16662883758545
89.3150024414063	2.95068370178342	18.44011328125	2.17322539538145
89.5149993896484	2.95722647570074	18.429326171875	2.1793523337692
89.7149963378906	2.96347658149898	18.416423828125	2.18560686334968
89.9150009155273	2.9695313423872	18.405205078125	2.19131144694984
90.1149978637695	2.97661125659943	18.418189453125	2.19756667502224
90.3150024414063	2.98378895968199	18.4238203125	2.2039944306016
90.5149993896484	2.99057620577514	18.419298828125	2.21042241901159
90.7149963378906	2.99672852270305	18.40056640625	2.21658661030233
90.9150009155273	3.00312507897615	18.395619140625	2.22255219705403
91.1149978637695	3.00971674732864	18.393009765625	2.22875503823161
91.3150024414063	3.01674799993634	18.402740234375	2.23480560816824
91.5149993896484	3.02373035810888	18.40490234375	2.24152603186667
91.7149963378906	3.03027336485684	18.3944609375	2.24779895506799
91.9150009155273	3.03671881556511	18.3840390625	2.25376640446484
92.1149978637695	3.04379872977734	18.388234375	2.26027076132596
92.3150024414063	3.05043952539563	18.38187890625	2.26677674800158
92.5149993896484	3.05722653865814	18.379232421875	2.27331044152379
92.7149963378906	3.06372065097094	18.36788671875	2.27948627434671
92.9150009155273	3.07016610167921	18.362419921875	2.28575943037868
93.1149978637695	3.07680666446686	18.3632265625	2.29193968698382
93.3150024414063	3.08364257216454	18.3615	2.29867314919829
93.5149993896484	3.08999023400247	18.344642578125	2.30463431216776
93.7149963378906	3.0965821351856	18.340884765625	2.31103575788438
93.9150009155273	3.10317380353808	18.338087890625	2.31734197586775
94.1149978637695	3.11015616171062	18.34308203125	2.32351245358586
94.3150024414063	3.11679695732892	18.328796875	2.3301059845835
94.5149993896484	3.12343752011657	18.32374609375	2.33616097830236
94.7149963378906	3.12968739308417	18.310787109375	2.34237755648792
94.9150009155273	3.1362792942673	18.30977734375	2.34887911938131
95.1149978637695	3.14365234225988	18.319984375	2.35537858679891
95.3150024414063	3.15048824995756	18.31284765625	2.3619313724339
95.5149993896484	3.15678701736033	18.294314453125	2.36825179308653
95.7149963378906	3.16303712315857	18.281009765625	2.37431819550693
95.9150009155273	3.16914054565132	18.269962890625	2.38041183911264
96.1149978637695	3.17636714316905	18.28674609375	2.38682026974857
96.3150024414063	3.1837890855968	18.295939453125	2.39367457106709
96.5149993896484	3.19072254933417	18.283490234375	2.40026670508087
96.7149963378906	3.19687509909272	18.25978125	2.40662274882197
96.9150009155273	3.20332031697035	18.249556640625	2.41299625486135
97.1149978637695	3.21000977419317	18.249189453125	2.41939746774733
97.3150024414063	3.2172363717109	18.25409375	2.42600124329329
97.5149993896484	3.2242676243186	18.249283203125	2.43299663998187
97.7149963378906	3.23066394776106	18.226697265625	2.43935221806169
97.9150009155273	3.23696294799447	18.21036328125	2.44575412943959
98.1149978637695	3.24374996125698	18.210966796875	2.45230481959879
98.3150024414063	3.25029296800494	18.202779296875	2.45884386822581
98.5149993896484	3.25717777013779	18.20028515625	2.46558361686766
98.7149963378906	3.26391612179577	18.191017578125	2.47216993011534
98.9150009155273	3.27055668458343	18.180294921875	2.47874762862921
99.1149978637695	3.27749014832079	18.1741796875	2.48539447784424
99.3150024414063	3.28432605601847	18.1611875	2.49196263030171
99.5149993896484	3.29052726738155	18.144041015625	2.49821762554348
99.7149963378906	3.29707027412951	18.132099609375	2.50487145967782
99.9150009155273	3.3035643864423	18.125333984375	2.5111383292824
100.11499786377	3.31054697744548	18.12719140625	2.51740938983858
100.315002441406	3.31713864579797	18.111630859375	2.52421642653644
100.514999389648	3.32368165254593	18.100205078125	2.53070471808314
100.714996337891	3.32983396947384	18.0826875	2.5367836933583
100.915000915527	3.33632808178663	18.076654296875	2.54341657273471
101.11499786377	3.34360357373953	18.079021484375	2.54960195161402
101.315002441406	3.35058593191206	18.072900390625	2.55675450898707
101.514999389648	3.35717783309519	18.05239453125	2.56344676017761
101.714996337891	3.36362305097282	18.033541015625	2.57010827772319
101.915000915527	3.3698242623359	18.0196484375	2.57626897655427
102.11499786377	3.37714841589332	18.0251640625	2.58313887752593
102.315002441406	3.38422856293619	18.018830078125	2.59029539301991
102.514999389648	3.39086912572384	17.9967578125	2.59713223204017
102.714996337891	3.39692388661206	17.967205078125	2.60364613495767
102.915000915527	3.40332021005452	17.95113671875	2.60984036140144
103.11499786377	3.41000966727734	17.946142578125	2.61635822243989
103.315002441406	3.4173340536654	17.95173828125	2.62349750846624
103.514999389648	3.4243653062731	17.942966796875	2.63073202222586
103.714996337891	3.43076162971556	17.912017578125	2.63754837214947
103.915000915527	3.43701173551381	17.8880234375	2.64418148435652
104.11499786377	3.44389653764665	17.87911328125	2.65091215260327
104.315002441406	3.45048820599914	17.8660234375	2.65756901353598
104.514999389648	3.45737300813198	17.85409765625	2.6645315811038
104.714996337891	3.46391601487994	17.833958984375	2.67113721929491
104.915000915527	3.47031257115304	17.814736328125	2.67756078392267
105.11499786377	3.47690423950553	17.801435546875	2.68425093963742
105.315002441406	3.48354503512383	17.78812890625	2.69106752239168
105.514999389648	3.48974601365626	17.766400390625	2.69717769697309
105.714996337891	3.49638680927455	17.755041015625	2.70372373051941
105.915000915527	3.50317382253706	17.7467890625	2.71076592616737
106.11499786377	3.51040042005479	17.7423515625	2.71743047051132
106.315002441406	3.51723632775247	17.71887890625	2.72463541477919
106.514999389648	3.52387689054012	17.69758203125	2.7313195168972
106.714996337891	3.52998054586351	17.664501953125	2.73799756541848
106.915000915527	3.53652355261147	17.652810546875	2.74476665072143
107.11499786377	3.54384770616889	17.65266796875	2.75180768221617
107.315002441406	3.55078116990626	17.63420703125	2.75887106545269
107.514999389648	3.55732417665422	17.60352734375	2.76594585739076
107.714996337891	3.56367183849216	17.5801796875	2.77246092446148
107.915000915527	3.56982415542006	17.5531328125	2.7788809966296
108.11499786377	3.57705075293779	17.55280859375	2.78608058579266
108.315002441406	3.58427735045552	17.543220703125	2.79345992021263
108.514999389648	3.59116215258837	17.51841015625	2.8007635846734
108.714996337891	3.59741202555597	17.48176171875	2.80731660313904
108.915000915527	3.6040039267391	17.459408203125	2.81426310539246
109.11499786377	3.61074227839708	17.440857421875	2.82113812863827
109.315002441406	3.61787108704448	17.4321328125	2.82838055863976
109.514999389648	3.6245605442673	17.406025390625	2.83545721322298
109.714996337891	3.63066396676004	17.368650390625	2.8420309536159
109.915000915527	3.63681651651859	17.343642578125	2.84820795059204
110.11499786377	3.6436035297811	17.336216796875	2.85481871105731
110.315002441406	3.65019519813359	17.31748828125	2.8616099152714
110.514999389648	3.65708000026643	17.304591796875	2.86851241253316
110.714996337891	3.66376945748925	17.283390625	2.8757166583091
110.915000915527	3.67026356980205	17.256283203125	2.88201426155865
111.11499786377	3.6770508158952	17.239212890625	2.88939382880926
111.315002441406	3.68393561802804	17.22151171875	2.89616035297513
111.514999389648	3.69042973034084	17.191146484375	2.90323817171156
111.714996337891	3.69716808199883	17.17132421875	2.91007617488503
111.915000915527	3.703857306391	17.149857421875	2.91693932376802
112.11499786377	3.71083989739418	17.1304140625	2.92401574552059
112.315002441406	3.71728511527181	17.1042109375	2.93106795288622
112.514999389648	3.72373056598008	17.077138671875	2.93810968287289
112.714996337891	3.72983398847282	17.041576171875	2.94478004798293
112.915000915527	3.73647455126047	17.029865234375	2.95124365948141
113.11499786377	3.74399404972792	17.028443359375	2.95858085155487
113.315002441406	3.75102530233562	16.999458984375	2.9662698507309
113.514999389648	3.75771475955844	16.9620390625	2.97327782027423
113.714996337891	3.76391597092152	16.92504296875	2.98040406778455
113.915000915527	3.7700196262449	16.894990234375	2.98677873797715
114.11499786377	3.77719732932746	16.89028515625	2.9938982333988
114.315002441406	3.78427724353969	16.86589453125	3.00136720761657
114.514999389648	3.79086914472282	16.82927734375	3.00843245349824
114.714996337891	3.79692390561104	16.796765625	3.01525415852666
114.915000915527	3.80322267301381	16.770869140625	3.02182347513735
115.11499786377	3.80966789089143	16.74978515625	3.02849197760224
115.315002441406	3.81669914349914	16.73670703125	3.03521985188127
115.514999389648	3.82363284006715	16.711333984375	3.04259452968836
115.714996337891	3.83017584681511	16.6804453125	3.04983370006084
115.915000915527	3.83657217025757	16.646287109375	3.0563969630748
116.11499786377	3.84355476126075	16.630697265625	3.06339631788433
116.315002441406	3.85029288008809	16.60056640625	3.0706156976521
116.514999389648	3.85712902061641	16.572482421875	3.07773519307375
116.714996337891	3.8637206889689	16.53612890625	3.08493664488196
116.915000915527	3.870117245242	16.50383984375	3.09157115407288
117.11499786377	3.87685536406934	16.484419921875	3.09856259264052
117.315002441406	3.88374016620219	16.45690234375	3.10591794550419
117.514999389648	3.89013672247529	16.419669921875	3.11263441108167
117.714996337891	3.89687507413328	16.396021484375	3.11975041404366
117.915000915527	3.9035645313561	16.3657802734375	3.12716048210859
118.11499786377	3.91069334000349	16.3423447265625	3.13457031734288
118.315002441406	3.917480353266	16.30212109375	3.14191007055342
118.514999389648	3.92421893775463	16.2684033203125	3.14899324439466
118.714996337891	3.93042014911771	16.219705078125	3.15595488063991
118.915000915527	3.93720716238022	16.196228515625	3.1630105804652
119.11499786377	3.94453108310699	16.1786220703125	3.17049585282803
119.315002441406	3.95112298429012	16.1310205078125	3.17777250893414
119.514999389648	3.95751930773258	16.0905244140625	3.18467267788947
119.714996337891	3.96357430145144	16.0503779296875	3.1915430445224
119.915000915527	3.96962882950902	16.0128671875	3.19793098606169
120.11499786377	3.97680653259158	16.0039697265625	3.20491171441972
120.315002441406	3.98403313010931	15.9764013671875	3.21271573193371
120.514999389648	3.99086903780699	15.926333984375	3.22030996903777
120.714996337891	3.99697246029973	15.8695517578125	3.22713516652584
120.915000915527	4.00336924940348	15.824548828125	3.23419761843979
121.11499786377	4.01005847379565	15.7904462890625	3.24131967499852
121.315002441406	4.01713885366917	15.7586484375	3.24869295582175
121.514999389648	4.02416987344623	15.708162109375	3.25613119639456
121.714996337891	4.03051776811481	15.64145703125	3.26376548036933
121.915000915527	4.0368651971221	15.5833193359375	3.2711261883378
122.11499786377	4.04370110481977	15.54115234375	3.278739284724
122.315002441406	4.05019521713257	15.4824267578125	3.28602269291878
122.514999389648	4.05703112483025	15.4235830078125	3.29395243898034
122.714996337891	4.06376970931888	15.342232421875	3.30198439769447
122.915000915527	4.07045893371105	15.1830439453125	3.31131229177117
123.059997558594	4.07631834968925	-1.55447119140625	3.40152089484036