File: data/rawdata1.txt
File Path: C:\2024\20240314 CTLbio tensile\Test Run 1 03-14-24 16 22 53 PM\DAQ- Time, … - (Timed).txt
Test: CTLbio_tensile_EC5AA
Test Run: Test Run 1
Date: 3/14/2024 3:49:00 PM


Time 	Crosshead 	Load 	Extensometer
sec	mm	kN	mm
0.952000021934509	0.001318359409197	0.0413074340820313	0.000184176656148338
1.15199995040894	0.00600585917709395	0.183003524780273	0.0018316392242923
1.35199999809265	0.0113769528979901	0.350580108642578	0.00381113090952567
1.55200004577637	0.0180664064828306	0.56235498046875	0.00643231578578707
1.75199997425079	0.0246093750320142	0.771902770996094	0.00888484919414623
1.95200002193451	0.0315429679176304	0.986718811035156	0.0114387439680286
2.15199995040894	0.0397460935346317	1.24807434082031	0.0145560306918924
2.35199999809265	0.0470214836241212	1.47521118164063	0.0173010921571404
2.55200004577637	0.053906249377178	1.70061755371094	0.0200582362595014
2.75200009346008	0.060449219745351	1.90823327636719	0.0227589989663102
2.95199990272522	0.0674804687150754	2.12958740234375	0.0252937607001513
3.15199995040894	0.0748046877561137	2.35638500976563	0.0281325355899753
3.35199999809265	0.0821777357487008	2.59053857421875	0.0310608047584537
3.55200004577637	0.0888183567440137	2.79673486328125	0.0335087715939153
3.75200009346008	0.0953613271121867	2.9963544921875	0.0359660407411866
3.95199990272522	0.102441408671439	3.21617138671875	0.0386851752409711
4.15199995040894	0.109277345472947	3.42525122070312	0.0411187247664202
4.35200023651123	0.116210940177552	3.64093139648438	0.0438379720435478
4.55200004577637	0.122900397400372	3.845021484375	0.0464187178295106
4.7519998550415	0.129394524265081	4.04630444335938	0.0490845886815805
4.9520001411438	0.136181639390998	4.2524013671875	0.0513699560542591
5.15199995040894	0.143017576192506	4.46108740234375	0.0540981309313793
5.35200023651123	0.149414059706032	4.65605078125	0.0563572175451554
5.55200004577637	0.156103516928852	4.86022216796875	0.0591312564210966
5.7519998550415	0.162988275405951	5.070482421875	0.0615661483607255
5.9520001411438	0.17026366549544	5.288865234375	0.0643153834971599
6.15199995040894	0.177197260200046	5.49830029296875	0.066901629907079
6.35200023651123	0.183886717422865	5.6988623046875	0.0694545014994219
6.55200004577637	0.189990227227099	5.8835888671875	0.0718511000741273
6.7519998550415	0.196728520677425	6.08408837890625	0.0745461584301665
6.9520001411438	0.204150390345603	6.30566748046875	0.0772181883803569
7.15199995040894	0.210839847568423	6.494517578125	0.0795583546278067
7.35200023651123	0.217382810660638	6.69179931640625	0.0820099448901601
7.55200004577637	0.223535156692378	6.87449951171875	0.0841396395117044
7.7519998550415	0.229687502724119	7.05934619140625	0.0865383917698637
7.9520001411438	0.237158208619803	7.2839521484375	0.0892693860805593
8.15200042724609	0.244335940806195	7.4837490234375	0.0917783327167854
8.35200023651123	0.251123041380197	7.68734326171875	0.0942945916904137
8.55200004577637	0.257275387411937	7.87103125	0.0966563820838928
8.7519998550415	0.263769528828561	8.06056982421875	0.0989472246146761
8.95199966430664	0.270507822278887	8.26273046875	0.10169341112487
9.15200042724609	0.277490238659084	8.469361328125	0.104196347820107
9.35200023651123	0.284228503005579	8.6690517578125	0.10628914606059
9.55200004577637	0.290185533231124	8.8401064453125	0.108878528408241
9.7519998550415	0.296386715490371	9.0112265625	0.110841727291699
9.95199966430664	0.303222652291879	9.2070576171875	0.113339548988733
10.1520004272461	0.309716793708503	9.3982509765625	0.115592556539923
10.3520002365112	0.316650402965024	9.5974169921875	0.118208816275001
10.5520000457764	0.323339831084013	9.7874111328125	0.120613556646276
10.7519998550415	0.329882808728144	9.9722626953125	0.122782555990852
10.9519996643066	0.336962897563353	10.1723828125	0.125440710689873
11.1520004272461	0.343798834364861	10.365921875	0.127806211821735
11.3520002365112	0.350292975781485	10.5468720703125	0.130101572722197
11.5520000457764	0.356982433004305	10.7363037109375	0.132451110403053
11.7519998550415	0.3637206973508	10.9122060546875	0.134737754706293
11.9519996643066	0.37080078618601	11.1000185546875	0.13719750859309
12.1520004272461	0.377294927602634	11.2835791015625	0.139398369356059
12.3520002365112	0.38388671237044	11.470017578125	0.141845870530233
12.5520000457764	0.389941415050998	11.6379794921875	0.143806944834068
12.7519998550415	0.396826158976182	11.8338466796875	0.146026242873631
12.9519996643066	0.404394522774965	12.0462294921875	0.148782055475749
13.1520004272461	0.411328132031485	12.234060546875	0.151269880007021
13.3520002365112	0.418066396377981	12.4226455078125	0.153563945787027
13.5520000457764	0.424169935286045	12.5874482421875	0.155737536260858
13.7519998550415	0.430322252213955	12.7529775390625	0.157929578563198
13.9519996643066	0.43759765685536	12.95173046875	0.160505122039467
14.1520004272461	0.444433593656868	13.1331611328125	0.162500873557292
14.3520002365112	0.450927735073492	13.3066240234375	0.164998811669648
14.5520000457764	0.456884765299037	13.46755078125	0.166929501574486
14.7519998550415	0.463183590909466	13.63621875	0.169120845384896
14.9519996643066	0.469775404781103	13.8128916015625	0.171169638633728
15.1520004272461	0.476855464512482	13.995560546875	0.173501815879717
15.3520002365112	0.483837880892679	14.17885546875	0.17564112204127
15.5520000457764	0.49023434985429	14.3474052734375	0.17812053556554
15.7519998550415	0.496777356602252	14.51418359375	0.180182731128298
15.9519996643066	0.503955059684813	14.7039609375	0.182554984348826
16.1520004272461	0.510644516907632	14.8718212890625	0.184805161552504
16.3519992828369	0.517626933287829	15.04937890625	0.187112833373249
16.5520000457764	0.524072267580777	15.2119091796875	0.189446422155015
16.7520008087158	0.530566379893571	15.3680927734375	0.191795785212889
16.9519996643066	0.537451182026416	15.53090234375	0.194210821064189
17.1520004272461	0.544140639249235	15.684392578125	0.196880690054968
17.3519992828369	0.550537137314677	15.82572265625	0.199168367544189
17.5520000457764	0.557226536329836	15.964025390625	0.201992777874693
17.7520008087158	0.564013666007668	16.10375390625	0.204880023375154
17.9519996643066	0.571240205317736	16.2436103515625	0.207973673241213
18.1520004272461	0.577978498768061	16.360900390625	0.211281178053468
18.3519992828369	0.584667955990881	16.468859375	0.21476685651578
18.5520000457764	0.590771494898945	16.554017578125	0.217914610402659
18.7520008087158	0.597656238824129	16.6588046875	0.221686437726021
18.9519996643066	0.604931614361703	16.75598046875	0.225844400119968
19.1520004272461	0.611279276199639	16.826755859375	0.229640165343881
19.3519992828369	0.617675774265081	16.88996484375	0.233569575357251
19.5520000457764	0.623583968263119	16.939017578125	0.237356623983942
19.7520008087158	0.629687507171184	16.9925	0.241613786784001
19.9519996643066	0.637158227618784	17.074701171875	0.246147596044466
20.1520004272461	0.644238258246332	17.1306484375	0.250816228799522
20.3519992828369	0.650976551696658	17.171494140625	0.25554295280017
20.5520000457764	0.657080090604722	17.2011875	0.259716238360852
20.7520008087158	0.66352536669001	17.23327734375	0.264553760644048
20.9519996643066	0.670214823912829	17.283337890625	0.269142707111314
21.1520004272461	0.677441421430558	17.329033203125	0.274405290838331
21.3519992828369	0.684375001583248	17.362419921875	0.279424333712086
21.5520000457764	0.690624990966171	17.37709765625	0.284146139165387
21.7520008087158	0.696972652804106	17.40289453125	0.288901530439034
21.9519996643066	0.703808618709445	17.440189453125	0.293808203423396
22.1520004272461	0.710302731022239	17.465431640625	0.298598170047626
22.3519992828369	0.717333983629942	17.5014921875	0.303798995446414
22.5520000457764	0.724072277080268	17.5251953125	0.308777933241799
22.7520008087158	0.730810570530593	17.546607421875	0.313872267724946
22.9519996643066	0.738085946068168	17.57996484375	0.319132523145527
23.1520004272461	0.744824239518493	17.5966015625	0.324403838021681
23.3519992828369	0.751367188058794	17.613529296875	0.329398550093174
23.5520000457764	0.758056645281613	17.63509765625	0.334527285303921
23.7520008087158	0.764794938731939	17.6549140625	0.339756545145065
23.9519996643066	0.771875027567148	17.684919921875	0.345094507792965
24.1520004272461	0.778320303652436	17.694369140625	0.350009999237955
24.3519992828369	0.78481447417289	17.708947265625	0.355288007995114
24.5520000457764	0.790624995715916	17.7078984375	0.359888013917953
24.7520008087158	0.797412125393748	17.7404140625	0.364564912160859
24.9519996643066	0.804687500931323	17.775884765625	0.370022229617462
25.1520004272461	0.811376958154142	17.78790625	0.37544869701378
25.3519992828369	0.818066415376961	17.79937890625	0.380612793378532
25.5520000457764	0.824218732304871	17.803537109375	0.38550901808776
25.7520008087158	0.830664066597819	17.81702734375	0.390298897400498
25.9519996643066	0.838232401292771	17.859095703125	0.395528506487608
26.1520004272461	0.84506836719811	17.870232421875	0.400963181164116
26.3519992828369	0.851513643283397	17.872123046875	0.406084174755961
26.5520000457764	0.857421895489097	17.871564453125	0.411041866755113
26.7520008087158	0.86391600780189	17.8920078125	0.41566661093384
26.9519996643066	0.870703137479722	17.913119140625	0.420667696744204
27.1520004272461	0.878027349244803	17.94427734375	0.426152575528249
27.3519992828369	0.884960929397494	17.95956640625	0.431613792898133
27.5520000457764	0.891210918780416	17.955041015625	0.436711154179648
27.7520008087158	0.897656253073364	17.966765625	0.441798387328163
27.9519996643066	0.904736341908574	17.990958984375	0.447017489932477
28.1520004272461	0.911328126676381	17.997146484375	0.452371023129672
28.3519992828369	0.918505887966603	18.023064453125	0.457652553450316
28.5520000457764	0.925000000279397	18.024013671875	0.462871015770361
28.7520008087158	0.931494112592191	18.032048828125	0.468171579996124
28.9519996643066	0.938330078497529	18.051658203125	0.473215884994715
29.1520004272461	0.944775412790477	18.053357421875	0.478332280181348
29.3519992828369	0.9510254021734	18.05740234375	0.483493786305189
29.5520000457764	0.957617186941206	18.073140625	0.488499470520765
29.7520008087158	0.964355480391532	18.0905078125	0.493616331368685
29.9519996643066	0.971533183474094	18.112623046875	0.499241577927023
30.1520004272461	0.978125026449561	18.11700390625	0.504445866681635
30.3519992828369	0.984619138762355	18.121193359375	0.509642413817346
30.5520000457764	0.990478554740548	18.112830078125	0.514425802975893
30.7520008087158	0.997265568003058	18.13368359375	0.519464432727545
30.9519996643066	1.0045898379758	18.16426171875	0.524933566339314
31.1520004272461	1.01127929519862	18.1676484375	0.530289544258267
31.3519992828369	1.01787107996643	18.172953125	0.535244587808847
31.5520000457764	1.02392572443932	18.1663984375	0.540431647095829
31.7520008087158	1.03017583023757	18.17333203125	0.545137212611735
31.9519996643066	1.03759765625	18.209099609375	0.550570490304381
32.1520004272461	1.04467768687755	18.224826171875	0.55615056771785
32.3520011901855	1.05146481655538	18.230611328125	0.561565277166665
32.5519981384277	1.0577148059383	18.223423828125	0.566565082408488
32.7519989013672	1.06445315759629	18.238255859375	0.571801036130637
32.9519996643066	1.07138673774898	18.254474609375	0.577308761421591
33.1520004272461	1.0785156628117	18.27130078125	0.582970504183322
33.3520011901855	1.08520512003452	18.274330078125	0.58839243138209
33.5519981384277	1.09125976450741	18.263876953125	0.593203876633197
33.7519989013672	1.09765620436519	18.268947265625	0.598335114773363
33.9519996643066	1.10463867895305	18.290123046875	0.603633932769299
34.1520004272461	1.11118168570101	18.2950078125	0.608733505941927
34.3520011901855	1.11831049434841	18.314451171875	0.614328018855304
34.5519981384277	1.12475582864136	18.31049609375	0.619390280917287
34.7519989013672	1.13125005736947	18.311734375	0.624589622020721
34.9519996643066	1.13818363752216	18.3291171875	0.629984133411199
35.1520004272461	1.1447265278548	18.33223046875	0.635131844319403
35.3520011901855	1.15117186214775	18.332583984375	0.640341255348176
35.5519981384277	1.15781254135072	18.341626953125	0.645524240098894
35.7519989013672	1.16445310413837	18.34943359375	0.650566129479557
35.9519996643066	1.17133790627122	18.3632578125	0.65575708867982
36.1520004272461	1.17768556810915	18.36082421875	0.661198107991368
36.3520011901855	1.18408200796694	18.36415625	0.666223233565688
36.5519981384277	1.19008787441999	18.35855859375	0.67105470225215
36.7519989013672	1.19702145457268	18.381173828125	0.676321040373296
36.9519996643066	1.20458984747529	18.409376953125	0.681820092722774
37.1520004272461	1.21152342762798	18.414724609375	0.68751018261537
37.3520011901855	1.21826166287065	18.412291015625	0.692825415171683
37.5519981384277	1.2242675293237	18.40217578125	0.698152289260179
37.7519989013672	1.23056641314179	18.404732421875	0.702876655850559
37.9519996643066	1.2381348060444	18.439021484375	0.708407140336931
38.1520004272461	1.24511716421694	18.442552734375	0.714097404852509
38.3520011901855	1.25180662143975	18.4438671875	0.71979477070272
38.5519981384277	1.25791016034782	18.433857421875	0.724771351087838
38.7519989013672	1.26435549464077	18.43922265625	0.729676685295999
38.9519996643066	1.27109372988343	18.44846875	0.735093432012945
39.1520004272461	1.27827143296599	18.468220703125	0.740902323741466
39.3520011901855	1.28520512953401	18.4751875	0.746373785659671
39.5519981384277	1.29145511891693	18.46640625	0.751448562368751
39.7519989013672	1.29809568170458	18.47078125	0.756822701077908
39.9519996643066	1.30512693431228	18.487822265625	0.762198935262859
40.1520004272461	1.31157226860523	18.482150390625	0.767363817431033
40.3520011901855	1.31835939828306	18.49354296875	0.772752508055419
40.5519981384277	1.32446293719113	18.480169921875	0.777841021772474
40.7519989013672	1.33066403213888	18.486798828125	0.782967428676784
40.9519996643066	1.33740238379687	18.497748046875	0.788304605521262
41.1520004272461	1.34399416856468	18.50403125	0.793399813119322
41.3520011901855	1.35039060842246	18.502705078125	0.798520573880523
41.5519981384277	1.35708006564528	18.513134765625	0.804035225883126
41.7519989013672	1.36386719532311	18.5198671875	0.809368910267949
41.9519996643066	1.37104489840567	18.534580078125	0.814869534224272
42.1520004272461	1.37778325006366	18.5322265625	0.820251938421279
42.3520011901855	1.38457026332617	18.541634765625	0.825644819997251
42.5519981384277	1.3907226966694	18.5309765625	0.830861099530011
42.7519989013672	1.39780272729695	18.54981640625	0.836396822705865
42.9519996643066	1.40517577528954	18.566119140625	0.842000532429665
43.1520004272461	1.41162110958248	18.55646875	0.847557210363448
43.3520011901855	1.41811522189528	18.551279296875	0.852822326123714
43.5519981384277	1.42412108834833	18.543669921875	0.857928418554366
43.7519989013672	1.43041997216642	18.5449375	0.86313346400857
43.9519996643066	1.43818359356374	18.58262109375	0.868952949531376
44.1520004272461	1.44531251862645	18.585458984375	0.874651770573109
44.3520011901855	1.45209964830428	18.586361328125	0.880110601428896
44.5519981384277	1.45815429277718	18.569498046875	0.885555287823081
44.7519989013672	1.46459962707013	18.5727109375	0.89068355737254
44.9519996643066	1.47148442920297	18.585572265625	0.896057346835732
45.1520004272461	1.47866213228554	18.59596484375	0.90170162729919
45.3520011901855	1.48544926196337	18.596076171875	0.907352368813008
45.5519981384277	1.49145512841642	18.58338671875	0.912378949578851
45.7519989013672	1.49780279025435	18.58296484375	0.917473633307964
45.9519996643066	1.50449213106185	18.591556640625	0.922641833312809
46.1520004272461	1.51083979289979	18.5890390625	0.927996879909188
46.3520011901855	1.51787104550749	18.6043125	0.933504139538854
46.5519981384277	1.52441405225545	18.605314453125	0.938816170673817
46.7519989013672	1.53115228749812	18.60913671875	0.944315106607974
46.9519996643066	1.538330106996	18.622525390625	0.94972737133503
47.1520004272461	1.54497066978365	18.61930078125	0.955248600803316
47.3520011901855	1.55131833162159	18.615001953125	0.960430596023798
47.5519981384277	1.55791011638939	18.618591796875	0.96577376825735
47.7519989013672	1.56445312313735	18.620349609375	0.970894296187907
47.9519996643066	1.5715331537649	18.633681640625	0.976500625256449
48.1520004272461	1.57797848805785	18.62775390625	0.98203809466213
48.3520011901855	1.58452149480581	18.63005078125	0.987384817562997
48.5519981384277	1.59052736125886	18.619353515625	0.992556218989193
48.7519989013672	1.59736326895654	18.634884765625	0.99802715703845
48.9519996643066	1.60483398940414	18.6577734375	1.00396038033068
49.1520004272461	1.61147455219179	18.653677734375	1.00923783611506
49.3520011901855	1.61826168186963	18.653873046875	1.01502577308565
49.5519981384277	1.6244628932327	18.640671875	1.02054921444505
49.7519989013672	1.63090822752565	18.637560546875	1.02562911342829
49.9519996643066	1.63852539844811	18.671265625	1.03127304464579
50.1520004272461	1.64521485567093	18.6626015625	1.03668740484864
50.3520011901855	1.65161129552871	18.65699609375	1.04232796002179
50.5519981384277	1.6574707115069	18.641552734375	1.04730762541294
50.7519989013672	1.66386715136468	18.64446875	1.05257681570947
50.9519996643066	1.67065428104252	18.65504296875	1.05809280648828
51.1520004272461	1.67792965658009	18.669041015625	1.06355745811015
51.3520011901855	1.68486323673278	18.67741796875	1.06907577719539
51.5519981384277	1.69101567007601	18.6625390625	1.07451633084565
51.7519989013672	1.69746088795364	18.6598828125	1.07974489219487
51.9519996643066	1.7044433625415	18.671482421875	1.08541292138398
52.1520004272461	1.7110351473093	18.671171875	1.09075172804296
52.3520011901855	1.71816407237202	18.682708984375	1.09639181755483
52.5519981384277	1.72470707911998	18.677912109375	1.10172212589532
52.7519989013672	1.73124996945262	18.6768046875	1.10725220292807
52.9519996643066	1.73808599356562	18.687271484375	1.11254525836557
53.1520004272461	1.74453121144325	18.6817109375	1.11825356725603
53.3520011901855	1.75078120082617	18.674080078125	1.1235069250688
53.5519981384277	1.75751955248415	18.682646484375	1.12892535980791
53.7519989013672	1.764404354617	18.69046484375	1.13447022158653
53.9519996643066	1.77177728619426	18.70712890625	1.14045350346714
54.1520004272461	1.77846674341708	18.6994921875	1.14604469854385
54.3520011901855	1.78500975016505	18.6960859375	1.15137698594481
54.5519981384277	1.79096683859825	18.68091796875	1.15676247514784
54.7519989013672	1.79785152431577	18.69284375	1.16198323667049
54.9519996643066	1.80517579428852	18.7101328125	1.16855662781745
55.1520004272461	1.81176757905632	18.70295703125	1.1739213950932
55.3520011901855	1.81835936382413	18.70255078125	1.17920769844204
55.5519981384277	1.82431645225734	18.68671875	1.18455255869776
55.7519989013672	1.83046876918525	18.681041015625	1.18965329602361
55.9519996643066	1.83789059519768	18.7074921875	1.1953798821196
56.1520004272461	1.84482417535037	18.711765625	1.20085699018091
56.3520011901855	1.85151363257319	18.707837890625	1.20678439270705
56.5519981384277	1.85771484393626	18.69525	1.21173309162259
56.7519989013672	1.86430662870407	18.6974765625	1.21701753232628
56.9519996643066	1.87119143083692	18.706748046875	1.22270383872092
57.1520004272461	1.87827146146446	18.716875	1.22830003965646
57.3520011901855	1.88491214066744	18.716115234375	1.23398494906723
57.5519981384277	1.89091800712049	18.698751953125	1.23920757323503
57.7519989013672	1.89716799650341	18.696080078125	1.24432763550431
57.9519996643066	1.9041015766561	18.711193359375	1.24996469821781
58.1520004272461	1.91064458340406	18.714333984375	1.25524739269167
58.3520011901855	1.91777339205146	18.7287265625	1.26102927606553
58.5519981384277	1.92431639879942	18.72233203125	1.26644584815949
58.7519989013672	1.93085940554738	18.7198671875	1.27222144510597
58.9519996643066	1.93784176371992	18.727208984375	1.2778613017872
59.1520004272461	1.9445801153779	18.725060546875	1.28347252029926
59.3520011901855	1.95112300571054	18.721587890625	1.28910993225873
59.5519981384277	1.95795902982354	18.725291015625	1.29477144218981
59.7519989013672	1.96469738148153	18.7262890625	1.3003961648792
59.9519996643066	1.97172840125859	18.729921875	1.3062598882243
60.1520004272461	1.97807606309652	18.725994140625	1.31194095592946
60.3520011901855	1.98447261936963	18.721388671875	1.31713890004903
60.5519981384277	1.99042959138751	18.70655859375	1.32238527294248
60.7519989013672	1.99736328795552	18.7219375	1.32801663130522
60.9519996643066	2.00493168085814	18.741607421875	1.33389024995267
61.1520004272461	2.01167003251612	18.736205078125	1.33945851121098
61.3520011901855	2.01826170086861	18.72721484375	1.34515727404505
61.5519981384277	2.02426756732166	18.710498046875	1.35035591665655
61.7519989013672	2.03046877868474	18.709224609375	1.35576084721833
61.9519996643066	2.03798827715218	18.73765234375	1.36121269315481
62.1520004272461	2.04492197372019	18.7388203125	1.36721832677722
62.3520011901855	2.05156253650784	18.7303984375	1.373051549308
62.5519981384277	2.0575684029609	18.7170859375	1.37815182097256
62.7519989013672	2.06391606479883	18.713896484375	1.38306815642864
62.9519996643066	2.07065418362617	18.72306640625	1.38863048050553
63.1520004272461	2.07778322510421	18.735818359375	1.39447546098381
63.3520011901855	2.08471668884158	18.736376953125	1.40007631853223
63.5519981384277	2.09101568907499	18.72909375	1.40529114287347
63.7519989013672	2.09765625186265	18.7277734375	1.41125300433487
63.9519996643066	2.10478506051004	18.741123046875	1.4168310444802
64.1520004272461	2.11127940565348	18.731458984375	1.42246368341148
64.3519973754883	2.11816397495568	18.7414296875	1.4281157637015
64.552001953125	2.12446297518909	18.72821875	1.43376679625362
64.7519989013672	2.13090819306672	18.72508984375	1.43936683889478
64.9520034790039	2.13779299519956	18.73388671875	1.44493079278618
65.1520004272461	2.14433600194752	18.7312578125	1.45046343095601
65.3519973754883	2.15068366378546	18.725171875	1.45603914279491
65.552001953125	2.15732422657311	18.72857421875	1.46129657514393
65.7519989013672	2.16386723332107	18.7300703125	1.46679452154785
65.9520034790039	2.17094738036394	18.737560546875	1.47264555562288
66.1520004272461	2.17749015428126	18.7339609375	1.4781589852646
66.3519973754883	2.18413094989955	18.730369140625	1.48350629024208
66.552001953125	2.1902343723923	18.71788671875	1.48886721581221
66.7519989013672	2.19716806896031	18.732623046875	1.49451673496515
66.9520034790039	2.2045411169529	18.74453515625	1.50020571891218
67.1520004272461	2.21103522926569	18.736712890625	1.50602089706808
67.3519973754883	2.21748044714332	18.730474609375	1.51142035610974
67.552001953125	2.22353520803154	18.720521484375	1.51671201456338
67.7519989013672	2.22978508099914	18.71883984375	1.52208714280277
67.9520034790039	2.23745126277208	18.7455390625	1.52788264676929
68.1520004272461	2.24472652189434	18.752712890625	1.53383589349687
68.3519973754883	2.25156242959201	18.74656640625	1.5397242968902
68.552001953125	2.25761719048023	18.7313984375	1.54512259177864
68.7519989013672	2.26411130279303	18.728716796875	1.55075371731073
68.9520034790039	2.2709472104907	18.73799609375	1.55619333963841
69.1520004272461	2.27817380800843	18.747142578125	1.56228814739734
69.3519973754883	2.28515616618097	18.748	1.56820320989937
69.552001953125	2.29125982150435	18.729109375	1.573545509018
69.7519989013672	2.29770503938198	18.725876953125	1.57921016216278
69.9520034790039	2.30449228547513	18.7317890625	1.58495630603284
70.1520004272461	2.31088860891759	18.729626953125	1.59042084123939
70.3519973754883	2.31796875596046	18.73963671875	1.59625173546374
70.552001953125	2.32460931874812	18.734998046875	1.60203292034566
70.7519989013672	2.3313476704061	18.734419921875	1.60771608352661
70.9520034790039	2.3384764790535	18.74455078125	1.61361158825457
71.1520004272461	2.34506838023663	18.730556640625	1.61915144417435
71.3519973754883	2.35136714763939	18.7243203125	1.62466673646122
71.552001953125	2.35791015438735	18.723314453125	1.63000088650733
71.7519989013672	2.36450205557048	18.72401953125	1.6357225831598
71.9520034790039	2.37153330817819	18.731439453125	1.64146744646132
72.1520004272461	2.37797852605581	18.726314453125	1.64684117771685
72.3519973754883	2.38447263836861	18.719302734375	1.65244680829346
72.552001953125	2.39052739925683	18.709916015625	1.65765662677586
72.7519989013672	2.3973633069545	18.724873046875	1.66331278160214
72.9520034790039	2.40478524938226	18.738609375	1.66933634318411
73.1520004272461	2.41147470660508	18.737298828125	1.67491845786572
73.3519973754883	2.4181641638279	18.73046484375	1.68066192418337
73.552001953125	2.42436514236033	18.7182734375	1.68609200045466
73.7519989013672	2.4308105930686	18.72022265625	1.69160147197545
73.9520034790039	2.43837898597121	18.74340625	1.69785623438656
74.1520004272461	2.44511710479856	18.740759765625	1.70348619576544
74.3519973754883	2.45156255550683	18.7276328125	1.70920579694211
74.552001953125	2.45751952752471	18.710951171875	1.71475089155138
74.7519989013672	2.4640136398375	18.71582421875	1.72018411103636
74.9520034790039	2.47089844197035	18.728404296875	1.72560405917466
75.1520004272461	2.47827148996294	18.74244140625	1.73213903326541
75.3519973754883	2.48525384813547	18.74060546875	1.738146180287
75.552001953125	2.49145505949855	18.720802734375	1.74407637678087
75.7519989013672	2.49785161577165	18.71612890625	1.7493317136541
75.9520034790039	2.50478507950902	18.72298046875	1.75509823020548
76.1520004272461	2.51123053021729	18.7139140625	1.76068628206849
76.3519973754883	2.51826178282499	18.723009765625	1.76665687467903
76.552001953125	2.52465810626745	18.71308984375	1.77237286698073
76.7519989013672	2.53100576810539	18.70571875	1.77788874134421
76.9520034790039	2.53774411976337	18.7125	1.78346841130406
77.1520004272461	2.54414067603648	18.70487109375	1.78895448334515
77.3519973754883	2.55039054900408	18.701919921875	1.794493640773
77.552001953125	2.5570800062269	18.70716796875	1.80012709461153
77.7519989013672	2.56396480835974	18.71191015625	1.80572306271642
77.9520034790039	2.57133785635233	18.72699609375	1.81163637898862
78.1520004272461	2.57802731357515	18.719228515625	1.81771127972752
78.3519973754883	2.58461921475828	18.714345703125	1.82378257159144
78.552001953125	2.59057618677616	18.6980859375	1.82865257374942
78.7519989013672	2.59746098890901	18.71054296875	1.83451687917113
78.9520034790039	2.60483403690159	18.723443359375	1.84069899842143
79.1520004272461	2.61152349412441	18.7211328125	1.84651196468621
79.3519973754883	2.61816405691206	18.714427734375	1.85225089080632
79.552001953125	2.62426747940481	18.69786328125	1.85799144674093
79.7519989013672	2.63051758520305	18.692705078125	1.86344084795564
79.9520034790039	2.63808597810566	18.716984375	1.86951248906553
80.1520004272461	2.64511723071337	18.724408203125	1.87582522630692
80.3519973754883	2.65190424397588	18.71662890625	1.88177370000631
80.552001953125	2.65810545533895	18.703625	1.88757281284779
80.7519989013672	2.66474601812661	18.69915625	1.89319264609367
80.9520034790039	2.67167971469462	18.705685546875	1.89919164404273
81.1520004272461	2.67875986173749	18.71091015625	1.90503871999681
81.3519973754883	2.68535153008997	18.7031796875	1.91082817036659
81.552001953125	2.69125984050333	18.683732421875	1.91634218208492
81.7519989013672	2.6975586079061	18.680146484375	1.92179228179157
81.9520034790039	2.70439451560378	18.689439453125	1.92752981092781
82.1520004272461	2.71088862791657	18.6855703125	1.9332425436005
82.3519973754883	2.71796877495944	18.701166015625	1.93918473087251
82.552001953125	2.72446288727224	18.692630859375	1.94492435548455
82.7519989013672	2.7310058940202	18.6891953125	1.95043883286417
82.9520034790039	2.73798825219274	18.694380859375	1.95638835430145
83.1520004272461	2.74462881498039	18.692173828125	1.96233415044844
83.3519973754883	2.75117182172835	18.688060546875	1.96809391491115
83.552001953125	2.7579590678215	18.689607421875	1.9737770780921
83.7519989013672	2.76474608108401	18.690701171875	1.97963579557836
83.9520034790039	2.77167977765203	18.696224609375	1.98573525995016
84.1520004272461	2.77802743948996	18.681615234375	1.99146149680018
84.3519973754883	2.78442376293242	18.67679296875	1.99700403027236
84.552001953125	2.79042962938547	18.66884375	2.00271746143699
84.7519989013672	2.79741222038865	18.67946484375	2.00856104493141
84.9520034790039	2.80502927489579	18.698857421875	2.01468635350466
85.1520004272461	2.81181652098894	18.69230078125	2.02107941731811
85.3519973754883	2.81845708377659	18.68183203125	2.02670320868492
85.552001953125	2.82441405579448	18.66866015625	2.03226483426988
85.7519989013672	2.83071282319725	18.660416015625	2.03780434094369
85.9520034790039	2.83818366006017	18.68328125	2.04387772828341
86.1520004272461	2.84506846219301	18.68189453125	2.0500267855823
86.3519973754883	2.85151368007064	18.671462890625	2.05590901896358
86.552001953125	2.857421990484	18.65315234375	2.06133001483977
86.7519989013672	2.86376941949129	18.653166015625	2.06683995202184
86.9520034790039	2.87031242623925	18.6556484375	2.07244278863072
87.1520004272461	2.87749012932181	18.668716796875	2.07840627990663
87.3519973754883	2.88437493145466	18.67026953125	2.08417745307088
87.552001953125	2.89082038216293	18.65875390625	2.09026597440243
87.7519989013672	2.89736338891089	18.65840625	2.09594890475273
87.9520034790039	2.90449219755828	18.668462890625	2.10190215148032
88.1520004272461	2.91113276034594	18.662693359375	2.10756831802428
88.3519973754883	2.91816401295364	18.668650390625	2.11380352266133
88.552001953125	2.92460946366191	18.656783203125	2.11961916647851
88.7519989013672	2.93105468153954	18.654884765625	2.12543527595699
88.9520034790039	2.93798837810755	18.65984765625	2.13144929148257
89.1520004272461	2.94453115202487	18.65521875	2.13735573925078
89.3519973754883	2.9510254971683	18.648455078125	2.14324309490621
89.552001953125	2.95771495439112	18.647703125	2.14915559627116
89.7519989013672	2.96450196765363	18.653615234375	2.15512304566801
89.9520034790039	2.97172856517136	18.658697265625	2.16141412965953
90.1520004272461	2.97836912795901	18.652748046875	2.16732989065349
90.3519973754883	2.98505858518183	18.6498203125	2.17330502346158
90.552001953125	2.99116200767457	18.633890625	2.17899563722312
90.7519989013672	2.99824215471745	18.645822265625	2.18508369289339
90.9520034790039	3.00556630827487	18.6558359375	2.19141924753785
91.1520004272461	3.0119139701128	18.639916015625	2.19739647582173
91.3519973754883	3.01826163195074	18.6293359375	2.2034386638552
91.552001953125	3.02412104792893	18.61083203125	2.2086335811764
91.7519989013672	3.03027336485684	18.608607421875	2.21408810466528
91.9520034790039	3.03779286332428	18.63491015625	2.22042924724519
92.1520004272461	3.04482411593199	18.636431640625	2.22658785060048
92.3519973754883	3.05146491155028	18.633607421875	2.23243632353842
92.552001953125	3.05751943960786	18.614462890625	2.23801657557487
92.7519989013672	3.06396489031613	18.610240234375	2.24375515244901
92.9520034790039	3.07075190357864	18.6203984375	2.24961317144334
93.1520004272461	3.07797850109637	18.632181640625	2.25573102943599
93.3519973754883	3.08486330322921	18.6256640625	2.26185447536409
93.552001953125	3.09106451459229	18.61220703125	2.2676179651171
93.7519989013672	3.09750973246992	18.605494140625	2.27359333075583
93.9520034790039	3.10434564016759	18.61276171875	2.27949861437082
94.1520004272461	3.1107421964407	18.608017578125	2.28542508557439
94.3519973754883	3.11782234348357	18.620205078125	2.2915699519217
94.552001953125	3.12446290627122	18.613466796875	2.29797489009798
94.7519989013672	3.13120125792921	18.6095546875	2.30379425920546
94.9520034790039	3.13837896101177	18.61987890625	2.31001270003617
95.1520004272461	3.14506841823459	18.609490234375	2.31625488959253
95.3519973754883	3.15146474167705	18.601791015625	2.32228124514222
95.552001953125	3.15815419889987	18.599771484375	2.32828757725656
95.7519989013672	3.16489255055785	18.602646484375	2.3344608489424
95.9520034790039	3.17197269760072	18.60519140625	2.34069302678108
96.1520004272461	3.17841791547835	18.5932265625	2.3471019230783
96.3519973754883	3.18491202779114	18.5852734375	2.35280441120267
96.552001953125	3.19077144376934	18.56848046875	2.35836068168283
96.7519989013672	3.19760735146701	18.580189453125	2.36448110081255
96.9520034790039	3.20488284341991	18.59379296875	2.37077940255404
97.1520004272461	3.21152340620756	18.585396484375	2.37686955370009
97.3519973754883	3.21821286343038	18.579994140625	2.38302769139409
97.552001953125	3.22431651875377	18.57084375	2.38883611746132
97.7519989013672	3.23066394776106	18.561048828125	2.39463499747217
97.9520034790039	3.23818367905915	18.5842890625	2.400764496997
98.1520004272461	3.24492179788649	18.58089453125	2.40709772333503
98.3519973754883	3.25141591019928	18.568107421875	2.41331290453672
98.552001953125	3.25732422061265	18.552814453125	2.41899187676609
98.7519989013672	3.26381833292544	18.552966796875	2.42471322417259
98.9520034790039	3.27070313505828	18.562501953125	2.43093795143068
99.1520004272461	3.27797862701118	18.575521484375	2.4371319450438
99.3519973754883	3.28500987961888	18.574537109375	2.44362582452595
99.552001953125	3.29121085815132	18.556947265625	2.44971085339785
99.7519989013672	3.29770497046411	18.55058203125	2.45573977008462
99.9520034790039	3.30478511750698	18.560427734375	2.4621207267046
100.152000427246	3.31137701869011	18.553611328125	2.46818619780242
100.351997375488	3.31855472177267	18.557759765625	2.47469660826027
100.552001953125	3.3249999396503	18.55372265625	2.4812682531774
100.751998901367	3.33159184083343	18.54423046875	2.48719286173582
100.952003479004	3.33837885409594	18.544263671875	2.49335891567171
101.152000427246	3.34482430480421	18.53375390625	2.49971426092088
101.351997375488	3.35107417777181	18.520705078125	2.50550452619791
101.552001953125	3.35771474055946	18.52558203125	2.51176464371383
101.751998901367	3.36450198665261	18.527060546875	2.51766853034496
101.952003479004	3.37172858417034	18.535390625	2.52436124719679
102.152000427246	3.37832025252283	18.525697265625	2.53033940680325
102.351997375488	3.38481436483562	18.516888671875	2.53635668195784
102.552001953125	3.39067378081381	18.4969453125	2.54231342114508
102.751998901367	3.39746102690697	18.504609375	2.54835817031562
102.952003479004	3.40478518046439	18.519373046875	2.55477009341121
103.152000427246	3.41137684881687	18.511330078125	2.56091495975852
103.351997375488	3.41791985556483	18.5034296875	2.56686471402645
103.552001953125	3.42397461645305	18.486037109375	2.57295975461602
103.751998901367	3.43012693338096	18.478267578125	2.57871625944972
103.952003479004	3.43754887580872	18.502806640625	2.58517591282725
104.152000427246	3.44458012841642	18.50343359375	2.59161414578557
104.351997375488	3.45136714167893	18.50385546875	2.59790499694645
104.552001953125	3.45756835304201	18.485013671875	2.6040815282613
104.751998901367	3.46430670469999	18.485037109375	2.61006550863385
104.952003479004	3.47128906287253	18.485314453125	2.6162697467953
105.152000427246	3.47846676595509	18.49416796875	2.62314034625888
105.351997375488	3.48510732874274	18.486259765625	2.62959278188646
105.552001953125	3.49106453359127	18.46527734375	2.63566989451647
105.751998901367	3.49741219542921	18.4562578125	2.64158751815557
105.952003479004	3.50434565916657	18.46380078125	2.64794076792896
106.152000427246	3.51088866591454	18.458595703125	2.65429797582328
106.351997375488	3.5180663689971	18.46782421875	2.66066147014499
106.552001953125	3.52456048130989	18.456669921875	2.66717374324799
106.751998901367	3.53105459362268	18.445373046875	2.67343851737678
106.952003479004	3.53803718462586	18.45241015625	2.67983134835958
107.152000427246	3.54458019137383	18.4417578125	2.68616201356053
107.351997375488	3.55107430368662	18.431806640625	2.69209127873182
107.552001953125	3.55781242251396	18.4326640625	2.69867130555212
107.751998901367	3.56455077417195	18.427044921875	2.70474259741604
107.952003479004	3.57153313234448	18.43219921875	2.71135615184903
108.152000427246	3.5778321325779	18.418576171875	2.71774246357381
108.351997375488	3.58427735045552	18.410869140625	2.72389804013073
108.552001953125	3.59028321690857	18.39277734375	2.72978306747973
108.751998901367	3.59726557508111	18.402029296875	2.73582944646478
108.952003479004	3.60488286241889	18.422341796875	2.74256221018732
109.152000427246	3.61171877011657	18.412294921875	2.74931429885328
109.351997375488	3.61840822733939	18.4013125	2.75566917844117
109.552001953125	3.62441409379244	18.377716796875	2.76177446357906
109.751998901367	3.63071286119521	18.37380859375	2.76788463816047
109.952003479004	3.63833014853299	18.391501953125	2.77456291951239
110.152000427246	3.64531250670552	18.389484375	2.781274728477
110.351997375488	3.65195306949317	18.375669921875	2.78786150738597
110.552001953125	3.65800783038139	18.3549375	2.79386295005679
110.751998901367	3.66445304825902	18.348951171875	2.80027044937015
110.952003479004	3.67119139991701	18.35105078125	2.80642695724964
111.152000427246	3.67827154695988	18.357216796875	2.8130472637713
111.351997375488	3.68520501069725	18.35651171875	2.81979166902602
111.552001953125	3.69140622206032	18.3344765625	2.82606482505798
111.751998901367	3.69799812324345	18.32890234375	2.83229188062251
111.952003479004	3.70498048141599	18.330005859375	2.83887633122504
112.152000427246	3.71137703768909	18.31657421875	2.84522259607911
112.351997375488	3.71821294538677	18.3163984375	2.85163894295692
112.552001953125	3.72436526231468	18.301189453125	2.85787554457784
112.751998901367	3.73076181858778	18.290828125	2.86380783654749
112.952003479004	3.73754883185029	18.2954921875	2.87022534757853
113.152000427246	3.74423828907311	18.28925	2.8765497263521
113.351997375488	3.75063484534621	18.27931640625	2.8829665388912
113.552001953125	3.75737296417356	18.277986328125	2.88939382880926
113.751998901367	3.76406242139637	18.273845703125	2.89591657929122
113.952003479004	3.77124012447894	18.276703125	2.90246866643429
114.152000427246	3.77792958170176	18.26148046875	2.90927686728537
114.351997375488	3.78457037732005	18.250591796875	2.91559076867998
114.552001953125	3.79067379981279	18.236634765625	2.92202713899314
114.751998901367	3.79765615798533	18.23819921875	2.92852218262851
114.952003479004	3.80507810041308	18.244556640625	2.93568195775151
115.152000427246	3.81157221272588	18.221734375	2.9421360231936
115.351997375488	3.81806632503867	18.21108203125	2.94880196452141
115.552001953125	3.82407219149172	18.19192578125	2.95502413064241
115.751998901367	3.83037119172513	18.17923046875	2.96127679757774
115.952003479004	3.83808603510261	18.205017578125	2.96827545389533
116.152000427246	3.84521484375	18.196	2.97509273514152
116.351997375488	3.85195319540799	18.181349609375	2.98220082186162
116.552001953125	3.85800772346556	18.15098046875	2.98855267465115
116.751998901367	3.864502068609	18.14198046875	2.99488031305373
116.952003479004	3.87128908187151	18.13934375	3.00168292596936
117.152000427246	3.8784178905189	18.1406875	3.00829508341849
117.351997375488	3.88515624217689	18.12958984375	3.0150911770761
117.552001953125	3.89121100306511	18.102240234375	3.0215464066714
117.751998901367	3.89750977046788	18.088130859375	3.02785565145314
117.952003479004	3.90424812212586	18.085734375	3.03428736515343
118.152000427246	3.91064444556832	18.073107421875	3.04070650599897
118.351997375488	3.9176270365715	18.07148046875	3.04746604524553
118.552001953125	3.92426736652851	18.060609375	3.05400346405804
118.751998901367	3.93090816214681	18.045056640625	3.06065683253109
118.952003479004	3.9380369707942	18.04685546875	3.06738796643913
119.152000427246	3.9446777664125	18.028736328125	3.07423924095929
119.351997375488	3.95112298429012	18.01135546875	3.08072287589312
119.552001953125	3.95776377990842	18.000208984375	3.08762048371136
119.751998901367	3.96445300430059	17.990626953125	3.09411576017737
119.952003479004	3.97158181294799	17.98808984375	3.10111441649497
120.152000427246	3.97807639092207	17.96353125	3.10770561918616
120.351997375488	3.98471672087908	17.954712890625	3.1146144028753
120.552001953125	3.99067392572761	17.9262734375	3.12105915509164
120.751998901367	3.99760762229562	17.927375	3.12742032110691
120.952003479004	4.00502933189273	17.928498046875	3.1348264310509
121.152000427246	4.01176745072007	17.9088359375	3.14172706566751
121.351997375488	4.0185060352087	17.893623046875	3.14866797998548
121.552001953125	4.02465835213661	17.862962890625	3.1554561574012
121.751998901367	4.03115246444941	17.849009765625	3.16186738200486
121.952003479004	4.03872085735202	17.852787109375	3.16926185041666
122.152000427246	4.04541008174419	17.8323828125	3.17601440474391
122.351997375488	4.05166018754244	17.806919921875	3.18262213841081
122.552001953125	4.05751960352063	17.775642578125	3.18899587728083
122.751998901367	4.06386703252792	17.763771484375	3.19554260931909
122.952003479004	4.07060561701655	17.76123828125	3.20217781700194
123.152000427246	4.07788064330816	17.7589453125	3.20906867273152
123.351997375488	4.08481433987617	17.7449765625	3.21593205444515
123.552001953125	4.09106444567442	17.71367578125	3.22278589010239
123.751998901367	4.09746076911688	17.6929453125	3.22914938442409
123.952003479004	4.10449225455523	17.685150390625	3.23628028854728
124.152000427246	4.11108415573835	17.66936328125	3.24273738078773
124.351997375488	4.11821296438575	17.66230859375	3.24961263686419
124.552001953125	4.12470707669854	17.6334375	3.25659313239157
124.751998901367	4.13115229457617	17.610396484375	3.26330144889653
124.952003479004	4.13803709670901	17.598638671875	3.27045819722116
125.152000427246	4.14448231458664	17.575529296875	3.27693787403405
125.351997375488	4.15083020925522	17.55423046875	3.28354723751545
125.552001953125	4.15756832808256	17.545490234375	3.29031096771359
125.751998901367	4.16450202465057	17.5319453125	3.29719693399966
125.952003479004	4.17187483981252	17.525134765625	3.30480257980525
126.152000427246	4.17861342430115	17.49578125	3.31180123612285
126.351997375488	4.18520485982299	17.47235546875	3.31885041669011
126.552001953125	4.19116206467152	17.434166015625	3.32544464617968
126.751998901367	4.19804686680436	17.42597265625	3.33238416351378
126.952003479004	4.20542014762759	17.420072265625	3.33955604583025
127.152000427246	4.21191425994039	17.3881640625	3.34667996503413
127.351997375488	4.21850569546223	17.362205078125	3.35324136540294
127.552001953125	4.22441400587559	17.3289375	3.35979764349759
127.751998901367	4.2305663228035	17.307400390625	3.36596951819956
127.952003479004	4.2379884980619	17.314365234375	3.3732415176928
128.151992797852	4.24492172896862	17.293486328125	3.38035589084029
128.352005004883	4.25166031345725	17.267564453125	3.38747259229422
128.552001953125	4.25776373594999	17.233798828125	3.39421513490379
128.751998901367	4.264404065907	17.214025390625	3.40110436081886
128.951995849609	4.27128886803985	17.199814453125	3.40788508765399
129.151992797852	4.27846657112241	17.183791015625	3.41502181254327
129.352005004883	4.28515626117587	17.15862109375	3.42202838510275
129.552001953125	4.29116189479828	17.12126171875	3.42851574532688
129.751998901367	4.29746089503169	17.098029296875	3.43494606204331
129.951995849609	4.3043945915997	17.087408203125	3.44235543161631
130.151992797852	4.3108887039125	17.063314453125	3.44909843988717
130.352005004883	4.31801751255989	17.050103515625	3.45632247626781
130.552001953125	4.32456051930785	17.019689453125	3.46331926994026
130.751998901367	4.33110352605581	16.994390625	3.47058312036097
130.951995849609	4.33818344026804	16.97634765625	3.47758340649307
131.151992797852	4.3448731303215	16.946716796875	3.48469917662442
131.352005004883	4.35141613706946	16.915615234375	3.49178095348179
131.552001953125	4.35820315033197	16.888263671875	3.49900824949145
131.751998901367	4.36499016359448	16.861537109375	3.50623880513012
131.951995849609	4.37187496572733	16.8369921875	3.51349473930895
132.151992797852	4.37812507152557	16.802603515625	3.52028803899884
132.352005004883	4.38447250053287	16.7689296875	3.52706667035818
132.552001953125	4.39028302207589	16.734822265625	3.53339384309947
132.751998901367	4.39711892977357	16.724615234375	3.54035198688507
132.951995849609	4.40458999946713	16.718130859375	3.54785239323974
133.151992797852	4.41137701272964	16.674265625	3.55511903762817
133.352005004883	4.41801780834794	16.642361328125	3.56254354119301
133.552001953125	4.42412123084068	16.59594921875	3.56936454772949
133.751998901367	4.43041976541281	16.560115234375	3.57627728953958
133.951995849609	4.43793926388025	16.550484375	3.58370505273342
134.151992797852	4.4449707493186	16.512310546875	3.59127903357148
134.352005004883	4.45165997371078	16.473689453125	3.59845557250082
134.552001953125	4.45776386186481	16.418869140625	3.60560393892229
134.751998901367	4.4642579741776	16.3832470703125	3.61219746991992
134.951995849609	4.47099609300494	16.34387890625	3.61995701678097
135.151992797852	4.4781737960875	16.306736328125	3.62782599404454
135.352005004883	4.48515638709068	16.2493916015625	3.63617180846632
135.552001953125	4.49145492166281	16.1119560546875	3.6455059889704
135.751998901367	4.49892599135637	-1.36688610839844	4.10558935254812
135.772003173828	4.50107408687472	-0.141590713500977	3.74622759409249